Workbook
Name IKAN: 'P NP MINAPADI KAB'!$D$1:$BY$1
Name KAB: 'P NP MINAPADI KAB'!$A$6:$BY$43
Name KABUPATEN: 'P NP MINAPADI KAB'!$A$5:$BY$43
Name Print_Area_MI: KARAMBA!$B$1:$Q$96
Name Print_Area_MI: KOLAM!$B$1:$T$95
Name Print_Area_MI: LAUT!$B$1:$T$95
Name Print_Area_MI: MINAPADI!$B$1:$Q$63
Name Print_Area_MI: TAMBAK!$B$1:$U$95
Name Print_Area_MI: 'TBK SEDERHANA'!$B$1:$V$95
Name Print_Area_MI: JAPUNG!$B$1:$V$95
Name Print_Titles_MI: JAPUNG!$A:$A
Name Print_Titles_MI: KARAMBA!$A:$A
Name Print_Titles_MI: KOLAM!$A:$A
Name Print_Titles_MI: LAUT!$A:$A
Name Print_Titles_MI: TAMBAK!$A:$A
Name Print_Titles_MI: 'TBK SEDERHANA'!$A:$A

Sheet DAFTAR ISI
B2: KLIK
A3: 1 | B3: P & NP | D3: INPUT
A4: 2 | B4: per KAB per WADAH per TW | D4: JUST SEE
A5: 3 | B5: NP | D5: JUST SEE
A6: 4 | B6: NP per IKAN per KAB | D6: JUST SEE
A7: 5 | B7: NP per IKAN per KAB per THN | D7: JUST SEE
A8: 6 | B8: P | D8: JUST SEE
A9: 7 | B9: P per IKAN per KAB | D9: JUST SEE
A10: 8 | B10: P per IKAN per KAB per THN | D10: JUST SEE
A11: 9 | B11: MENURUT TRIWULAN | D11: DATA
A12: 10 | B12: USAHA per TW | D12: DATA
A13: 11 | B13: per IKAN per WADAH per TAHUN | D13: DATA
A14: 12 | B14: KAB per JENIS per THN | D14: DATA
A15: 13 | B15: KAB per IKAN per THN | D15: DATA
A16: 14 | B16: PERBANDINGAN DENGAN TAHUN SEBELUMNYA
A17: 15 | B17: P & NP per BLN per KAB

Sheet PROGRAM
D2: 1 | T2: 2 | AJ2: 3 | AZ2: 4 | BP2: 5 | CF2: 6 | CV2: 7 | DJ2: 8 | DX2: 9 | EL2: 10 | EZ2: 11 | FN2: 12 | GC2: TRIWULAN 1 | GR2: TRIWULAN 2 | HG2: TRIWULAN 3 | HV2: TRIWULAN 4
B3: ='P & NP'!B1 -> 1.442333e+09 | C3: ='P & NP'!B3 -> 2.153823e+10 | D3: JANUARI | E3: JANUARI | F3: JANUARI | G3: JANUARI | H3: JANUARI | I3: JANUARI | J3: JANUARI | K3: JANUARI | L3: JANUARI | M3: JANUARI | N3: JANUARI | O3: JANUARI | P3: JANUARI | Q3: JANUARI | R3: JANUARI | S3: JANUARI | T3: FEBRUARI | U3: FEBRUARI | V3: FEBRUARI | W3: FEBRUARI | X3: FEBRUARI | Y3: FEBRUARI | Z3: FEBRUARI | AA3: FEBRUARI | AB3: FEBRUARI | AC3: FEBRUARI | AD3: FEBRUARI | AE3: FEBRUARI | AF3: FEBRUARI | AG3: FEBRUARI | AH3: FEBRUARI | AI3: FEBRUARI | AJ3: MARET | AK3: MARET | AL3: MARET | AM3: MARET | AN3: MARET | AO3: MARET | AP3: MARET | AQ3: MARET | AR3: MARET | AS3: MARET | AT3: MARET | AU3: MARET | AV3: MARET | AW3: MARET | AX3: MARET | AY3: MARET | AZ3: APRIL | BA3: APRIL | BB3: APRIL | BC3: APRIL | BD3: APRIL | BE3: APRIL | BF3: APRIL | BG3: APRIL | BH3: APRIL | BI3: APRIL | BJ3: APRIL | BK3: APRIL | BL3: APRIL | BM3: APRIL | BN3: APRIL | BO3: APRIL | BP3: MEI | BQ3: MEI | BR3: MEI | BS3: MEI | BT3: MEI | BU3: MEI | BV3: MEI | BW3: MEI | BX3: MEI | BY3: MEI | BZ3: MEI | CA3: MEI | CB3: MEI | CC3: MEI | CD3: MEI | CE3: MEI | CF3: JUNI | CG3: JUNI | CH3: JUNI | CI3: JUNI | CJ3: JUNI | CK3: JUNI | CL3: JUNI | CM3: JUNI | CN3: JUNI | CO3: JUNI | CP3: JUNI | CQ3: JUNI | CR3: JUNI | CS3: JUNI | CT3: JUNI | CU3: JUNI | CV3: JULI | CW3: JULI | CX3: JULI | CY3: JULI | CZ3: JULI | DA3: JULI | DB3: JULI | DC3: JULI | DD3: JULI | DE3: JULI | DF3: JULI | DG3: JULI | DH3: JULI | DI3: JULI | DJ3: AGUSTUS | DK3: AGUSTUS | DL3: AGUSTUS | DM3: AGUSTUS | DN3: AGUSTUS | DO3: AGUSTUS | DP3: AGUSTUS | DQ3: AGUSTUS | DR3: AGUSTUS | DS3: AGUSTUS | DT3: AGUSTUS | DU3: AGUSTUS | DV3: AGUSTUS | DW3: AGUSTUS | DX3: SEPTEMBER | DY3: SEPTEMBER | DZ3: SEPTEMBER | EA3: SEPTEMBER | EB3: SEPTEMBER | EC3: SEPTEMBER | ED3: SEPTEMBER | EE3: SEPTEMBER | EF3: SEPTEMBER | EG3: SEPTEMBER | EH3: SEPTEMBER | EI3: SEPTEMBER | EJ3: SEPTEMBER | EK3: SEPTEMBER | EL3: OKTOBER | EM3: OKTOBER | EN3: OKTOBER | EO3: OKTOBER | EP3: OKTOBER | EQ3: OKTOBER | ER3: OKTOBER | ES3: OKTOBER | ET3: OKTOBER | EU3: OKTOBER | EV3: OKTOBER | EW3: OKTOBER | EX3: OKTOBER | EY3: OKTOBER | EZ3: NOVEMBER | FA3: NOVEMBER | FB3: NOVEMBER | FC3: NOVEMBER | FD3: NOVEMBER | FE3: NOVEMBER | FF3: NOVEMBER | FG3: NOVEMBER | FH3: NOVEMBER | FI3: NOVEMBER | FJ3: NOVEMBER | FK3: NOVEMBER | FL3: NOVEMBER | FM3: NOVEMBER | FN3: DESEMBER | FO3: DESEMBER | FP3: DESEMBER | FQ3: DESEMBER | FR3: DESEMBER | FS3: DESEMBER | FT3: DESEMBER | FU3: DESEMBER | FV3: DESEMBER | FW3: DESEMBER | FX3: DESEMBER | FY3: DESEMBER | FZ3: DESEMBER | GA3: DESEMBER | GC3: TW1 | GD3: TW1 | GE3: TW1 | GF3: TW1 | GG3: TW1 | GH3: TW1 | GI3: TW1 | GJ3: TW1 | GK3: TW1 | GL3: TW1 | GM3: TW1 | GN3: TW1 | GO3: TW1 | GP3: TW1 | GR3: TW2 | GS3: TW2 | GT3: TW2 | GU3: TW2 | GV3: TW2 | GW3: TW2 | GX3: TW2 | GY3: TW2 | GZ3: TW2 | HA3: TW2 | HB3: TW2 | HC3: TW2 | HD3: TW2 | HE3: TW2 | HG3: TW3 | HH3: TW3 | HI3: TW3 | HJ3: TW3 | HK3: TW3 | HL3: TW3 | HM3: TW3 | HN3: TW3 | HO3: TW3 | HP3: TW3 | HQ3: TW3 | HR3: TW3 | HS3: TW3 | HT3: TW3 | HV3: TW4 | HW3: TW4 | HX3: TW4 | HY3: TW4 | HZ3: TW4 | IA3: TW4 | IB3: TW4 | IC3: TW4 | ID3: TW4 | IE3: TW4 | IF3: TW4 | IG3: TW4 | IH3: TW4 | II3: TW4
A4: KABUPATEN / KOTA | B4: JUMLAH TOTAL | D4: LAUT / KJA LAUT | F4: TAMBAK | H4: TAMBAK SEDERHANA | J4: KOLAM | L4: MINA PADI | N4: KARAMBA | P4: JAPUNG / KJA TAWAR | R4: JUMLAH TOTAL PER BULAN | T4: LAUT / KJA LAUT | V4: TAMBAK | X4: TAMBAK SEDERHANA | Z4: KOLAM | AB4: MINA PADI | AD4: KARAMBA | AF4: JAPUNG / KJA TAWAR | AH4: JUMLAH TOTAL PER BULAN | AJ4: LAUT / KJA LAUT | AL4: TAMBAK | AN4: TAMBAK SEDERHANA | AP4: KOLAM | AR4: MINA PADI | AT4: KARAMBA | AV4: JAPUNG / KJA TAWAR | AX4: JUMLAH TOTAL PER BULAN | AZ4: LAUT / KJA LAUT | BB4: TAMBAK | BD4: TAMBAK SEDERHANA | BF4: KOLAM | BH4: MINA PADI | BJ4: KARAMBA | BL4: JAPUNG / KJA TAWAR | BN4: JUMLAH TOTAL PER BULAN | BP4: LAUT / KJA LAUT | BR4: TAMBAK | BT4: SEDERHANATAMBAK | BV4: KOLAM | BX4: MINA PADI | BZ4: KARAMBA | CB4: JAPUNG / KJA TAWAR | CD4: JUMLAH TOTAL PER BULAN | CF4: LAUT / KJA LAUT | CH4: TAMBAK | CJ4: TAMBAK SEDERHANA | CL4: KOLAM | CN4: MINA PADI | CP4: KARAMBA | CR4: JAPUNG / KJA TAWAR | CT4: JUMLAH TOTAL PER BULAN | CV4: LAUT / KJA LAUT | CX4: TAMBAK | CZ4: KOLAM | DB4: MINA PADI / SAWAH TAMBAK | DD4: KARAMBA | DF4: JAPUNG / KJA TAWAR | DH4: JUMLAH TOTAL PER BULAN | DJ4: LAUT / KJA LAUT | DL4: TAMBAK | DN4: KOLAM | DP4: MINA PADI / SAWAH TAMBAK | DR4: KARAMBA | DT4: JAPUNG / KJA TAWAR | DV4: JUMLAH TOTAL PER BULAN | DX4: LAUT / KJA LAUT | DZ4: TAMBAK | EB4: KOLAM | ED4: MINA PADI / SAWAH TAMBAK | EF4: KARAMBA | EH4: JAPUNG / KJA TAWAR | EJ4: JUMLAH TOTAL PER BULAN | EL4: LAUT / KJA LAUT | EN4: TAMBAK | EP4: KOLAM | ER4: MINA PADI / SAWAH TAMBAK | ET4: KARAMBA | EV4: JAPUNG / KJA TAWAR | EX4: JUMLAH TOTAL PER BULAN | EZ4: LAUT / KJA LAUT | FB4: TAMBAK | FD4: KOLAM | FF4: MINA PADI / SAWAH TAMBAK | FH4: KARAMBA | FJ4: JAPUNG / KJA TAWAR | FL4: JUMLAH TOTAL PER BULAN | FN4: LAUT / KJA LAUT | FP4: TAMBAK | FR4: KOLAM | FT4: MINA PADI / SAWAH TAMBAK | FV4: KARAMBA | FX4: JAPUNG / KJA TAWAR | FZ4: JUMLAH TOTAL PER BULAN | GC4: LAUT / KJA LAUT | GE4: TAMBAK | GG4: KOLAM | GI4: MINA PADI / SAWAH TAMBAK | GK4: KARAMBA | GM4: JAPUNG / KJA TAWAR | GO4: JUMLAH TOTAL PER BULAN | GR4: LAUT / KJA LAUT | GT4: TAMBAK | GV4: KOLAM | GX4: MINA PADI / SAWAH TAMBAK | GZ4: KARAMBA | HB4: JAPUNG / KJA TAWAR | HD4: JUMLAH TOTAL PER BULAN | HG4: LAUT / KJA LAUT | HI4: TAMBAK | HK4: KOLAM | HM4: MINA PADI / SAWAH TAMBAK | HO4: KARAMBA | HQ4: JAPUNG / KJA TAWAR | HS4: JUMLAH TOTAL PER BULAN | HV4: LAUT / KJA LAUT | HX4: TAMBAK | HZ4: KOLAM | IB4: MINA PADI / SAWAH TAMBAK | ID4: KARAMBA | IF4: JAPUNG / KJA TAWAR | IH4: JUMLAH TOTAL PER BULAN
B5: P | C5: NP | D5: P | E5: NP | F5: P | G5: NP | H5: P | I5: NP | J5: P | K5: NP | L5: P | M5: NP | N5: P | O5: NP | P5: P | Q5: NP | R5: PT1 | S5: NPT1 | T5: P | U5: NP | V5: P | W5: NP | X5: P | Y5: NP | Z5: P | AA5: NP | AB5: P | AC5: NP | AD5: P | AE5: NP | AF5: P | AG5: NP | AH5: PT | AI5: NPT | AJ5: P | AK5: NP | AL5: P | AM5: NP | AN5: P | AO5: NP | AP5: P | AQ5: NP | AR5: P | AS5: NP | AT5: P | AU5: NP | AV5: P | AW5: NP | AX5: PT | AY5: NPT | AZ5: P | BA5: NP | BB5: P | BC5: NP | BD5: P | BE5: NP | BF5: P | BG5: NP | BH5: P | BI5: NP | BJ5: P | BK5: NP | BL5: P | BM5: NP | BN5: PT | BO5: NPT | BP5: P | BQ5: NP | BR5: P | BS5: NP | BT5: P | BU5: NP | BV5: P | BW5: NP | BX5: P | BY5: NP | BZ5: P | CA5: NP | CB5: P | CC5: NP | CD5: PT | CE5: NPT | CF5: P | CG5: NP | CH5: P | CI5: NP | CJ5: P | CK5: NP | CL5: P | CM5: NP | CN5: P | CO5: NP | CP5: P | CQ5: NP | CR5: P | CS5: NP | CT5: PT | CU5: NPT | CV5: P | CW5: NP | CX5: P | CY5: NP | CZ5: P | DA5: NP | DB5: P | DC5: NP | DD5: P | DE5: NP | DF5: P | DG5: NP | DH5: PT | DI5: NPT | DJ5: P | DK5: NP | DL5: P | DM5: NP | DN5: P | DO5: NP | DP5: P | DQ5: NP | DR5: P | DS5: NP | DT5: P | DU5: NP | DV5: PT | DW5: NPT | DX5: P | DY5: NP | DZ5: P | EA5: NP | EB5: P | EC5: NP | ED5: P | EE5: NP | EF5: P | EG5: NP | EH5: P | EI5: NP | EJ5: PT | EK5: NPT | EL5: P | EM5: NP | EN5: P | EO5: NP | EP5: P | EQ5: NP | ER5: P | ES5: NP | ET5: P | EU5: NP | EV5: P | EW5: NP | EX5: PT | EY5: NPT | EZ5: P | FA5: NP | FB5: P | FC5: NP | FD5: P | FE5: NP | FF5: P | FG5: NP | FH5: P | FI5: NP | FJ5: P | FK5: NP | FL5: PT | FM5: NPT | FN5: P | FO5: NP | FP5: P | FQ5: NP | FR5: P | FS5: NP | FT5: P | FU5: NP | FV5: P | FW5: NP | FX5: P | FY5: NP | FZ5: PT | GA5: NPT | GC5: PL | GD5: NPL | GE5: PT | GF5: NPT | GG5: PK | GH5: NPK | GI5: PS | GJ5: NPS | GK5: PM | GL5: NPM | GM5: PJ | GN5: NPJ | GO5: PT | GP5: NPT | GR5: PL | GS5: NPL | GT5: PT | GU5: NPT | GV5: PK | GW5: NPK | GX5: PS | GY5: NPS | GZ5: PM | HA5: NPM | HB5: PJ | HC5: NPJ | HD5: PT | HE5: NPT | HG5: PL | HH5: NPL | HI5: PT | HJ5: NPT | HK5: PK | HL5: NPK | HM5: PS | HN5: NPS | HO5: PM | HP5: NPM | HQ5: PJ | HR5: NPJ | HS5: PT | HT5: NPT | HV5: PL | HW5: NPL | HX5: PT | HY5: NPT | HZ5: PK | IA5: NPK | IB5: PS | IC5: NPS | ID5: PM | IE5: NPM | IF5: PJ | IG5: NPJ | IH5: PT | II5: NPT
B6: (Kg) | C6: (Rp. 000,-) | D6: (Kg) | E6: (Rp. 000,-) | F6: (Kg) | G6: (Rp. 000,-) | H6: (Kg) | I6: (Rp. 000,-) | J6: (Kg) | K6: (Rp. 000,-) | L6: (Kg) | M6: (Rp. 000,-) | N6: (Kg) | O6: (Rp. 000,-) | P6: (Kg) | Q6: (Rp. 000,-) | R6: (Kg) | S6: (Rp. 000,-) | T6: (Kg) | U6: (Rp. 000,-) | V6: (Kg) | W6: (Rp. 000,-) | X6: (Kg) | Y6: (Rp. 000,-) | Z6: (Kg) | AA6: (Rp. 000,-) | AB6: (Kg) | AC6: (Rp. 000,-) | AD6: (Kg) | AE6: (Rp. 000,-) | AF6: (Kg) | AG6: (Rp. 000,-) | AH6: (Kg) | AI6: (Rp. 000,-) | AJ6: (Kg) | AK6: (Rp. 000,-) | AL6: (Kg) | AM6: (Rp. 000,-) | AN6: (Kg) | AO6: (Rp. 000,-) | AP6: (Kg) | AQ6: (Rp. 000,-) | AR6: (Kg) | AS6: (Rp. 000,-) | AT6: (Kg) | AU6: (Rp. 000,-) | AV6: (Kg) | AW6: (Rp. 000,-) | AX6: (Kg) | AY6: (Rp. 000,-) | AZ6: (Kg) | BA6: (Rp. 000,-) | BB6: (Kg) | BC6: (Rp. 000,-) | BD6: (Kg) | BE6: (Rp. 000,-) | BF6: (Kg) | BG6: (Rp. 000,-) | BH6: (Kg) | BI6: (Rp. 000,-) | BJ6: (Kg) | BK6: (Rp. 000,-) | BL6: (Kg) | BM6: (Rp. 000,-) | BN6: (Kg) | BO6: (Rp. 000,-) | BP6: (Kg) | BQ6: (Rp. 000,-) | BR6: (Kg) | BS6: (Rp. 000,-) | BT6: (Kg) | BU6: (Rp. 000,-) | BV6: (Kg) | BW6: (Rp. 000,-) | BX6: (Kg) | BY6: (Rp. 000,-) | BZ6: (Kg) | CA6: (Rp. 000,-) | CB6: (Kg) | CC6: (Rp. 000,-) | CD6: (Kg) | CE6: (Rp. 000,-) | CF6: (Kg) | CG6: (Rp. 000,-) | CH6: (Kg) | CI6: (Rp. 000,-) | CJ6: (Kg) | CK6: (Rp. 000,-) | CL6: (Kg) | CM6: (Rp. 000,-) | CN6: (Kg) | CO6: (Rp. 000,-) | CP6: (Kg) | CQ6: (Rp. 000,-) | CR6: (Kg) | CS6: (Rp. 000,-) | CT6: (Kg) | CU6: (Rp. 000,-) | CV6: (Kg) | CW6: (Rp. 000,-) | CX6: (Kg) | CY6: (Rp. 000,-) | CZ6: (Kg) | DA6: (Rp. 000,-) | DB6: (Kg) | DC6: (Rp. 000,-) | DD6: (Kg) | DE6: (Rp. 000,-) | DF6: (Kg) | DG6: (Rp. 000,-) | DH6: (Kg) | DI6: (Rp. 000,-) | DJ6: (Kg) | DK6: (Rp. 000,-) | DL6: (Kg) | DM6: (Rp. 000,-) | DN6: (Kg) | DO6: (Rp. 000,-) | DP6: (Kg) | DQ6: (Rp. 000,-) | DR6: (Kg) | DS6: (Rp. 000,-) | DT6: (Kg) | DU6: (Rp. 000,-) | DV6: (Kg) | DW6: (Rp. 000,-) | DX6: (Kg) | DY6: (Rp. 000,-) | DZ6: (Kg) | EA6: (Rp. 000,-) | EB6: (Kg) | EC6: (Rp. 000,-) | ED6: (Kg) | EE6: (Rp. 000,-) | EF6: (Kg) | EG6: (Rp. 000,-) | EH6: (Kg) | EI6: (Rp. 000,-) | EJ6: (Kg) | EK6: (Rp. 000,-) | EL6: (Kg) | EM6: (Rp. 000,-) | EN6: (Kg) | EO6: (Rp. 000,-) | EP6: (Kg) | EQ6: (Rp. 000,-) | ER6: (Kg) | ES6: (Rp. 000,-) | ET6: (Kg) | EU6: (Rp. 000,-) | EV6: (Kg) | EW6: (Rp. 000,-) | EX6: (Kg) | EY6: (Rp. 000,-) | EZ6: (Kg) | FA6: (Rp. 000,-) | FB6: (Kg) | FC6: (Rp. 000,-) | FD6: (Kg) | FE6: (Rp. 000,-) | FF6: (Kg) | FG6: (Rp. 000,-) | FH6: (Kg) | FI6: (Rp. 000,-) | FJ6: (Kg) | FK6: (Rp. 000,-) | FL6: (Kg) | FM6: (Rp. 000,-) | FN6: (Kg) | FO6: (Rp. 000,-) | FP6: (Kg) | FQ6: (Rp. 000,-) | FR6: (Kg) | FS6: (Rp. 000,-) | FT6: (Kg) | FU6: (Rp. 000,-) | FV6: (Kg) | FW6: (Rp. 000,-) | FX6: (Kg) | FY6: (Rp. 000,-) | FZ6: (Kg) | GA6: (Rp. 000,-) | GC6: (Kg) | GD6: (Rp. 000,-) | GE6: (Kg) | GF6: (Rp. 000,-) | GG6: (Kg) | GH6: (Rp. 000,-) | GI6: (Kg) | GJ6: (Rp. 000,-) | GK6: (Kg) | GL6: (Rp. 000,-) | GM6: (Kg) | GN6: (Rp. 000,-) | GO6: (Kg) | GP6: (Rp. 000,-) | GR6: (Kg) | GS6: (Rp. 000,-) | GT6: (Kg) | GU6: (Rp. 000,-) | GV6: (Kg) | GW6: (Rp. 000,-) | GX6: (Kg) | GY6: (Rp. 000,-) | GZ6: (Kg) | HA6: (Rp. 000,-) | HB6: (Kg) | HC6: (Rp. 000,-) | HD6: (Kg) | HE6: (Rp. 000,-) | HG6: (Kg) | HH6: (Rp. 000,-) | HI6: (Kg) | HJ6: (Rp. 000,-) | HK6: (Kg) | HL6: (Rp. 000,-) | HM6: (Kg) | HN6: (Rp. 000,-) | HO6: (Kg) | HP6: (Rp. 000,-) | HQ6: (Kg) | HR6: (Rp. 000,-) | HS6: (Kg) | HT6: (Rp. 000,-) | HV6: (Kg) | HW6: (Rp. 000,-) | HX6: (Kg) | HY6: (Rp. 000,-) | HZ6: (Kg) | IA6: (Rp. 000,-) | IB6: (Kg) | IC6: (Rp. 000,-) | ID6: (Kg) | IE6: (Rp. 000,-) | IF6: (Kg) | IG6: (Rp. 000,-) | IH6: (Kg) | II6: (Rp. 000,-)
A7: JUMLAH | B7: =SUM(B8:B45) -> 1.442333e+09 | C7: =SUM(C8:C45) -> 2.153823e+10 | D7: =SUM(D8:D45) -> 47094474 | E7: =SUM(E8:E45) -> 289366046 | F7: =SUM(F8:F45) -> 22313374 | G7: =SUM(G8:G45) -> 7.8496901e+08 | H7: =SUM(H8:H45) -> 0 | I7: =SUM(I8:I45) -> 0 | ... GA7: =SUM(GA8:GA45) -> 1.9134131e+09 | GC7: =SUM(GC8:GC45) -> 156469131 | GD7: =SUM(GD8:GD45) -> 958355908 | GE7: =SUM(GE8:GE45) -> 71273383 | GF7: =SUM(GF8:GF45) -> 2.520146e+09 | GG7: =SUM(GG8:GG45) -> 93157607 | GH7: =SUM(GH8:GH45) -> 1.9007219e+09 | GI7: =SUM(GI8:GI45) -> 5244263 | GJ7: =SUM(GJ8:GJ45) -> 139551385 | ... GP7: =SUM(GP8:GP45) -> 5.603264e+09 | GR7: =SUM(GR8:GR45) -> 1.6955027e+08 | GS7: =SUM(GS8:GS45) -> 7.2965705e+08 | GT7: =SUM(GT8:GT45) -> 67363208 | GU7: =SUM(GU8:GU45) -> 2.3196143e+09 | GV7: =SUM(GV8:GV45) -> 1.061463e+08 | GW7: =SUM(GW8:GW45) -> 2.1994705e+09 | GX7: =SUM(GX8:GX45) -> 4892209 | GY7: =SUM(GY8:GY45) -> 1.2697872e+08 | ... HE7: =SUM(HE8:HE45) -> 5.4400047e+09 | HG7: =SUM(HG8:HG45) -> 227792889 | HH7: =SUM(HH8:HH45) -> 1.1825157e+09 | HI7: =SUM(HI8:HI45) -> 74491898 | HJ7: =SUM(HJ8:HJ45) -> 2.4934956e+09 | HK7: =SUM(HK8:HK45) -> 78438276 | HL7: =SUM(HL8:HL45) -> 1.4661259e+09 | HM7: =SUM(HM8:HM45) -> 2141071 | HN7: =SUM(HN8:HN45) -> 64309236 | ... HT7: =SUM(HT8:HT45) -> 5.2418236e+09 | HV7: =SUM(HV8:HV45) -> 2.2060287e+08 | HW7: =SUM(HW8:HW45) -> 1.1235125e+09 | HX7: =SUM(HX8:HX45) -> 69231143 | HY7: =SUM(HY8:HY45) -> 2.3441474e+09 | HZ7: =SUM(HZ8:HZ45) -> 78921149 | IA7: =SUM(IA8:IA45) -> 1.5926947e+09 | IB7: =SUM(IB8:IB45) -> 4038755 | IC7: =SUM(IC8:IC45) -> 115174730 | ... II7: =SUM(II8:II45) -> 5.2531373e+09
A8: KABUPATEN BANGKALAN | B8: =SUMIF($D$5:$GA$5,$B$5,D8:GA8) -> 15081607 | C8: =SUMIF($D$5:$GA$5,$C$5,D8:GA8) -> 5.4974742e+08 | D8: ='P & NP'!C13 -> 0 | E8: ='P & NP'!D13 -> 0 | F8: ='P & NP'!E13 -> 1499605 | G8: ='P & NP'!F13 -> 51715632 | H8: ='P & NP'!G13 -> 0 | I8: ='P & NP'!H13 -> 0 | J8: ='P & NP'!I13 -> 105800 | K8: ='P & NP'!J13 -> 2377400 | ... Q8: ='P & NP'!P13 -> 0 | R8: =SUM(D8,F8,J8,L8,N8,P8) -> 1605705 | S8: =SUM(E8,G8,K8,M8,O8,Q8) -> 54099032 | T8: ='P & NP'!C51 -> 0 | U8: ='P & NP'!D51 -> 0 | V8: ='P & NP'!E51 -> 1519847 | W8: ='P & NP'!F51 -> 49728962 | X8: ='P & NP'!G51 -> 0 | Y8: ='P & NP'!H51 -> 0 | Z8: ='P & NP'!I51 -> 114350 | AA8: ='P & NP'!J51 -> 2569250 | ... AG8: ='P & NP'!P51 -> 0 | AH8: =SUM(T8,V8,Z8,AB8,AD8,AF8) -> 1634597 | AI8: =SUM(U8,W8,AA8,AC8,AE8,AG8) -> 52306212 | AJ8: ='P & NP'!C89 -> 0 | AK8: ='P & NP'!D89 -> 0 | AL8: ='P & NP'!E89 -> 1596050 | AM8: ='P & NP'!F89 -> 52101740 | AN8: ='P & NP'!G89 -> 0 | AO8: ='P & NP'!H89 -> 0 | AP8: ='P & NP'!I89 -> 118600 | AQ8: ='P & NP'!J89 -> 2665300 | ... AW8: ='P & NP'!P89 -> 0 | AX8: =SUM(AJ8,AL8,AP8,AR8,AT8,AV8) -> 1715250 | AY8: =SUM(AK8,AM8,AQ8,AS8,AU8,AW8) -> 54779040 | AZ8: ='P & NP'!C127 -> 0 | BA8: ='P & NP'!D127 -> 0 | BB8: ='P & NP'!E127 -> 685250 | BC8: ='P & NP'!F127 -> 22405000 | BD8: ='P & NP'!G127 -> 0 | BE8: ='P & NP'!H127 -> 0 | BF8: ='P & NP'!I127 -> 50750 | BG8: ='P & NP'!J127 -> 1140550 | ... BM8: ='P & NP'!P127 -> 0 | BN8: =SUM(AZ8,BB8,BF8,BH8,BJ8,BL8) -> 736500 | BO8: =SUM(BA8,BC8,BG8,BI8,BK8,BM8) -> 23555550 | BP8: ='P & NP'!C165 -> 0 | BQ8: ='P & NP'!D165 -> 0 | BR8: ='P & NP'!E165 -> 620085 | BS8: ='P & NP'!F165 -> 20050910 | BT8: ='P & NP'!G165 -> 0 | BU8: ='P & NP'!H165 -> 0 | BV8: ='P & NP'!I165 -> 46500 | BW8: ='P & NP'!J165 -> 1044500 | ... CC8: ='P & NP'!P165 -> 0 | CD8: =SUM(BP8,BR8,BV8,BX8,BZ8,CB8) -> 666785 | CE8: =SUM(BQ8,BS8,BW8,BY8,CA8,CC8) -> 21099410 | CF8: ='P & NP'!C203 -> 0 | CG8: ='P & NP'!D203 -> 0 | CH8: ='P & NP'!E203 -> 590600 | CI8: ='P & NP'!F203 -> 20069145 | CJ8: ='P & NP'!G203 -> 0 | CK8: ='P & NP'!H203 -> 0 | CL8: ='P & NP'!I203 -> 42300 | CM8: ='P & NP'!J203 -> 950200 | ... CS8: ='P & NP'!P203 -> 0 | CT8: =SUM(CF8,CH8,CL8,CN8,CP8,CR8) -> 633000 | CU8: =SUM(CG8,CI8,CM8,CO8,CQ8,CS8) -> 21021345 | CV8: ='P & NP'!C241 -> 0 | CW8: ='P & NP'!D241 -> 0 | CX8: ='P & NP'!E241 -> 553320 | CY8: ='P & NP'!F241 -> 18713746 | CZ8: ='P & NP'!I241 -> 59300 | DA8: ='P & NP'!J241 -> 1332400 | DB8: ='P & NP'!K241 -> 0 | DC8: ='P & NP'!L241 -> 0 | DD8: ='P & NP'!M241 -> 200 | DE8: ='P & NP'!N241 -> 4000 | DF8: ='P & NP'!O241 -> 0 | DG8: ='P & NP'!P241 -> 0 | DH8: =SUM(CV8,CX8,CZ8,DB8,DD8,DF8) -> 612820 | DI8: =SUM(CW8,CY8,DA8,DC8,DE8,DG8) -> 20050146 | DJ8: ='P & NP'!C279 -> 0 | DK8: ='P & NP'!D279 -> 0 | DL8: ='P & NP'!E279 -> 548500 | DM8: ='P & NP'!F279 -> 19466200 | DN8: ='P & NP'!I279 -> 45200 | DO8: ='P & NP'!J279 -> 1035900 | DP8: ='P & NP'!K279 -> 0 | DQ8: ='P & NP'!L279 -> 0 | DR8: ='P & NP'!M279 -> 300 | DS8: ='P & NP'!N279 -> 6000 | DT8: ='P & NP'!O279 -> 0 | DU8: ='P & NP'!P279 -> 0 | DV8: =SUM(DJ8,DL8,DN8,DP8,DR8,DT8) -> 594000 | DW8: =SUM(DK8,DM8,DO8,DQ8,DS8,DU8) -> 20508100 | DX8: ='P & NP'!C317 -> 0 | DY8: ='P & NP'!D317 -> 0 | DZ8: ='P & NP'!E317 -> 515900 | EA8: ='P & NP'!F317 -> 18494340 | EB8: ='P & NP'!I317 -> 33850 | EC8: ='P & NP'!J317 -> 760350 | ED8: ='P & NP'!K317 -> 0 | EE8: ='P & NP'!L317 -> 0 | EF8: ='P & NP'!M317 -> 200 | EG8: ='P & NP'!N317 -> 4000 | EH8: ='P & NP'!O317 -> 0 | EI8: ='P & NP'!P317 -> 0 | EJ8: =SUM(DX8,DZ8,EB8,ED8,EF8,EH8) -> 549950 | EK8: =SUM(DY8,EA8,EC8,EE8,EG8,EI8) -> 19258690 | EL8: ='P & NP'!C355 -> 0 | EM8: ='P & NP'!D355 -> 0 | EN8: ='P & NP'!E355 -> 1337700 | EO8: ='P & NP'!F355 -> 45079460 | EP8: ='P & NP'!I355 -> 76300 | EQ8: ='P & NP'!J355 -> 1715400 | ER8: ='P & NP'!K355 -> 0 | ES8: ='P & NP'!L355 -> 0 | ET8: ='P & NP'!M355 -> 400 | EU8: ='P & NP'!N355 -> 8000 | EV8: ='P & NP'!O355 -> 0 | EW8: ='P & NP'!P355 -> 0 | EX8: =SUM(EL8,EN8,EP8,ER8,ET8,EV8) -> 1414400 | EY8: =SUM(EM8,EO8,EQ8,ES8,EU8,EW8) -> 46802860 | EZ8: ='P & NP'!C393 -> 0 | FA8: ='P & NP'!D393 -> 0 | FB8: ='P & NP'!E393 -> 1870400 | FC8: ='P & NP'!F393 -> 77566000 | FD8: ='P & NP'!I393 -> 67700 | FE8: ='P & NP'!J393 -> 1521500 | FF8: ='P & NP'!K393 -> 0 | FG8: ='P & NP'!L393 -> 0 | FH8: ='P & NP'!M393 -> 600 | FI8: ='P & NP'!N393 -> 12000 | FJ8: ='P & NP'!O393 -> 0 | FK8: ='P & NP'!P393 -> 0 | FL8: =SUM(EZ8,FB8,FD8,FF8,FH8,FJ8) -> 1938700 | FM8: =SUM(FA8,FC8,FE8,FG8,FI8,FK8) -> 79099500 | FN8: ='P & NP'!C431 -> 0 | FO8: ='P & NP'!D431 -> 0 | FP8: ='P & NP'!E431 -> 2886000 | FQ8: ='P & NP'!F431 -> 135059540 | FR8: ='P & NP'!I431 -> 93100 | FS8: ='P & NP'!J431 -> 2092000 | FT8: ='P & NP'!K431 -> 0 | FU8: ='P & NP'!L431 -> 0 | FV8: ='P & NP'!M431 -> 800 | FW8: ='P & NP'!N431 -> 16000 | FX8: ='P & NP'!O431 -> 0 | FY8: ='P & NP'!P431 -> 0 | FZ8: =SUM(FN8,FP8,FR8,FT8,FV8,FX8) -> 2979900 | GA8: =SUM(FO8,FQ8,FS8,FU8,FW8,FY8) -> 137167540 | GC8: =SUMIF($D$46:$AY$46,$GC$5,D8:AY8) -> 0 | GD8: =SUMIF($D$46:$AY$46,$GD$5,D8:AY8) -> 0 | GE8: =SUMIF($D$46:$AY$46,$GE$5,D8:AY8) -> 4615502 | GF8: =SUMIF($D$46:$AY$46,$GF$5,D8:AY8) -> 1.5354633e+08 | GG8: =SUMIF($D$46:$AY$46,$GG$5,D8:AY8) -> 338750 | GH8: =SUMIF($D$46:$AY$46,$GH$5,D8:AY8) -> 7611950 | GI8: =SUMIF($D$46:$AY$46,$GI$5,D8:AY8) -> 0 | GJ8: =SUMIF($D$46:$AY$46,$GJ$5,D8:AY8) -> 0 | GK8: =SUMIF($D$46:$AY$46,$GK$5,D8:AY8) -> 1300 | GL8: =SUMIF($D$46:$AY$46,$GL$5,D8:AY8) -> 26000 | GM8: =SUMIF($D$46:$AY$46,$GM$5,D8:AY8) -> 0 | GN8: =SUMIF($D$46:$AY$46,$GN$5,D8:AY8) -> 0 | GO8: =SUM(GC8,GE8,GG8,GI8,GK8,GM8) -> 4955552 | GP8: =SUM(GD8,GF8,GH8,GJ8,GL8,GN8) -> 1.6118428e+08 | GR8: =SUMIF($AZ$46:$CU$46,$GR$5,AZ8:CU8) -> 0 | GS8: =SUMIF($AZ$46:$CU$46,$GS$5,AZ8:CU8) -> 0 | GT8: =SUMIF($AZ$46:$CU$46,$GT$5,AZ8:CU8) -> 1895935 | GU8: =SUMIF($AZ$46:$CU$46,$GU$5,AZ8:CU8) -> 62525055 | GV8: =SUMIF($AZ$46:$CU$46,$GV$5,AZ8:CU8) -> 139550 | GW8: =SUMIF($AZ$46:$CU$46,$GW$5,AZ8:CU8) -> 3135250 | GX8: =SUMIF($AZ$46:$CU$46,$GX$5,AZ8:CU8) -> 0 | GY8: =SUMIF($AZ$46:$CU$46,$GY$5,AZ8:CU8) -> 0 | GZ8: =SUMIF($AZ$46:$CU$46,$GZ$5,AZ8:CU8) -> 800 | HA8: =SUMIF($AZ$46:$CU$46,$HA$5,AZ8:CU8) -> 16000 | HB8: =SUMIF($AZ$46:$CU$46,$HB$5,AZ8:CU8) -> 0 | HC8: =SUMIF($AZ$46:$CU$46,$HC$5,AZ8:CU8) -> 0 | HD8: =SUM(GR8,GT8,GV8,GX8,GZ8,HB8) -> 2036285 | HE8: =SUM(GS8,GU8,GW8,GY8,HA8,HC8) -> 65676305 | HG8: =SUMIF($CV$46:$EK$46,$HG$5,CV8:EK8) -> 0 | HH8: =SUMIF($CV$46:$EK$46,$HH$5,CV8:EK8) -> 0 | HI8: =SUMIF($CV$46:$EK$46,$HI$5,CV8:EK8) -> 1617720 | HJ8: =SUMIF($CV$46:$EK$46,$HJ$5,CV8:EK8) -> 56674286 | HK8: =SUMIF($CV$46:$EK$46,$HK$5,CV8:EK8) -> 138350 | HL8: =SUMIF($CV$46:$EK$46,$HL$5,CV8:EK8) -> 3128650 | HM8: =SUMIF($CV$46:$EK$46,$HM$5,CV8:EK8) -> 0 | HN8: =SUMIF($CV$46:$EK$46,$HN$5,CV8:EK8) -> 0 | HO8: =SUMIF($CV$46:$EK$46,$HO$5,CV8:EK8) -> 700 | HP8: =SUMIF($CV$46:$EK$46,$HP$5,CV8:EK8) -> 14000 | HQ8: =SUMIF($CV$46:$EK$46,$HQ$5,CV8:EK8) -> 0 | HR8: =SUMIF($CV$46:$EK$46,$HR$5,CV8:EK8) -> 0 | HS8: =SUM(HG8,HI8,HK8,HM8,HO8,HQ8) -> 1756770 | HT8: =SUM(HH8,HJ8,HL8,HN8,HP8,HR8) -> 59816936 | HV8: =SUMIF($EL$46:$GA$46,$HV$5,EL8:GA8) -> 0 | HW8: =SUMIF($EL$46:$GA$46,$HW$5,EL8:GA8) -> 0 | HX8: =SUMIF($EL$46:$GA$46,$HX$5,EL8:GA8) -> 6094100 | HY8: =SUMIF($EL$46:$GA$46,$HY$5,EL8:GA8) -> 257705000 | HZ8: =SUMIF($EL$46:$GA$46,$HZ$5,EL8:GA8) -> 237100 | IA8: =SUMIF($EL$46:$GA$46,$IA$5,EL8:GA8) -> 5328900 | IB8: =SUMIF($EL$46:$GA$46,$IB$5,EL8:GA8) -> 0 | IC8: =SUMIF($EL$46:$GA$46,$IC$5,EL8:GA8) -> 0 | ID8: =SUMIF($EL$46:$GA$46,$ID$5,EL8:GA8) -> 1800 | IE8: =SUMIF($EL$46:$GA$46,$IE$5,EL8:GA8) -> 36000 | IF8: =SUMIF($EL$46:$GA$46,$IF$5,EL8:GA8) -> 0 | IG8: =SUMIF($EL$46:$GA$46,$IG$5,EL8:GA8) -> 0 | IH8: =SUM(HV8,HX8,HZ8,IB8,ID8,IF8) -> 6333000 | II8: =SUM(HW8,HY8,IA8,IC8,IE8,IG8) -> 263069900
A9: KABUPATEN BANYUWANGI | B9: =SUMIF($D$5:$GA$5,$B$5,D9:GA9) -> 30646435 | C9: =SUMIF($D$5:$GA$5,$C$5,D9:GA9) -> 1257733055 | D9: ='P & NP'!S13 -> 3900 | E9: ='P & NP'!T13 -> 550250 | F9: ='P & NP'!U13 -> 1543690 | G9: ='P & NP'!V13 -> 76939050 | H9: ='P & NP'!W13 -> 0 | I9: ='P & NP'!X13 -> 0 | J9: ='P & NP'!Y13 -> 846770 | K9: ='P & NP'!Z13 -> 17206355 | ... Q9: ='P & NP'!AF13 -> 43900 | R9: =SUM(D9,F9,J9,L9,N9,P9) -> 2406035 | S9: =SUM(E9,G9,K9,M9,O9,Q9) -> 95010830 | T9: ='P & NP'!S51 -> 4380 | U9: ='P & NP'!T51 -> 577300 | V9: ='P & NP'!U51 -> 1593845 | W9: ='P & NP'!V51 -> 79905325 | X9: ='P & NP'!W51 -> 0 | Y9: ='P & NP'!X51 -> 0 | Z9: ='P & NP'!Y51 -> 841220 | AA9: ='P & NP'!Z51 -> 17054465 | ... AG9: ='P & NP'!AF51 -> 52225 | AH9: =SUM(T9,V9,Z9,AB9,AD9,AF9) -> 2451255 | AI9: =SUM(U9,W9,AA9,AC9,AE9,AG9) -> 97853915 | AJ9: ='P & NP'!S89 -> 5150 | AK9: ='P & NP'!T89 -> 635900 | AL9: ='P & NP'!U89 -> 1608090 | AM9: ='P & NP'!V89 -> 79992275 | AN9: ='P & NP'!W89 -> 0 | AO9: ='P & NP'!X89 -> 0 | AP9: ='P & NP'!Y89 -> 820170 | AQ9: ='P & NP'!Z89 -> 16694595 | ... AW9: ='P & NP'!AF89 -> 40050 | AX9: =SUM(AJ9,AL9,AP9,AR9,AT9,AV9) -> 2444880 | AY9: =SUM(AK9,AM9,AQ9,AS9,AU9,AW9) -> 97629645 | AZ9: ='P & NP'!S127 -> 9795 | BA9: ='P & NP'!T127 -> 968075 | BB9: ='P & NP'!U127 -> 1686755 | BC9: ='P & NP'!V127 -> 87732050 | BD9: ='P & NP'!W127 -> 0 | BE9: ='P & NP'!X127 -> 0 | BF9: ='P & NP'!Y127 -> 778410 | BG9: ='P & NP'!Z127 -> 15848220 | ... BM9: ='P & NP'!AF127 -> 54475 | BN9: =SUM(AZ9,BB9,BF9,BH9,BJ9,BL9) -> 2485895 | BO9: =SUM(BA9,BC9,BG9,BI9,BK9,BM9) -> 104838295 | BP9: ='P & NP'!S165 -> 4630 | BQ9: ='P & NP'!T165 -> 509175 | BR9: ='P & NP'!U165 -> 1723220 | BS9: ='P & NP'!V165 -> 89804160 | BT9: ='P & NP'!W165 -> 0 | BU9: ='P & NP'!X165 -> 0 | BV9: ='P & NP'!Y165 -> 804519 | BW9: ='P & NP'!Z165 -> 16393445 | ... CC9: ='P & NP'!AF165 -> 61250 | CD9: =SUM(BP9,BR9,BV9,BX9,BZ9,CB9) -> 2543509 | CE9: =SUM(BQ9,BS9,BW9,BY9,CA9,CC9) -> 107000905 | CF9: ='P & NP'!S203 -> 4045 | CG9: ='P & NP'!T203 -> 483775 | CH9: ='P & NP'!U203 -> 1736715 | CI9: ='P & NP'!V203 -> 90640250 | CJ9: ='P & NP'!W203 -> 0 | CK9: ='P & NP'!X203 -> 0 | CL9: ='P & NP'!Y203 -> 767550 | CM9: ='P & NP'!Z203 -> 15678910 | ... CS9: ='P & NP'!AF203 -> 60000 | CT9: =SUM(CF9,CH9,CL9,CN9,CP9,CR9) -> 2519450 | CU9: =SUM(CG9,CI9,CM9,CO9,CQ9,CS9) -> 107097810 | CV9: ='P & NP'!S241 -> 2615 | CW9: ='P & NP'!T241 -> 353825 | CX9: ='P & NP'!U241 -> 1671820 | CY9: ='P & NP'!V241 -> 91277925 | CZ9: ='P & NP'!Y241 -> 895441 | DA9: ='P & NP'!Z241 -> 18230110 | DB9: ='P & NP'!AA241 -> 5670 | DC9: ='P & NP'!AB241 -> 155550 | DD9: ='P & NP'!AC241 -> 4985 | DE9: ='P & NP'!AD241 -> 136600 | DF9: ='P & NP'!AE241 -> 1615 | DG9: ='P & NP'!AF241 -> 37250 | DH9: =SUM(CV9,CX9,CZ9,DB9,DD9,DF9) -> 2582146 | DI9: =SUM(CW9,CY9,DA9,DC9,DE9,DG9) -> 110191260 | DJ9: ='P & NP'!S279 -> 2260 | DK9: ='P & NP'!T279 -> 276950 | DL9: ='P & NP'!U279 -> 1677680 | DM9: ='P & NP'!V279 -> 91757575 | DN9: ='P & NP'!Y279 -> 850960 | DO9: ='P & NP'!Z279 -> 17334370 | DP9: ='P & NP'!AA279 -> 5830 | DQ9: ='P & NP'!AB279 -> 159275 | DR9: ='P & NP'!AC279 -> 4295 | DS9: ='P & NP'!AD279 -> 117250 | DT9: ='P & NP'!AE279 -> 1530 | DU9: ='P & NP'!AF279 -> 33900 | DV9: =SUM(DJ9,DL9,DN9,DP9,DR9,DT9) -> 2542555 | DW9: =SUM(DK9,DM9,DO9,DQ9,DS9,DU9) -> 109679320 | DX9: ='P & NP'!S317 -> 2205 | DY9: ='P & NP'!T317 -> 237525 | DZ9: ='P & NP'!U317 -> 1691140 | EA9: ='P & NP'!V317 -> 92660225 | EB9: ='P & NP'!Y317 -> 892994 | EC9: ='P & NP'!Z317 -> 18193110 | ED9: ='P & NP'!AA317 -> 5780 | EE9: ='P & NP'!AB317 -> 157375 | EF9: ='P & NP'!AC317 -> 4025 | EG9: ='P & NP'!AD317 -> 109900 | EH9: ='P & NP'!AE317 -> 1505 | EI9: ='P & NP'!AF317 -> 31750 | EJ9: =SUM(DX9,DZ9,EB9,ED9,EF9,EH9) -> 2597649 | EK9: =SUM(DY9,EA9,EC9,EE9,EG9,EI9) -> 111389885 | EL9: ='P & NP'!S355 -> 3165 | EM9: ='P & NP'!T355 -> 381750 | EN9: ='P & NP'!U355 -> 1666265 | EO9: ='P & NP'!V355 -> 82818575 | EP9: ='P & NP'!Y355 -> 988160 | EQ9: ='P & NP'!Z355 -> 20159370 | ER9: ='P & NP'!AA355 -> 5415 | ES9: ='P & NP'!AB355 -> 148575 | ET9: ='P & NP'!AC355 -> 4480 | EU9: ='P & NP'!AD355 -> 123950 | EV9: ='P & NP'!AE355 -> 2145 | EW9: ='P & NP'!AF355 -> 47550 | EX9: =SUM(EL9,EN9,EP9,ER9,ET9,EV9) -> 2669630 | EY9: =SUM(EM9,EO9,EQ9,ES9,EU9,EW9) -> 103679770 | EZ9: ='P & NP'!S393 -> 2975 | FA9: ='P & NP'!T393 -> 351775 | FB9: ='P & NP'!U393 -> 1755495 | FC9: ='P & NP'!V393 -> 87403750 | FD9: ='P & NP'!Y393 -> 959326 | FE9: ='P & NP'!Z393 -> 19575475 | FF9: ='P & NP'!AA393 -> 5405 | FG9: ='P & NP'!AB393 -> 150100 | FH9: ='P & NP'!AC393 -> 4875 | FI9: ='P & NP'!AD393 -> 134700 | FJ9: ='P & NP'!AE393 -> 1975 | FK9: ='P & NP'!AF393 -> 42500 | FL9: =SUM(EZ9,FB9,FD9,FF9,FH9,FJ9) -> 2730051 | FM9: =SUM(FA9,FC9,FE9,FG9,FI9,FK9) -> 107658300 | FN9: ='P & NP'!S431 -> 3140 | FO9: ='P & NP'!T431 -> 395350 | FP9: ='P & NP'!U431 -> 1717675 | FQ9: ='P & NP'!V431 -> 85767450 | FR9: ='P & NP'!Y431 -> 940215 | FS9: ='P & NP'!Z431 -> 19211795 | FT9: ='P & NP'!AA431 -> 5415 | FU9: ='P & NP'!AB431 -> 149475 | FV9: ='P & NP'!AC431 -> 4900 | FW9: ='P & NP'!AD431 -> 136175 | FX9: ='P & NP'!AE431 -> 2035 | FY9: ='P & NP'!AF431 -> 42875 | FZ9: =SUM(FN9,FP9,FR9,FT9,FV9,FX9) -> 2673380 | GA9: =SUM(FO9,FQ9,FS9,FU9,FW9,FY9) -> 105703120 | GC9: =SUMIF($D$46:$AY$46,$GC$5,D9:AY9) -> 13430 | GD9: =SUMIF($D$46:$AY$46,$GD$5,D9:AY9) -> 1763450 | GE9: =SUMIF($D$46:$AY$46,$GE$5,D9:AY9) -> 4745625 | GF9: =SUMIF($D$46:$AY$46,$GF$5,D9:AY9) -> 236836650 | GG9: =SUMIF($D$46:$AY$46,$GG$5,D9:AY9) -> 2508160 | GH9: =SUMIF($D$46:$AY$46,$GH$5,D9:AY9) -> 50955415 | GI9: =SUMIF($D$46:$AY$46,$GI$5,D9:AY9) -> 18740 | GJ9: =SUMIF($D$46:$AY$46,$GJ$5,D9:AY9) -> 510625 | GK9: =SUMIF($D$46:$AY$46,$GK$5,D9:AY9) -> 10610 | GL9: =SUMIF($D$46:$AY$46,$GL$5,D9:AY9) -> 292075 | GM9: =SUMIF($D$46:$AY$46,$GM$5,D9:AY9) -> 5605 | GN9: =SUMIF($D$46:$AY$46,$GN$5,D9:AY9) -> 136175 | GO9: =SUM(GC9,GE9,GG9,GI9,GK9,GM9) -> 7302170 | GP9: =SUM(GD9,GF9,GH9,GJ9,GL9,GN9) -> 290494390 | GR9: =SUMIF($AZ$46:$CU$46,$GR$5,AZ9:CU9) -> 18470 | GS9: =SUMIF($AZ$46:$CU$46,$GS$5,AZ9:CU9) -> 1961025 | GT9: =SUMIF($AZ$46:$CU$46,$GT$5,AZ9:CU9) -> 5146690 | GU9: =SUMIF($AZ$46:$CU$46,$GU$5,AZ9:CU9) -> 268176460 | GV9: =SUMIF($AZ$46:$CU$46,$GV$5,AZ9:CU9) -> 2350479 | GW9: =SUMIF($AZ$46:$CU$46,$GW$5,AZ9:CU9) -> 47920575 | GX9: =SUMIF($AZ$46:$CU$46,$GX$5,AZ9:CU9) -> 15950 | GY9: =SUMIF($AZ$46:$CU$46,$GY$5,AZ9:CU9) -> 436300 | GZ9: =SUMIF($AZ$46:$CU$46,$GZ$5,AZ9:CU9) -> 9645 | HA9: =SUMIF($AZ$46:$CU$46,$HA$5,AZ9:CU9) -> 266925 | HB9: =SUMIF($AZ$46:$CU$46,$HB$5,AZ9:CU9) -> 7620 | HC9: =SUMIF($AZ$46:$CU$46,$HC$5,AZ9:CU9) -> 175725 | HD9: =SUM(GR9,GT9,GV9,GX9,GZ9,HB9) -> 7548854 | HE9: =SUM(GS9,GU9,GW9,GY9,HA9,HC9) -> 318937010 | HG9: =SUMIF($CV$46:$EK$46,$HG$5,CV9:EK9) -> 7080 | HH9: =SUMIF($CV$46:$EK$46,$HH$5,CV9:EK9) -> 868300 | HI9: =SUMIF($CV$46:$EK$46,$HI$5,CV9:EK9) -> 5040640 | HJ9: =SUMIF($CV$46:$EK$46,$HJ$5,CV9:EK9) -> 275695725 | HK9: =SUMIF($CV$46:$EK$46,$HK$5,CV9:EK9) -> 2639395 | HL9: =SUMIF($CV$46:$EK$46,$HL$5,CV9:EK9) -> 53757590 | HM9: =SUMIF($CV$46:$EK$46,$HM$5,CV9:EK9) -> 17280 | HN9: =SUMIF($CV$46:$EK$46,$HN$5,CV9:EK9) -> 472200 | HO9: =SUMIF($CV$46:$EK$46,$HO$5,CV9:EK9) -> 13305 | HP9: =SUMIF($CV$46:$EK$46,$HP$5,CV9:EK9) -> 363750 | HQ9: =SUMIF($CV$46:$EK$46,$HQ$5,CV9:EK9) -> 4650 | HR9: =SUMIF($CV$46:$EK$46,$HR$5,CV9:EK9) -> 102900 | HS9: =SUM(HG9,HI9,HK9,HM9,HO9,HQ9) -> 7722350 | HT9: =SUM(HH9,HJ9,HL9,HN9,HP9,HR9) -> 331260465 | HV9: =SUMIF($EL$46:$GA$46,$HV$5,EL9:GA9) -> 9280 | HW9: =SUMIF($EL$46:$GA$46,$HW$5,EL9:GA9) -> 1128875 | HX9: =SUMIF($EL$46:$GA$46,$HX$5,EL9:GA9) -> 5139435 | HY9: =SUMIF($EL$46:$GA$46,$HY$5,EL9:GA9) -> 255989775 | HZ9: =SUMIF($EL$46:$GA$46,$HZ$5,EL9:GA9) -> 2887701 | IA9: =SUMIF($EL$46:$GA$46,$IA$5,EL9:GA9) -> 58946640 | IB9: =SUMIF($EL$46:$GA$46,$IB$5,EL9:GA9) -> 16235 | IC9: =SUMIF($EL$46:$GA$46,$IC$5,EL9:GA9) -> 448150 | ID9: =SUMIF($EL$46:$GA$46,$ID$5,EL9:GA9) -> 14255 | IE9: =SUMIF($EL$46:$GA$46,$IE$5,EL9:GA9) -> 394825 | IF9: =SUMIF($EL$46:$GA$46,$IF$5,EL9:GA9) -> 6155 | IG9: =SUMIF($EL$46:$GA$46,$IG$5,EL9:GA9) -> 132925 | IH9: =SUM(HV9,HX9,HZ9,IB9,ID9,IF9) -> 8073061 | II9: =SUM(HW9,HY9,IA9,IC9,IE9,IG9) -> 317041190
A10: KABUPATEN BLITAR | B10: =SUMIF($D$5:$GA$5,$B$5,D10:GA10) -> 17736425 | C10: =SUMIF($D$5:$GA$5,$C$5,D10:GA10) -> 414183920 | D10: ='P & NP'!AI13 -> 0 | E10: ='P & NP'!AJ13 -> 0 | F10: ='P & NP'!AK13 -> 34100 | G10: ='P & NP'!AL13 -> 2216500 | H10: ='P & NP'!AM13 -> 0 | I10: ='P & NP'!AN13 -> 0 | J10: ='P & NP'!AO13 -> 1312000 | K10: ='P & NP'!AP13 -> 28693200 | ... Q10: ='P & NP'!AV13 -> 52500 | R10: =SUM(D10,F10,J10,L10,N10,P10) -> 1348300 | S10: =SUM(E10,G10,K10,M10,O10,Q10) -> 30964700 | T10: ='P & NP'!AI51 -> 0 | U10: ='P & NP'!AJ51 -> 0 | V10: ='P & NP'!AK51 -> 35200 | W10: ='P & NP'!AL51 -> 2288000 | X10: ='P & NP'!AM51 -> 0 | Y10: ='P & NP'!AN51 -> 0 | Z10: ='P & NP'!AO51 -> 1331600 | AA10: ='P & NP'!AP51 -> 29130100 | ... AG10: ='P & NP'!AV51 -> 60000 | AH10: =SUM(T10,V10,Z10,AB10,AD10,AF10) -> 1369320 | AI10: =SUM(U10,W10,AA10,AC10,AE10,AG10) -> 31481100 | AJ10: ='P & NP'!AI89 -> 0 | AK10: ='P & NP'!AJ89 -> 0 | AL10: ='P & NP'!AK89 -> 35700 | AM10: ='P & NP'!AL89 -> 2320500 | AN10: ='P & NP'!AM89 -> 0 | AO10: ='P & NP'!AN89 -> 0 | AP10: ='P & NP'!AO89 -> 1382100 | AQ10: ='P & NP'!AP89 -> 30199400 | ... AW10: ='P & NP'!AV89 -> 61440 | AX10: =SUM(AJ10,AL10,AP10,AR10,AT10,AV10) -> 1420560 | AY10: =SUM(AK10,AM10,AQ10,AS10,AU10,AW10) -> 32586140 | AZ10: ='P & NP'!AI127 -> 0 | BA10: ='P & NP'!AJ127 -> 0 | BB10: ='P & NP'!AK127 -> 36200 | BC10: ='P & NP'!AL127 -> 2353000 | BD10: ='P & NP'!AM127 -> 0 | BE10: ='P & NP'!AN127 -> 0 | BF10: ='P & NP'!AO127 -> 1452700 | BG10: ='P & NP'!AP127 -> 31596400 | ... BM10: ='P & NP'!AV127 -> 73200 | BN10: =SUM(AZ10,BB10,BF10,BH10,BJ10,BL10) -> 1492150 | BO10: =SUM(BA10,BC10,BG10,BI10,BK10,BM10) -> 34027400 | BP10: ='P & NP'!AI165 -> 0 | BQ10: ='P & NP'!AJ165 -> 0 | BR10: ='P & NP'!AK165 -> 36700 | BS10: ='P & NP'!AL165 -> 2385500 | BT10: ='P & NP'!AM165 -> 0 | BU10: ='P & NP'!AN165 -> 0 | BV10: ='P & NP'!AO165 -> 1441800 | BW10: ='P & NP'!AP165 -> 31538600 | ... CC10: ='P & NP'!AV165 -> 74640 | CD10: =SUM(BP10,BR10,BV10,BX10,BZ10,CB10) -> 1481800 | CE10: =SUM(BQ10,BS10,BW10,BY10,CA10,CC10) -> 34003300 | CF10: ='P & NP'!AI203 -> 0 | CG10: ='P & NP'!AJ203 -> 0 | CH10: ='P & NP'!AK203 -> 36100 | CI10: ='P & NP'!AL203 -> 2346500 | CJ10: ='P & NP'!AM203 -> 0 | CK10: ='P & NP'!AN203 -> 0 | CL10: ='P & NP'!AO203 -> 1434700 | CM10: ='P & NP'!AP203 -> 31984800 | ... CS10: ='P & NP'!AV203 -> 67920 | CT10: =SUM(CF10,CH10,CL10,CN10,CP10,CR10) -> 1473790 | CU10: =SUM(CG10,CI10,CM10,CO10,CQ10,CS10) -> 34403060 | CV10: ='P & NP'!AI241 -> 0 | CW10: ='P & NP'!AJ241 -> 0 | CX10: ='P & NP'!AK241 -> 37900 | CY10: ='P & NP'!AL241 -> 2463500 | CZ10: ='P & NP'!AO241 -> 1448200 | DA10: ='P & NP'!AP241 -> 32260500 | DB10: ='P & NP'!AQ241 -> 170 | DC10: ='P & NP'!AR241 -> 4080 | DD10: ='P & NP'!AS241 -> 0 | DE10: ='P & NP'!AT241 -> 0 | DF10: ='P & NP'!AU241 -> 2190 | DG10: ='P & NP'!AV241 -> 52560 | DH10: =SUM(CV10,CX10,CZ10,DB10,DD10,DF10) -> 1488460 | DI10: =SUM(CW10,CY10,DA10,DC10,DE10,DG10) -> 34780640 | DJ10: ='P & NP'!AI279 -> 0 | DK10: ='P & NP'!AJ279 -> 0 | DL10: ='P & NP'!AK279 -> 37200 | DM10: ='P & NP'!AL279 -> 2418000 | DN10: ='P & NP'!AO279 -> 1441500 | DO10: ='P & NP'!AP279 -> 32091200 | DP10: ='P & NP'!AQ279 -> 150 | DQ10: ='P & NP'!AR279 -> 3600 | DR10: ='P & NP'!AS279 -> 0 | DS10: ='P & NP'!AT279 -> 0 | DT10: ='P & NP'!AU279 -> 2050 | DU10: ='P & NP'!AV279 -> 49200 | DV10: =SUM(DJ10,DL10,DN10,DP10,DR10,DT10) -> 1480900 | DW10: =SUM(DK10,DM10,DO10,DQ10,DS10,DU10) -> 34562000 | DX10: ='P & NP'!AI317 -> 0 | DY10: ='P & NP'!AJ317 -> 0 | DZ10: ='P & NP'!AK317 -> 37700 | EA10: ='P & NP'!AL317 -> 2450500 | EB10: ='P & NP'!AO317 -> 1270500 | EC10: ='P & NP'!AP317 -> 29154800 | ED10: ='P & NP'!AQ317 -> 150 | EE10: ='P & NP'!AR317 -> 3600 | EF10: ='P & NP'!AS317 -> 0 | EG10: ='P & NP'!AT317 -> 0 | EH10: ='P & NP'!AU317 -> 2150 | EI10: ='P & NP'!AV317 -> 51600 | EJ10: =SUM(DX10,DZ10,EB10,ED10,EF10,EH10) -> 1310500 | EK10: =SUM(DY10,EA10,EC10,EE10,EG10,EI10) -> 31660500 | EL10: ='P & NP'!AI355 -> 0 | EM10: ='P & NP'!AJ355 -> 0 | EN10: ='P & NP'!AK355 -> 36400 | EO10: ='P & NP'!AL355 -> 2366000 | EP10: ='P & NP'!AO355 -> 1530300 | EQ10: ='P & NP'!AP355 -> 34818500 | ER10: ='P & NP'!AQ355 -> 130 | ES10: ='P & NP'!AR355 -> 3120 | ET10: ='P & NP'!AS355 -> 0 | EU10: ='P & NP'!AT355 -> 0 | EV10: ='P & NP'!AU355 -> 2085 | EW10: ='P & NP'!AV355 -> 50040 | EX10: =SUM(EL10,EN10,EP10,ER10,ET10,EV10) -> 1568915 | EY10: =SUM(EM10,EO10,EQ10,ES10,EU10,EW10) -> 37237660 | EZ10: ='P & NP'!AI393 -> 0 | FA10: ='P & NP'!AJ393 -> 0 | FB10: ='P & NP'!AK393 -> 36300 | FC10: ='P & NP'!AL393 -> 2359500 | FD10: ='P & NP'!AO393 -> 1603100 | FE10: ='P & NP'!AP393 -> 36565200 | FF10: ='P & NP'!AQ393 -> 150 | FG10: ='P & NP'!AR393 -> 3600 | FH10: ='P & NP'!AS393 -> 0 | FI10: ='P & NP'!AT393 -> 0 | FJ10: ='P & NP'!AU393 -> 1910 | FK10: ='P & NP'!AV393 -> 45840 | FL10: =SUM(EZ10,FB10,FD10,FF10,FH10,FJ10) -> 1641460 | FM10: =SUM(FA10,FC10,FE10,FG10,FI10,FK10) -> 38974140 | FN10: ='P & NP'!AI431 -> 0 | FO10: ='P & NP'!AJ431 -> 0 | FP10: ='P & NP'!AK431 -> 36600 | FQ10: ='P & NP'!AL431 -> 2379000 | FR10: ='P & NP'!AO431 -> 1621800 | FS10: ='P & NP'!AP431 -> 37079400 | FT10: ='P & NP'!AQ431 -> 100 | FU10: ='P & NP'!AR431 -> 2400 | FV10: ='P & NP'!AS431 -> 0 | FW10: ='P & NP'!AT431 -> 0 | FX10: ='P & NP'!AU431 -> 1770 | FY10: ='P & NP'!AV431 -> 42480 | FZ10: =SUM(FN10,FP10,FR10,FT10,FV10,FX10) -> 1660270 | GA10: =SUM(FO10,FQ10,FS10,FU10,FW10,FY10) -> 39503280 | GC10: =SUMIF($D$46:$AY$46,$GC$5,D10:AY10) -> 0 | GD10: =SUMIF($D$46:$AY$46,$GD$5,D10:AY10) -> 0 | GE10: =SUMIF($D$46:$AY$46,$GE$5,D10:AY10) -> 105000 | GF10: =SUMIF($D$46:$AY$46,$GF$5,D10:AY10) -> 6825000 | GG10: =SUMIF($D$46:$AY$46,$GG$5,D10:AY10) -> 4025700 | GH10: =SUMIF($D$46:$AY$46,$GH$5,D10:AY10) -> 88022700 | GI10: =SUMIF($D$46:$AY$46,$GI$5,D10:AY10) -> 420 | GJ10: =SUMIF($D$46:$AY$46,$GJ$5,D10:AY10) -> 10300 | GK10: =SUMIF($D$46:$AY$46,$GK$5,D10:AY10) -> 0 | GL10: =SUMIF($D$46:$AY$46,$GL$5,D10:AY10) -> 0 | GM10: =SUMIF($D$46:$AY$46,$GM$5,D10:AY10) -> 7060 | GN10: =SUMIF($D$46:$AY$46,$GN$5,D10:AY10) -> 173940 | GO10: =SUM(GC10,GE10,GG10,GI10,GK10,GM10) -> 4138180 | GP10: =SUM(GD10,GF10,GH10,GJ10,GL10,GN10) -> 95031940 | GR10: =SUMIF($AZ$46:$CU$46,$GR$5,AZ10:CU10) -> 0 | GS10: =SUMIF($AZ$46:$CU$46,$GS$5,AZ10:CU10) -> 0 | GT10: =SUMIF($AZ$46:$CU$46,$GT$5,AZ10:CU10) -> 109000 | GU10: =SUMIF($AZ$46:$CU$46,$GU$5,AZ10:CU10) -> 7085000 | GV10: =SUMIF($AZ$46:$CU$46,$GV$5,AZ10:CU10) -> 4329200 | GW10: =SUMIF($AZ$46:$CU$46,$GW$5,AZ10:CU10) -> 95119800 | GX10: =SUMIF($AZ$46:$CU$46,$GX$5,AZ10:CU10) -> 550 | GY10: =SUMIF($AZ$46:$CU$46,$GY$5,AZ10:CU10) -> 13200 | GZ10: =SUMIF($AZ$46:$CU$46,$GZ$5,AZ10:CU10) -> 0 | HA10: =SUMIF($AZ$46:$CU$46,$HA$5,AZ10:CU10) -> 0 | HB10: =SUMIF($AZ$46:$CU$46,$HB$5,AZ10:CU10) -> 8990 | HC10: =SUMIF($AZ$46:$CU$46,$HC$5,AZ10:CU10) -> 215760 | HD10: =SUM(GR10,GT10,GV10,GX10,GZ10,HB10) -> 4447740 | HE10: =SUM(GS10,GU10,GW10,GY10,HA10,HC10) -> 102433760 | HG10: =SUMIF($CV$46:$EK$46,$HG$5,CV10:EK10) -> 0 | HH10: =SUMIF($CV$46:$EK$46,$HH$5,CV10:EK10) -> 0 | HI10: =SUMIF($CV$46:$EK$46,$HI$5,CV10:EK10) -> 112800 | HJ10: =SUMIF($CV$46:$EK$46,$HJ$5,CV10:EK10) -> 7332000 | HK10: =SUMIF($CV$46:$EK$46,$HK$5,CV10:EK10) -> 4160200 | HL10: =SUMIF($CV$46:$EK$46,$HL$5,CV10:EK10) -> 93506500 | HM10: =SUMIF($CV$46:$EK$46,$HM$5,CV10:EK10) -> 470 | HN10: =SUMIF($CV$46:$EK$46,$HN$5,CV10:EK10) -> 11280 | HO10: =SUMIF($CV$46:$EK$46,$HO$5,CV10:EK10) -> 0 | HP10: =SUMIF($CV$46:$EK$46,$HP$5,CV10:EK10) -> 0 | HQ10: =SUMIF($CV$46:$EK$46,$HQ$5,CV10:EK10) -> 6390 | HR10: =SUMIF($CV$46:$EK$46,$HR$5,CV10:EK10) -> 153360 | HS10: =SUM(HG10,HI10,HK10,HM10,HO10,HQ10) -> 4279860 | HT10: =SUM(HH10,HJ10,HL10,HN10,HP10,HR10) -> 101003140 | HV10: =SUMIF($EL$46:$GA$46,$HV$5,EL10:GA10) -> 0 | HW10: =SUMIF($EL$46:$GA$46,$HW$5,EL10:GA10) -> 0 | HX10: =SUMIF($EL$46:$GA$46,$HX$5,EL10:GA10) -> 109300 | HY10: =SUMIF($EL$46:$GA$46,$HY$5,EL10:GA10) -> 7104500 | HZ10: =SUMIF($EL$46:$GA$46,$HZ$5,EL10:GA10) -> 4755200 | IA10: =SUMIF($EL$46:$GA$46,$IA$5,EL10:GA10) -> 108463100 | IB10: =SUMIF($EL$46:$GA$46,$IB$5,EL10:GA10) -> 380 | IC10: =SUMIF($EL$46:$GA$46,$IC$5,EL10:GA10) -> 9120 | ID10: =SUMIF($EL$46:$GA$46,$ID$5,EL10:GA10) -> 0 | IE10: =SUMIF($EL$46:$GA$46,$IE$5,EL10:GA10) -> 0 | IF10: =SUMIF($EL$46:$GA$46,$IF$5,EL10:GA10) -> 5765 | IG10: =SUMIF($EL$46:$GA$46,$IG$5,EL10:GA10) -> 138360 | IH10: =SUM(HV10,HX10,HZ10,IB10,ID10,IF10) -> 4870645 | II10: =SUM(HW10,HY10,IA10,IC10,IE10,IG10) -> 115715080
A11: KABUPATEN BOJONEGORO | B11: =SUMIF($D$5:$GA$5,$B$5,D11:GA11) -> 5384128 | C11: =SUMIF($D$5:$GA$5,$C$5,D11:GA11) -> 1.0786123e+08 | D11: ='P & NP'!AY13 -> 0 | E11: ='P & NP'!AZ13 -> 0 | F11: ='P & NP'!BA13 -> 0 | G11: ='P & NP'!BB13 -> 0 | H11: ='P & NP'!BC13 -> 0 | I11: ='P & NP'!BD13 -> 0 | J11: ='P & NP'!BE13 -> 537648 | K11: ='P & NP'!BF13 -> 10724879 | ... Q11: ='P & NP'!BL13 -> 66721 | R11: =SUM(D11,F11,J11,L11,N11,P11) -> 566063 | S11: =SUM(E11,G11,K11,M11,O11,Q11) -> 11217179 | T11: ='P & NP'!AY51 -> 0 | U11: ='P & NP'!AZ51 -> 0 | V11: ='P & NP'!BA51 -> 0 | W11: ='P & NP'!BB51 -> 0 | X11: ='P & NP'!BC51 -> 0 | Y11: ='P & NP'!BD51 -> 0 | Z11: ='P & NP'!BE51 -> 516246 | AA11: ='P & NP'!BF51 -> 10341892 | ... AG11: ='P & NP'!BL51 -> 72480 | AH11: =SUM(T11,V11,Z11,AB11,AD11,AF11) -> 540145 | AI11: =SUM(U11,W11,AA11,AC11,AE11,AG11) -> 10774344 | AJ11: ='P & NP'!AY89 -> 0 | AK11: ='P & NP'!AZ89 -> 0 | AL11: ='P & NP'!BA89 -> 0 | AM11: ='P & NP'!BB89 -> 0 | AN11: ='P & NP'!BC89 -> 0 | AO11: ='P & NP'!BD89 -> 0 | AP11: ='P & NP'!BE89 -> 488845 | AQ11: ='P & NP'!BF89 -> 9843470 | ... AW11: ='P & NP'!BL89 -> 54730 | AX11: =SUM(AJ11,AL11,AP11,AR11,AT11,AV11) -> 504827 | AY11: =SUM(AK11,AM11,AQ11,AS11,AU11,AW11) -> 10163396 | AZ11: ='P & NP'!AY127 -> 0 | BA11: ='P & NP'!AZ127 -> 0 | BB11: ='P & NP'!BA127 -> 0 | BC11: ='P & NP'!BB127 -> 0 | BD11: ='P & NP'!BC127 -> 0 | BE11: ='P & NP'!BD127 -> 0 | BF11: ='P & NP'!BE127 -> 447886 | BG11: ='P & NP'!BF127 -> 9068208 | ... BM11: ='P & NP'!BL127 -> 46451 | BN11: =SUM(AZ11,BB11,BF11,BH11,BJ11,BL11) -> 460570 | BO11: =SUM(BA11,BC11,BG11,BI11,BK11,BM11) -> 9336227 | BP11: ='P & NP'!AY165 -> 0 | BQ11: ='P & NP'!AZ165 -> 0 | BR11: ='P & NP'!BA165 -> 0 | BS11: ='P & NP'!BB165 -> 0 | BT11: ='P & NP'!BC165 -> 0 | BU11: ='P & NP'!BD165 -> 0 | BV11: ='P & NP'!BE165 -> 412161 | BW11: ='P & NP'!BF165 -> 8371618 | ... CC11: ='P & NP'!BL165 -> 28040 | CD11: =SUM(BP11,BR11,BV11,BX11,BZ11,CB11) -> 422380 | CE11: =SUM(BQ11,BS11,BW11,BY11,CA11,CC11) -> 8592767 | CF11: ='P & NP'!AY203 -> 0 | CG11: ='P & NP'!AZ203 -> 0 | CH11: ='P & NP'!BA203 -> 0 | CI11: ='P & NP'!BB203 -> 0 | CJ11: ='P & NP'!BC203 -> 0 | CK11: ='P & NP'!BD203 -> 0 | CL11: ='P & NP'!BE203 -> 378066 | CM11: ='P & NP'!BF203 -> 7683089 | ... CS11: ='P & NP'!BL203 -> 20675 | CT11: =SUM(CF11,CH11,CL11,CN11,CP11,CR11) -> 383756 | CU11: =SUM(CG11,CI11,CM11,CO11,CQ11,CS11) -> 7815514 | CV11: ='P & NP'!AY241 -> 0 | CW11: ='P & NP'!AZ241 -> 0 | CX11: ='P & NP'!BA241 -> 0 | CY11: ='P & NP'!BB241 -> 0 | CZ11: ='P & NP'!BE241 -> 330496 | DA11: ='P & NP'!BF241 -> 6763176 | DB11: ='P & NP'!BG241 -> 323 | DC11: ='P & NP'!BH241 -> 8075 | DD11: ='P & NP'!BI241 -> 0 | DE11: ='P & NP'!BJ241 -> 0 | DF11: ='P & NP'!BK241 -> 765 | DG11: ='P & NP'!BL241 -> 12645 | DH11: =SUM(CV11,CX11,CZ11,DB11,DD11,DF11) -> 331584 | DI11: =SUM(CW11,CY11,DA11,DC11,DE11,DG11) -> 6783896 | DJ11: ='P & NP'!AY279 -> 0 | DK11: ='P & NP'!AZ279 -> 0 | DL11: ='P & NP'!BA279 -> 0 | DM11: ='P & NP'!BB279 -> 0 | DN11: ='P & NP'!BE279 -> 344298 | DO11: ='P & NP'!BF279 -> 6999497 | DP11: ='P & NP'!BG279 -> 412 | DQ11: ='P & NP'!BH279 -> 10300 | DR11: ='P & NP'!BI279 -> 0 | DS11: ='P & NP'!BJ279 -> 0 | DT11: ='P & NP'!BK279 -> 943 | DU11: ='P & NP'!BL279 -> 16900 | DV11: =SUM(DJ11,DL11,DN11,DP11,DR11,DT11) -> 345653 | DW11: =SUM(DK11,DM11,DO11,DQ11,DS11,DU11) -> 7026697 | DX11: ='P & NP'!AY317 -> 0 | DY11: ='P & NP'!AZ317 -> 0 | DZ11: ='P & NP'!BA317 -> 0 | EA11: ='P & NP'!BB317 -> 0 | EB11: ='P & NP'!BE317 -> 384462 | EC11: ='P & NP'!BF317 -> 7658808.5 | ED11: ='P & NP'!BG317 -> 568 | EE11: ='P & NP'!BH317 -> 14200 | EF11: ='P & NP'!BI317 -> 0 | EG11: ='P & NP'!BJ317 -> 0 | EH11: ='P & NP'!BK317 -> 1555 | EI11: ='P & NP'!BL317 -> 25495 | EJ11: =SUM(DX11,DZ11,EB11,ED11,EF11,EH11) -> 386585 | EK11: =SUM(DY11,EA11,EC11,EE11,EG11,EI11) -> 7698503.5 | EL11: ='P & NP'!AY355 -> 0 | EM11: ='P & NP'!AZ355 -> 0 | EN11: ='P & NP'!BA355 -> 0 | EO11: ='P & NP'!BB355 -> 0 | EP11: ='P & NP'!BE355 -> 418951 | EQ11: ='P & NP'!BF355 -> 8330310 | ER11: ='P & NP'!BG355 -> 846 | ES11: ='P & NP'!BH355 -> 19275 | ET11: ='P & NP'!BI355 -> 0 | EU11: ='P & NP'!BJ355 -> 0 | EV11: ='P & NP'!BK355 -> 2799 | EW11: ='P & NP'!BL355 -> 45577 | EX11: =SUM(EL11,EN11,EP11,ER11,ET11,EV11) -> 422596 | EY11: =SUM(EM11,EO11,EQ11,ES11,EU11,EW11) -> 8395162 | EZ11: ='P & NP'!AY393 -> 0 | FA11: ='P & NP'!AZ393 -> 0 | FB11: ='P & NP'!BA393 -> 0 | FC11: ='P & NP'!BB393 -> 0 | FD11: ='P & NP'!BE393 -> 500677 | FE11: ='P & NP'!BF393 -> 9860077 | FF11: ='P & NP'!BG393 -> 1129 | FG11: ='P & NP'!BH393 -> 26080 | FH11: ='P & NP'!BI393 -> 0 | FI11: ='P & NP'!BJ393 -> 0 | FJ11: ='P & NP'!BK393 -> 3811 | FK11: ='P & NP'!BL393 -> 61485 | FL11: =SUM(EZ11,FB11,FD11,FF11,FH11,FJ11) -> 505617 | FM11: =SUM(FA11,FC11,FE11,FG11,FI11,FK11) -> 9947642 | FN11: ='P & NP'!AY431 -> 0 | FO11: ='P & NP'!AZ431 -> 0 | FP11: ='P & NP'!BA431 -> 0 | FQ11: ='P & NP'!BB431 -> 0 | FR11: ='P & NP'!BE431 -> 508669 | FS11: ='P & NP'!BF431 -> 10011381 | FT11: ='P & NP'!BG431 -> 1117 | FU11: ='P & NP'!BH431 -> 25495 | FV11: ='P & NP'!BI431 -> 0 | FW11: ='P & NP'!BJ431 -> 0 | FX11: ='P & NP'!BK431 -> 4566 | FY11: ='P & NP'!BL431 -> 73024 | FZ11: =SUM(FN11,FP11,FR11,FT11,FV11,FX11) -> 514352 | GA11: =SUM(FO11,FQ11,FS11,FU11,FW11,FY11) -> 10109900 | GC11: =SUMIF($D$46:$AY$46,$GC$5,D11:AY11) -> 0 | GD11: =SUMIF($D$46:$AY$46,$GD$5,D11:AY11) -> 0 | GE11: =SUMIF($D$46:$AY$46,$GE$5,D11:AY11) -> 0 | GF11: =SUMIF($D$46:$AY$46,$GF$5,D11:AY11) -> 0 | GG11: =SUMIF($D$46:$AY$46,$GG$5,D11:AY11) -> 1542739 | GH11: =SUMIF($D$46:$AY$46,$GH$5,D11:AY11) -> 30910241 | GI11: =SUMIF($D$46:$AY$46,$GI$5,D11:AY11) -> 56772 | GJ11: =SUMIF($D$46:$AY$46,$GJ$5,D11:AY11) -> 1050747 | GK11: =SUMIF($D$46:$AY$46,$GK$5,D11:AY11) -> 0 | GL11: =SUMIF($D$46:$AY$46,$GL$5,D11:AY11) -> 0 | GM11: =SUMIF($D$46:$AY$46,$GM$5,D11:AY11) -> 11524 | GN11: =SUMIF($D$46:$AY$46,$GN$5,D11:AY11) -> 193931 | GO11: =SUM(GC11,GE11,GG11,GI11,GK11,GM11) -> 1611035 | GP11: =SUM(GD11,GF11,GH11,GJ11,GL11,GN11) -> 32154919 | GR11: =SUMIF($AZ$46:$CU$46,$GR$5,AZ11:CU11) -> 0 | GS11: =SUMIF($AZ$46:$CU$46,$GS$5,AZ11:CU11) -> 0 | GT11: =SUMIF($AZ$46:$CU$46,$GT$5,AZ11:CU11) -> 0 | GU11: =SUMIF($AZ$46:$CU$46,$GU$5,AZ11:CU11) -> 0 | GV11: =SUMIF($AZ$46:$CU$46,$GV$5,AZ11:CU11) -> 1238113 | GW11: =SUMIF($AZ$46:$CU$46,$GW$5,AZ11:CU11) -> 25122915 | GX11: =SUMIF($AZ$46:$CU$46,$GX$5,AZ11:CU11) -> 23055 | GY11: =SUMIF($AZ$46:$CU$46,$GY$5,AZ11:CU11) -> 526427 | GZ11: =SUMIF($AZ$46:$CU$46,$GZ$5,AZ11:CU11) -> 0 | HA11: =SUMIF($AZ$46:$CU$46,$HA$5,AZ11:CU11) -> 0 | HB11: =SUMIF($AZ$46:$CU$46,$HB$5,AZ11:CU11) -> 5538 | HC11: =SUMIF($AZ$46:$CU$46,$HC$5,AZ11:CU11) -> 95166 | HD11: =SUM(GR11,GT11,GV11,GX11,GZ11,HB11) -> 1266706 | HE11: =SUM(GS11,GU11,GW11,GY11,HA11,HC11) -> 25744508 | HG11: =SUMIF($CV$46:$EK$46,$HG$5,CV11:EK11) -> 0 | HH11: =SUMIF($CV$46:$EK$46,$HH$5,CV11:EK11) -> 0 | HI11: =SUMIF($CV$46:$EK$46,$HI$5,CV11:EK11) -> 0 | HJ11: =SUMIF($CV$46:$EK$46,$HJ$5,CV11:EK11) -> 0 | HK11: =SUMIF($CV$46:$EK$46,$HK$5,CV11:EK11) -> 1059256 | HL11: =SUMIF($CV$46:$EK$46,$HL$5,CV11:EK11) -> 21421482 | HM11: =SUMIF($CV$46:$EK$46,$HM$5,CV11:EK11) -> 1303 | HN11: =SUMIF($CV$46:$EK$46,$HN$5,CV11:EK11) -> 32575 | HO11: =SUMIF($CV$46:$EK$46,$HO$5,CV11:EK11) -> 0 | HP11: =SUMIF($CV$46:$EK$46,$HP$5,CV11:EK11) -> 0 | HQ11: =SUMIF($CV$46:$EK$46,$HQ$5,CV11:EK11) -> 3263 | HR11: =SUMIF($CV$46:$EK$46,$HR$5,CV11:EK11) -> 55040 | HS11: =SUM(HG11,HI11,HK11,HM11,HO11,HQ11) -> 1063822 | HT11: =SUM(HH11,HJ11,HL11,HN11,HP11,HR11) -> 21509096 | HV11: =SUMIF($EL$46:$GA$46,$HV$5,EL11:GA11) -> 0 | HW11: =SUMIF($EL$46:$GA$46,$HW$5,EL11:GA11) -> 0 | HX11: =SUMIF($EL$46:$GA$46,$HX$5,EL11:GA11) -> 0 | HY11: =SUMIF($EL$46:$GA$46,$HY$5,EL11:GA11) -> 0 | HZ11: =SUMIF($EL$46:$GA$46,$HZ$5,EL11:GA11) -> 1428297 | IA11: =SUMIF($EL$46:$GA$46,$IA$5,EL11:GA11) -> 28201768 | IB11: =SUMIF($EL$46:$GA$46,$IB$5,EL11:GA11) -> 3092 | IC11: =SUMIF($EL$46:$GA$46,$IC$5,EL11:GA11) -> 70850 | ID11: =SUMIF($EL$46:$GA$46,$ID$5,EL11:GA11) -> 0 | IE11: =SUMIF($EL$46:$GA$46,$IE$5,EL11:GA11) -> 0 | IF11: =SUMIF($EL$46:$GA$46,$IF$5,EL11:GA11) -> 11176 | IG11: =SUMIF($EL$46:$GA$46,$IG$5,EL11:GA11) -> 180086 | IH11: =SUM(HV11,HX11,HZ11,IB11,ID11,IF11) -> 1442565 | II11: =SUM(HW11,HY11,IA11,IC11,IE11,IG11) -> 28452704
A12: KABUPATEN BONDOWOSO | B12: =SUMIF($D$5:$GA$5,$B$5,D12:GA12) -> 849316 | C12: =SUMIF($D$5:$GA$5,$C$5,D12:GA12) -> 18251469 | D12: ='P & NP'!BO13 -> 0 | E12: ='P & NP'!BP13 -> 0 | F12: ='P & NP'!BQ13 -> 0 | G12: ='P & NP'!BR13 -> 0 | H12: ='P & NP'!BS13 -> 0 | I12: ='P & NP'!BT13 -> 0 | J12: ='P & NP'!BU13 -> 75492 | K12: ='P & NP'!BV13 -> 1625994 | ... Q12: ='P & NP'!CB13 -> 0 | R12: =SUM(D12,F12,J12,L12,N12,P12) -> 75492 | S12: =SUM(E12,G12,K12,M12,O12,Q12) -> 1625994 | T12: ='P & NP'!BO51 -> 0 | U12: ='P & NP'!BP51 -> 0 | V12: ='P & NP'!BQ51 -> 0 | W12: ='P & NP'!BR51 -> 0 | X12: ='P & NP'!BS51 -> 0 | Y12: ='P & NP'!BT51 -> 0 | Z12: ='P & NP'!BU51 -> 72229 | AA12: ='P & NP'!BV51 -> 1545611 | ... AG12: ='P & NP'!CB51 -> 0 | AH12: =SUM(T12,V12,Z12,AB12,AD12,AF12) -> 72229 | AI12: =SUM(U12,W12,AA12,AC12,AE12,AG12) -> 1545611 | AJ12: ='P & NP'!BO89 -> 0 | AK12: ='P & NP'!BP89 -> 0 | AL12: ='P & NP'!BQ89 -> 0 | AM12: ='P & NP'!BR89 -> 0 | AN12: ='P & NP'!BS89 -> 0 | AO12: ='P & NP'!BT89 -> 0 | AP12: ='P & NP'!BU89 -> 78873 | AQ12: ='P & NP'!BV89 -> 1699424 | ... AW12: ='P & NP'!CB89 -> 0 | AX12: =SUM(AJ12,AL12,AP12,AR12,AT12,AV12) -> 78873 | AY12: =SUM(AK12,AM12,AQ12,AS12,AU12,AW12) -> 1699424 | AZ12: ='P & NP'!BO127 -> 0 | BA12: ='P & NP'!BP127 -> 0 | BB12: ='P & NP'!BQ127 -> 0 | BC12: ='P & NP'!BR127 -> 0 | BD12: ='P & NP'!BS127 -> 0 | BE12: ='P & NP'!BT127 -> 0 | BF12: ='P & NP'!BU127 -> 70170 | BG12: ='P & NP'!BV127 -> 1504428 | ... BM12: ='P & NP'!CB127 -> 0 | BN12: =SUM(AZ12,BB12,BF12,BH12,BJ12,BL12) -> 70170 | BO12: =SUM(BA12,BC12,BG12,BI12,BK12,BM12) -> 1504428 | BP12: ='P & NP'!BO165 -> 0 | BQ12: ='P & NP'!BP165 -> 0 | BR12: ='P & NP'!BQ165 -> 0 | BS12: ='P & NP'!BR165 -> 0 | BT12: ='P & NP'!BS165 -> 0 | BU12: ='P & NP'!BT165 -> 0 | BV12: ='P & NP'!BU165 -> 66314 | BW12: ='P & NP'!BV165 -> 1423961 | ... CC12: ='P & NP'!CB165 -> 0 | CD12: =SUM(BP12,BR12,BV12,BX12,BZ12,CB12) -> 66314 | CE12: =SUM(BQ12,BS12,BW12,BY12,CA12,CC12) -> 1423961 | CF12: ='P & NP'!BO203 -> 0 | CG12: ='P & NP'!BP203 -> 0 | CH12: ='P & NP'!BQ203 -> 0 | CI12: ='P & NP'!BR203 -> 0 | CJ12: ='P & NP'!BS203 -> 0 | CK12: ='P & NP'!BT203 -> 0 | CL12: ='P & NP'!BU203 -> 70069 | CM12: ='P & NP'!BV203 -> 1503581 | ... CS12: ='P & NP'!CB203 -> 0 | CT12: =SUM(CF12,CH12,CL12,CN12,CP12,CR12) -> 70069 | CU12: =SUM(CG12,CI12,CM12,CO12,CQ12,CS12) -> 1503581 | CV12: ='P & NP'!BO241 -> 0 | CW12: ='P & NP'!BP241 -> 0 | CX12: ='P & NP'!BQ241 -> 0 | CY12: ='P & NP'!BR241 -> 0 | CZ12: ='P & NP'!BU241 -> 67283 | DA12: ='P & NP'!BV241 -> 1442655 | DB12: ='P & NP'!BW241 -> 0 | DC12: ='P & NP'!BX241 -> 0 | DD12: ='P & NP'!BY241 -> 0 | DE12: ='P & NP'!BZ241 -> 0 | DF12: ='P & NP'!CA241 -> 0 | DG12: ='P & NP'!CB241 -> 0 | DH12: =SUM(CV12,CX12,CZ12,DB12,DD12,DF12) -> 67283 | DI12: =SUM(CW12,CY12,DA12,DC12,DE12,DG12) -> 1442655 | DJ12: ='P & NP'!BO279 -> 0 | DK12: ='P & NP'!BP279 -> 0 | DL12: ='P & NP'!BQ279 -> 0 | DM12: ='P & NP'!BR279 -> 0 | DN12: ='P & NP'!BU279 -> 69232 | DO12: ='P & NP'!BV279 -> 1488475 | DP12: ='P & NP'!BW279 -> 0 | DQ12: ='P & NP'!BX279 -> 0 | DR12: ='P & NP'!BY279 -> 0 | DS12: ='P & NP'!BZ279 -> 0 | DT12: ='P & NP'!CA279 -> 0 | DU12: ='P & NP'!CB279 -> 0 | DV12: =SUM(DJ12,DL12,DN12,DP12,DR12,DT12) -> 69232 | DW12: =SUM(DK12,DM12,DO12,DQ12,DS12,DU12) -> 1488475 | DX12: ='P & NP'!BO317 -> 0 | DY12: ='P & NP'!BP317 -> 0 | DZ12: ='P & NP'!BQ317 -> 0 | EA12: ='P & NP'!BR317 -> 0 | EB12: ='P & NP'!BU317 -> 66202 | EC12: ='P & NP'!BV317 -> 1421964 | ED12: ='P & NP'!BW317 -> 0 | EE12: ='P & NP'!BX317 -> 0 | EF12: ='P & NP'!BY317 -> 0 | EG12: ='P & NP'!BZ317 -> 0 | EH12: ='P & NP'!CA317 -> 0 | EI12: ='P & NP'!CB317 -> 0 | EJ12: =SUM(DX12,DZ12,EB12,ED12,EF12,EH12) -> 66202 | EK12: =SUM(DY12,EA12,EC12,EE12,EG12,EI12) -> 1421964 | EL12: ='P & NP'!BO355 -> 0 | EM12: ='P & NP'!BP355 -> 0 | EN12: ='P & NP'!BQ355 -> 0 | EO12: ='P & NP'!BR355 -> 0 | EP12: ='P & NP'!BU355 -> 67037 | EQ12: ='P & NP'!BV355 -> 1437315 | ER12: ='P & NP'!BW355 -> 0 | ES12: ='P & NP'!BX355 -> 0 | ET12: ='P & NP'!BY355 -> 0 | EU12: ='P & NP'!BZ355 -> 0 | EV12: ='P & NP'!CA355 -> 0 | EW12: ='P & NP'!CB355 -> 0 | EX12: =SUM(EL12,EN12,EP12,ER12,ET12,EV12) -> 67037 | EY12: =SUM(EM12,EO12,EQ12,ES12,EU12,EW12) -> 1437315 | EZ12: ='P & NP'!BO393 -> 0 | FA12: ='P & NP'!BP393 -> 0 | FB12: ='P & NP'!BQ393 -> 0 | FC12: ='P & NP'!BR393 -> 0 | FD12: ='P & NP'!BU393 -> 67907 | FE12: ='P & NP'!BV393 -> 1458717 | FF12: ='P & NP'!BW393 -> 0 | FG12: ='P & NP'!BX393 -> 0 | FH12: ='P & NP'!BY393 -> 0 | FI12: ='P & NP'!BZ393 -> 0 | FJ12: ='P & NP'!CA393 -> 0 | FK12: ='P & NP'!CB393 -> 0 | FL12: =SUM(EZ12,FB12,FD12,FF12,FH12,FJ12) -> 67907 | FM12: =SUM(FA12,FC12,FE12,FG12,FI12,FK12) -> 1458717 | FN12: ='P & NP'!BO431 -> 0 | FO12: ='P & NP'!BP431 -> 0 | FP12: ='P & NP'!BQ431 -> 0 | FQ12: ='P & NP'!BR431 -> 0 | FR12: ='P & NP'!BU431 -> 78508 | FS12: ='P & NP'!BV431 -> 1699344 | FT12: ='P & NP'!BW431 -> 0 | FU12: ='P & NP'!BX431 -> 0 | FV12: ='P & NP'!BY431 -> 0 | FW12: ='P & NP'!BZ431 -> 0 | FX12: ='P & NP'!CA431 -> 0 | FY12: ='P & NP'!CB431 -> 0 | FZ12: =SUM(FN12,FP12,FR12,FT12,FV12,FX12) -> 78508 | GA12: =SUM(FO12,FQ12,FS12,FU12,FW12,FY12) -> 1699344 | GC12: =SUMIF($D$46:$AY$46,$GC$5,D12:AY12) -> 0 | GD12: =SUMIF($D$46:$AY$46,$GD$5,D12:AY12) -> 0 | GE12: =SUMIF($D$46:$AY$46,$GE$5,D12:AY12) -> 0 | GF12: =SUMIF($D$46:$AY$46,$GF$5,D12:AY12) -> 0 | GG12: =SUMIF($D$46:$AY$46,$GG$5,D12:AY12) -> 226594 | GH12: =SUMIF($D$46:$AY$46,$GH$5,D12:AY12) -> 4871029 | GI12: =SUMIF($D$46:$AY$46,$GI$5,D12:AY12) -> 0 | GJ12: =SUMIF($D$46:$AY$46,$GJ$5,D12:AY12) -> 0 | GK12: =SUMIF($D$46:$AY$46,$GK$5,D12:AY12) -> 0 | GL12: =SUMIF($D$46:$AY$46,$GL$5,D12:AY12) -> 0 | GM12: =SUMIF($D$46:$AY$46,$GM$5,D12:AY12) -> 0 | GN12: =SUMIF($D$46:$AY$46,$GN$5,D12:AY12) -> 0 | GO12: =SUM(GC12,GE12,GG12,GI12,GK12,GM12) -> 226594 | GP12: =SUM(GD12,GF12,GH12,GJ12,GL12,GN12) -> 4871029 | GR12: =SUMIF($AZ$46:$CU$46,$GR$5,AZ12:CU12) -> 0 | GS12: =SUMIF($AZ$46:$CU$46,$GS$5,AZ12:CU12) -> 0 | GT12: =SUMIF($AZ$46:$CU$46,$GT$5,AZ12:CU12) -> 0 | GU12: =SUMIF($AZ$46:$CU$46,$GU$5,AZ12:CU12) -> 0 | GV12: =SUMIF($AZ$46:$CU$46,$GV$5,AZ12:CU12) -> 206553 | GW12: =SUMIF($AZ$46:$CU$46,$GW$5,AZ12:CU12) -> 4431970 | GX12: =SUMIF($AZ$46:$CU$46,$GX$5,AZ12:CU12) -> 0 | GY12: =SUMIF($AZ$46:$CU$46,$GY$5,AZ12:CU12) -> 0 | GZ12: =SUMIF($AZ$46:$CU$46,$GZ$5,AZ12:CU12) -> 0 | HA12: =SUMIF($AZ$46:$CU$46,$HA$5,AZ12:CU12) -> 0 | HB12: =SUMIF($AZ$46:$CU$46,$HB$5,AZ12:CU12) -> 0 | HC12: =SUMIF($AZ$46:$CU$46,$HC$5,AZ12:CU12) -> 0 | HD12: =SUM(GR12,GT12,GV12,GX12,GZ12,HB12) -> 206553 | HE12: =SUM(GS12,GU12,GW12,GY12,HA12,HC12) -> 4431970 | HG12: =SUMIF($CV$46:$EK$46,$HG$5,CV12:EK12) -> 0 | HH12: =SUMIF($CV$46:$EK$46,$HH$5,CV12:EK12) -> 0 | HI12: =SUMIF($CV$46:$EK$46,$HI$5,CV12:EK12) -> 0 | HJ12: =SUMIF($CV$46:$EK$46,$HJ$5,CV12:EK12) -> 0 | HK12: =SUMIF($CV$46:$EK$46,$HK$5,CV12:EK12) -> 202717 | HL12: =SUMIF($CV$46:$EK$46,$HL$5,CV12:EK12) -> 4353094 | HM12: =SUMIF($CV$46:$EK$46,$HM$5,CV12:EK12) -> 0 | HN12: =SUMIF($CV$46:$EK$46,$HN$5,CV12:EK12) -> 0 | HO12: =SUMIF($CV$46:$EK$46,$HO$5,CV12:EK12) -> 0 | HP12: =SUMIF($CV$46:$EK$46,$HP$5,CV12:EK12) -> 0 | HQ12: =SUMIF($CV$46:$EK$46,$HQ$5,CV12:EK12) -> 0 | HR12: =SUMIF($CV$46:$EK$46,$HR$5,CV12:EK12) -> 0 | HS12: =SUM(HG12,HI12,HK12,HM12,HO12,HQ12) -> 202717 | HT12: =SUM(HH12,HJ12,HL12,HN12,HP12,HR12) -> 4353094 | HV12: =SUMIF($EL$46:$GA$46,$HV$5,EL12:GA12) -> 0 | HW12: =SUMIF($EL$46:$GA$46,$HW$5,EL12:GA12) -> 0 | HX12: =SUMIF($EL$46:$GA$46,$HX$5,EL12:GA12) -> 0 | HY12: =SUMIF($EL$46:$GA$46,$HY$5,EL12:GA12) -> 0 | HZ12: =SUMIF($EL$46:$GA$46,$HZ$5,EL12:GA12) -> 213452 | IA12: =SUMIF($EL$46:$GA$46,$IA$5,EL12:GA12) -> 4595376 | IB12: =SUMIF($EL$46:$GA$46,$IB$5,EL12:GA12) -> 0 | IC12: =SUMIF($EL$46:$GA$46,$IC$5,EL12:GA12) -> 0 | ID12: =SUMIF($EL$46:$GA$46,$ID$5,EL12:GA12) -> 0 | IE12: =SUMIF($EL$46:$GA$46,$IE$5,EL12:GA12) -> 0 | IF12: =SUMIF($EL$46:$GA$46,$IF$5,EL12:GA12) -> 0 | IG12: =SUMIF($EL$46:$GA$46,$IG$5,EL12:GA12) -> 0 | IH12: =SUM(HV12,HX12,HZ12,IB12,ID12,IF12) -> 213452 | II12: =SUM(HW12,HY12,IA12,IC12,IE12,IG12) -> 4595376
