Workbook

Sheet Daftar Isi
A1: Daftar Tabel | B1: Halaman
A3: ='Unit Usaha'!B47 -> Tabel 1 Jumlah Unit Usaha Aktif berdasarkan Jenis Kegiatan | B3: 1
A4: ='Unit Usaha'!B48 -> Tabel 2 Jumlah Unit Usaha Aktif berdasarkan Jenis Kegiatan Pengolahan | B4: 2
A5: ='Unit Usaha'!B49 -> Tabel 3 Jumlah Unit Usaha Aktif berdasarkan Jenis Kegiatan Pemasaran | B5: 3
A6: ='Unit Usaha'!B50 -> Tabel 4 Jumlah Unit Usaha Aktif berdasarkan Skala Usaha | B6: 4
A7: ='Unit Usaha'!B51 -> Tabel 5 Jumlah Unit Usaha Aktif berdasarkan Skala Usaha pada Kegiatan Pengolahan | B7: 5
A8: ='Unit Usaha'!B52 -> Tabel 6 Jumlah Unit Usaha Aktif berdasarkan Skala Usaha pada Kegiatan Pemasaran | B8: 6
A9: ='Unit Usaha'!B53 -> Tabel 7 Jumlah Unit Usaha Aktif berdasarkan Skala Usaha pada Jenis Kegiatan Fermentasi | B9: 7
A10: ='Unit Usaha'!B54 -> Tabel 8 Jumlah Unit Usaha Aktif berdasarkan Skala Usaha pada Jenis Kegiatan Pelumatan Daging Ikan | B10: 8
A11: ='Unit Usaha'!B55 -> Tabel 9 Jumlah Unit Usaha Aktif berdasarkan Skala Usaha pada Jenis Kegiatan Pembekuan | B11: 9
A12: ='Unit Usaha'!B56 -> Tabel 10 Jumlah Unit Usaha Aktif berdasarkan Skala Usaha pada Jenis Kegiatan Pemindangan | B12: 10
A13: ='Unit Usaha'!B57 -> Tabel 11 Jumlah Unit Usaha Aktif berdasarkan Skala Usaha pada Jenis Kegiatan Penanganan Produk Segar | B13: 11
A14: ='Unit Usaha'!B58 -> Tabel 12 Jumlah Unit Usaha Aktif berdasarkan Skala Usaha pada Jenis Kegiatan Pengalengan | B14: 12
... A20: ='Unit Usaha'!B64 -> Tabel 18 Jumlah Unit Usaha Aktif berdasarkan Skala Usaha pada Jenis Kegiatan Pengecer | B20: 18
A21: =Kapasitas!B47 -> Tabel 19 Jumlah Kapasitas (Kg) berdasarkan Jenis Kegiatan | B21: 19
A22: =Kapasitas!B48 -> Tabel 20 Jumlah Kapasitas (Kg) berdasarkan Jenis Kegiatan Pengolahan | B22: 20
A23: =Kapasitas!B49 -> Tabel 21 Jumlah Kapasitas (Kg) berdasarkan Jenis Kegiatan Pemasaran | B23: 21
A24: =Kapasitas!B50 -> Tabel 22 Jumlah Kapasitas (Kg) berdasarkan Skala Usaha | B24: 22
A25: =Kapasitas!B51 -> Tabel 23 Jumlah Kapasitas (Kg) berdasarkan Skala Usaha pada Kegiatan Pengolahan | B25: 23
A26: =Kapasitas!B52 -> Tabel 24 Jumlah Kapasitas (Kg) berdasarkan Skala Usaha pada Kegiatan Pemasaran | B26: 24
A27: =Kapasitas!B53 -> Tabel 25 Jumlah Kapasitas (Kg) berdasarkan Skala Usaha pada Jenis Kegiatan Fermentasi | B27: 25
A28: =Kapasitas!B54 -> Tabel 26 Jumlah Kapasitas (Kg) berdasarkan Skala Usaha pada Jenis Kegiatan Pelumatan Daging Ikan | B28: 26
A29: =Kapasitas!B55 -> Tabel 27 Jumlah Kapasitas (Kg) berdasarkan Skala Usaha pada Jenis Kegiatan Pembekuan | B29: 27
A30: =Kapasitas!B56 -> Tabel 28 Jumlah Kapasitas (Kg) berdasarkan Skala Usaha pada Jenis Kegiatan Pemindangan | B30: 28
A31: =Kapasitas!B57 -> Tabel 29 Jumlah Kapasitas (Kg) berdasarkan Skala Usaha pada Jenis Kegiatan Penanganan Produk Segar | B31: 29
A32: =Kapasitas!B58 -> Tabel 30 Jumlah Kapasitas (Kg) berdasarkan Skala Usaha pada Jenis Kegiatan Pengalengan | B32: 30
... A38: =Kapasitas!B64 -> Tabel 36 Jumlah Kapasitas (Kg) berdasarkan Skala Usaha pada Jenis Kegiatan Pengecer | B38: 36
A39: =Biaya!B47 -> Tabel 37 Jumlah Biaya (Rp) berdasarkan Jenis Kegiatan | B39: 37
A40: =Biaya!B48 -> Tabel 38 Jumlah Biaya (Rp) berdasarkan Jenis Kegiatan Pengolahan | B40: 38
A41: =Biaya!B49 -> Tabel 39 Jumlah Biaya (Rp) berdasarkan Jenis Kegiatan Pemasaran | B41: 39
A42: =Biaya!B50 -> Tabel 40 Jumlah Biaya (Rp) berdasarkan Skala Usaha | B42: 40
A43: =Biaya!B51 -> Tabel 41 Jumlah Biaya (Rp) berdasarkan Skala Usaha pada Kegiatan Pengolahan | B43: 41
A44: =Biaya!B52 -> Tabel 42 Jumlah Biaya (Rp) berdasarkan Skala Usaha pada Kegiatan Pemasaran | B44: 42
A45: =Biaya!B53 -> Tabel 43 Jumlah Biaya (Rp) berdasarkan Skala Usaha pada Jenis Kegiatan Fermentasi | B45: 43
A46: =Biaya!B54 -> Tabel 44 Jumlah Biaya (Rp) berdasarkan Skala Usaha pada Jenis Kegiatan Pelumatan Daging Ikan | B46: 44
A47: =Biaya!B55 -> Tabel 45 Jumlah Biaya (Rp) berdasarkan Skala Usaha pada Jenis Kegiatan Pembekuan | B47: 45
A48: =Biaya!B56 -> Tabel 46 Jumlah Biaya (Rp) berdasarkan Skala Usaha pada Jenis Kegiatan Pemindangan | B48: 46
A49: =Biaya!B57 -> Tabel 47 Jumlah Biaya (Rp) berdasarkan Skala Usaha pada Jenis Kegiatan Penanganan Produk Segar | B49: 47
A50: =Biaya!B58 -> Tabel 48 Jumlah Biaya (Rp) berdasarkan Skala Usaha pada Jenis Kegiatan Pengalengan | B50: 48
... A56: =Biaya!B64 -> Tabel 54 Jumlah Biaya (Rp) berdasarkan Skala Usaha pada Jenis Kegiatan Pengecer | B56: 54
...

Sheet Unit Usaha
A1: Tabel 1 Jumlah Unit Usaha Aktif berdasarkan Jenis Kegiatan | P1: Tabel 2 Jumlah Unit Usaha Aktif berdasarkan Jenis Kegiatan Pengolahan | AC1: Tabel 3 Jumlah Unit Usaha Aktif berdasarkan Jenis Kegiatan Pemasaran | AH1: Tabel 4 Jumlah Unit Usaha Aktif berdasarkan Skala Usaha | AO1: Tabel 5 Jumlah Unit Usaha Aktif berdasarkan Skala Usaha pada Kegiatan Pengolahan | AV1: Tabel 6 Jumlah Unit Usaha Aktif berdasarkan Skala Usaha pada Kegiatan Pemasaran | BC1: Tabel 7 Jumlah Unit Usaha Aktif berdasarkan Skala Usaha pada Jenis Kegiatan Fermentasi | BJ1: Tabel 8 Jumlah Unit Usaha Aktif berdasarkan Skala Usaha pada Jenis Kegiatan Pelumatan Daging Ikan | BQ1: Tabel 9 Jumlah Unit Usaha Aktif berdasarkan Skala Usaha pada Jenis Kegiatan Pembekuan | BX1: Tabel 10 Jumlah Unit Usaha Aktif berdasarkan Skala Usaha pada Jenis Kegiatan Pemindangan | CE1: Tabel 11 Jumlah Unit Usaha Aktif berdasarkan Skala Usaha pada Jenis Kegiatan Penanganan Produk Segar | CL1: Tabel 12 Jumlah Unit Usaha Aktif berdasarkan Skala Usaha pada Jenis Kegiatan Pengalengan | CS1: Tabel 13 Jumlah Unit Usaha Aktif berdasarkan Skala Usaha pada Jenis Kegiatan Pengasapan / Pemanggangan | CZ1: Tabel 14 Jumlah Unit Usaha Aktif berdasarkan Skala Usaha pada Jenis Kegiatan Penggaraman / Pengeringan | DG1: Tabel 15 Jumlah Unit Usaha Aktif berdasarkan Skala Usaha pada Jenis Kegiatan Pereduksian/Ekstraksi | DN1: Tabel 16 Jumlah Unit Usaha Aktif berdasarkan Skala Usaha pada Jenis Kegiatan Pengolahan Lainnya | DU1: Tabel 17 Jumlah Unit Usaha Aktif berdasarkan Skala Usaha pada Jenis Kegiatan Pengumpul/Pedagang Besar/Distributor | EB1: Tabel 18 Jumlah Unit Usaha Aktif berdasarkan Skala Usaha pada Jenis Kegiatan Pengecer
A2: No | B2: Kabupaten/Kota | C2: Jenis Kegiatan | O2: Jumlah Total | P2: No | Q2: Kabupaten/Kota | R2: Jenis Kegiatan | AB2: Jumlah Total | AC2: No | AD2: Kabupaten/Kota | AE2: Jenis Kegiatan | AG2: Jumlah Total | AH2: No | AI2: Kabupaten/Kota | AJ2: Skala Usaha | AN2: Jumlah Total | AO2: No | AP2: Kabupaten/Kota | AQ2: Skala Usaha | AU2: Jumlah Total | AV2: No | AW2: Kabupaten/Kota | AX2: Skala Usaha | BB2: Jumlah Total | BC2: No | BD2: Kabupaten/Kota | BE2: Skala Usaha | BI2: Jumlah Total | BJ2: No | BK2: Kabupaten/Kota | BL2: Skala Usaha | BP2: Jumlah Total | BQ2: No | BR2: Kabupaten/Kota | BS2: Skala Usaha | BW2: Jumlah Total | BX2: No | BY2: Kabupaten/Kota | BZ2: Skala Usaha | CD2: Jumlah Total | CE2: No | CF2: Kabupaten/Kota | CG2: Skala Usaha | CK2: Jumlah Total | CL2: No | CM2: Kabupaten/Kota | CN2: Skala Usaha | CR2: Jumlah Total | CS2: No | CT2: Kabupaten/Kota | CU2: Skala Usaha | CY2: Jumlah Total | CZ2: No | DA2: Kabupaten/Kota | DB2: Skala Usaha | DF2: Jumlah Total | DG2: No | DH2: Kabupaten/Kota | DI2: Skala Usaha | DM2: Jumlah Total | DN2: No | DO2: Kabupaten/Kota | DP2: Skala Usaha | DT2: Jumlah Total | DU2: No | DV2: Kabupaten/Kota | DW2: Skala Usaha | EA2: Jumlah Total | EB2: No | EC2: Kabupaten/Kota | ED2: Skala Usaha | EH2: Jumlah Total
C3: Fermentasi | D3: Pelumatan Daging Ikan | E3: Pembekuan | F3: Pemindangan | G3: Penanganan Produk Segar | H3: Pengalengan | I3: Pengasapan/ Pemanggangan | J3: Pereduksian/ Ekstraksi | K3: Penggaraman/Pengeringan | L3: Pengolahan Lainnya | M3: Pengecer | N3: Pengumpul/ Pedagang Besar/ Distributor | R3: Fermentasi | S3: Pelumatan Daging Ikan | T3: Pembekuan | U3: Pemindangan | V3: Penanganan Produk Segar | W3: Pengalengan | X3: Pengasapan/ Pemanggangan | Y3: Pereduksian/ Ekstraksi | Z3: Penggaraman/ Pengeringan | AA3: Pengolahan Lainnya | AE3: Pengecer | AF3: Pengumpul/ Pedagang Besar/ Distributor | AJ3: Mikro | AK3: Kecil | AL3: Menengah | AM3: Besar | AQ3: Mikro | AR3: Kecil | AS3: Menengah | AT3: Besar | AX3: Mikro | AY3: Kecil | AZ3: Menengah | BA3: Besar | BE3: Mikro | BF3: Kecil | BG3: Menengah | BH3: Besar | BL3: Mikro | BM3: Kecil | BN3: Menengah | BO3: Besar | BS3: Mikro | BT3: Kecil | BU3: Menengah | BV3: Besar | BZ3: Mikro | CA3: Kecil | CB3: Menengah | CC3: Besar | CG3: Mikro | CH3: Kecil | CI3: Menengah | CJ3: Besar | CN3: Mikro | CO3: Kecil | CP3: Menengah | CQ3: Besar | CU3: Mikro | CV3: Kecil | CW3: Menengah | CX3: Besar | DB3: Mikro | DC3: Kecil | DD3: Menengah | DE3: Besar | DI3: Mikro | DJ3: Kecil | DK3: Menengah | DL3: Besar | DP3: Mikro | DQ3: Kecil | DR3: Menengah | DS3: Besar | DW3: Mikro | DX3: Kecil | DY3: Menengah | DZ3: Besar | ED3: Mikro | EE3: Kecil | EF3: Menengah | EG3: Besar
A4: 01 | B4: KAB. PACITAN | C4: =BI4 -> 25.421186 | D4: =BP4 -> 58.259161 | E4: =BW4 -> 6.1745993 | F4: =CD4 -> 16.245109 | G4: =CK4 -> 196.01507 | H4: =CR4 -> 0 | I4: =CY4 -> 10.89582 | J4: =DM4 -> 5.7032025 | K4: =DF4 -> 48.894989 | L4: =DT4 -> 28.74859 | M4: =EH4 -> 536.7764 | N4: =EA4 -> 24.801538 | O4: =SUM(C4:N4) -> 957.93567 | P4: 01 | Q4: KAB. PACITAN | R4: =C4 -> 25.421186 | S4: =D4 -> 58.259161 | T4: =E4 -> 6.1745993 | U4: =F4 -> 16.245109 | V4: =G4 -> 196.01507 | W4: =H4 -> 0 | X4: =I4 -> 10.89582 | Y4: =J4 -> 5.7032025 | ... AA4: =L4 -> 28.74859 | AB4: =SUM(R4:AA4) -> 396.35773 | AC4: 01 | AD4: KAB. PACITAN | AE4: =M4 -> 536.7764 | AF4: =N4 -> 24.801538 | AG4: =SUM(AE4:AF4) -> 561.57794 | AH4: 01 | AI4: KAB. PACITAN | AJ4: =AQ4+AX4 -> 914.01442 | AK4: =AR4+AY4 -> 41.879905 | AL4: =AS4+AZ4 -> 2.0413391 | AM4: =AT4+BA4 -> 0 | AN4: =SUM(AJ4:AM4) -> 957.93567 | AO4: 01 | AP4: KAB. PACITAN | AQ4: =BE4+BL4+BS4+BZ4+CG4+CN4+CU4+DB4+DI4+DP4 -> 355.50152 | AR4: =BF4+BM4+BT4+CA4+CH4+CO4+CV4+DC4+DJ4+DQ4 -> 38.814868 | AS4: =BG4+BN4+BU4+CB4+CI4+CP4+CW4+DD4+DK4+DR4 -> 2.0413391 | AT4: =BH4+BO4+BV4+CC4+CJ4+CQ4+CX4+DE4+DL4+DS4 -> 0 | AU4: =SUM(AQ4:AT4) -> 396.35773 | AV4: 01 | AW4: KAB. PACITAN | AX4: =DW4+ED4 -> 558.5129 | AY4: =DX4+EE4 -> 3.0650374 | AZ4: =DY4+EF4 -> 0 | BA4: =DZ4+EG4 -> 0 | BB4: =SUM(AX4:BA4) -> 561.57794 | BC4: 01 | BD4: KAB. PACITAN | BE4: 25.421186 | BF4: 0 | BG4: 0 | BH4: 0 | BI4: 25.421186 | BJ4: 01 | BK4: KAB. PACITAN | BL4: 19.444294 | BM4: 36.773529 | BN4: 2.0413391 | BO4: 0 | BP4: 58.259161 | BQ4: 01 | BR4: KAB. PACITAN | BS4: 6.1745993 | BT4: 0 | BU4: 0 | BV4: 0 | BW4: 6.1745993 | BX4: 01 | BY4: KAB. PACITAN | BZ4: 16.245109 | CA4: 0 | CB4: 0 | CC4: 0 | CD4: 16.245109 | CE4: 01 | CF4: KAB. PACITAN | CG4: 193.97373 | CH4: 2.0413391 | CI4: 0 | CJ4: 0 | CK4: 196.01507 | CL4: 01 | CM4: KAB. PACITAN | CN4: 0 | CO4: 0 | CP4: 0 | CQ4: 0 | CR4: 0 | CS4: 01 | CT4: KAB. PACITAN | CU4: 10.89582 | CV4: 0 | CW4: 0 | CX4: 0 | CY4: 10.89582 | CZ4: 01 | DA4: KAB. PACITAN | DB4: 48.894989 | DC4: 0 | DD4: 0 | DE4: 0 | DF4: 48.894989 | DG4: 01 | DH4: KAB. PACITAN | DI4: 5.7032025 | DJ4: 0 | DK4: 0 | DL4: 0 | DM4: 5.7032025 | DN4: 01 | DO4: KAB. PACITAN | DP4: 28.74859 | DQ4: 0 | DR4: 0 | DS4: 0 | DT4: 28.74859 | DU4: 01 | DV4: KAB. PACITAN | DW4: 21.736501 | DX4: 3.0650374 | DY4: 0 | DZ4: 0 | EA4: 24.801538 | EB4: 01 | EC4: KAB. PACITAN | ED4: 536.7764 | EE4: 0 | EF4: 0 | EG4: 0 | EH4: 536.7764
A5: 02 | B5: KAB. PONOROGO | C5: =BI5 -> 0 | D5: =BP5 -> 40.608934 | E5: =BW5 -> 0 | F5: =CD5 -> 0 | G5: =CK5 -> 2.0413391 | H5: =CR5 -> 0 | I5: =CY5 -> 0 | J5: =DM5 -> 0 | K5: =DF5 -> 0 | L5: =DT5 -> 67.844304 | M5: =EH5 -> 747.55517 | N5: =EA5 -> 109.48951 | O5: =SUM(C5:N5) -> 967.53926 | P5: 02 | Q5: KAB. PONOROGO | R5: =C5 -> 0 | S5: =D5 -> 40.608934 | T5: =E5 -> 0 | U5: =F5 -> 0 | V5: =G5 -> 2.0413391 | W5: =H5 -> 0 | X5: =I5 -> 0 | Y5: =J5 -> 0 | ... AA5: =L5 -> 67.844304 | AB5: =SUM(R5:AA5) -> 110.49458 | AC5: 02 | AD5: KAB. PONOROGO | AE5: =M5 -> 747.55517 | AF5: =N5 -> 109.48951 | AG5: =SUM(AE5:AF5) -> 857.04468 | AH5: 02 | AI5: KAB. PONOROGO | AJ5: =AQ5+AX5 -> 901.3512 | AK5: =AR5+AY5 -> 50.560403 | AL5: =AS5+AZ5 -> 15.627658 | AM5: =AT5+BA5 -> 0 | AN5: =SUM(AJ5:AM5) -> 967.53926 | AO5: 02 | AP5: KAB. PONOROGO | AQ5: =BE5+BL5+BS5+BZ5+CG5+CN5+CU5+DB5+DI5+DP5 -> 86.739808 | AR5: =BF5+BM5+BT5+CA5+CH5+CO5+CV5+DC5+DJ5+DQ5 -> 23.754769 | AS5: =BG5+BN5+BU5+CB5+CI5+CP5+CW5+DD5+DK5+DR5 -> 0 | AT5: =BH5+BO5+BV5+CC5+CJ5+CQ5+CX5+DE5+DL5+DS5 -> 0 | AU5: =SUM(AQ5:AT5) -> 110.49458 | AV5: 02 | AW5: KAB. PONOROGO | AX5: =DW5+ED5 -> 814.61139 | AY5: =DX5+EE5 -> 26.805634 | AZ5: =DY5+EF5 -> 15.627658 | BA5: =DZ5+EG5 -> 0 | BB5: =SUM(AX5:BA5) -> 857.04468 | BC5: 02 | BD5: KAB. PONOROGO | BE5: 0 | BF5: 0 | BG5: 0 | BH5: 0 | BI5: 0 | BJ5: 02 | BK5: KAB. PONOROGO | BL5: 25.409813 | BM5: 15.199122 | BN5: 0 | BO5: 0 | BP5: 40.608934 | BQ5: 02 | BR5: KAB. PONOROGO | BS5: 0 | BT5: 0 | BU5: 0 | BV5: 0 | BW5: 0 | BX5: 02 | BY5: KAB. PONOROGO | BZ5: 0 | CA5: 0 | CB5: 0 | CC5: 0 | CD5: 0 | CE5: 02 | CF5: KAB. PONOROGO | CG5: 2.0413391 | CH5: 0 | CI5: 0 | CJ5: 0 | CK5: 2.0413391 | CL5: 02 | CM5: KAB. PONOROGO | CN5: 0 | CO5: 0 | CP5: 0 | CQ5: 0 | CR5: 0 | CS5: 02 | CT5: KAB. PONOROGO | CU5: 0 | CV5: 0 | CW5: 0 | CX5: 0 | CY5: 0 | CZ5: 02 | DA5: KAB. PONOROGO | DB5: 0 | DC5: 0 | DD5: 0 | DE5: 0 | DF5: 0 | DG5: 02 | DH5: KAB. PONOROGO | DI5: 0 | DJ5: 0 | DK5: 0 | DL5: 0 | DM5: 0 | DN5: 02 | DO5: KAB. PONOROGO | DP5: 59.288657 | DQ5: 8.5556475 | DR5: 0 | DS5: 0 | DT5: 67.844304 | DU5: 02 | DV5: KAB. PONOROGO | DW5: 79.558345 | DX5: 14.303508 | DY5: 15.627658 | DZ5: 0 | EA5: 109.48951 | EB5: 02 | EC5: KAB. PONOROGO | ED5: 735.05305 | EE5: 12.502126 | EF5: 0 | EG5: 0 | EH5: 747.55517
A6: 03 | B6: KAB. TRENGGALEK | C6: =BI6 -> 0 | D6: =BP6 -> 41.296251 | E6: =BW6 -> 3.1013295 | F6: =CD6 -> 67.494318 | G6: =CK6 -> 0 | H6: =CR6 -> 0 | I6: =CY6 -> 256.39684 | J6: =DM6 -> 0 | K6: =DF6 -> 56.664275 | L6: =DT6 -> 7.2764943 | M6: =EH6 -> 867.64076 | N6: =EA6 -> 29.648874 | O6: =SUM(C6:N6) -> 1329.5191 | P6: 03 | Q6: KAB. TRENGGALEK | R6: =C6 -> 0 | S6: =D6 -> 41.296251 | T6: =E6 -> 3.1013295 | U6: =F6 -> 67.494318 | V6: =G6 -> 0 | W6: =H6 -> 0 | X6: =I6 -> 256.39684 | Y6: =J6 -> 0 | ... AA6: =L6 -> 7.2764943 | AB6: =SUM(R6:AA6) -> 432.2295 | AC6: 03 | AD6: KAB. TRENGGALEK | AE6: =M6 -> 867.64076 | AF6: =N6 -> 29.648874 | AG6: =SUM(AE6:AF6) -> 897.28964 | AH6: 03 | AI6: KAB. TRENGGALEK | AJ6: =AQ6+AX6 -> 1162.6197 | AK6: =AR6+AY6 -> 117.04578 | AL6: =AS6+AZ6 -> 37.912779 | AM6: =AT6+BA6 -> 11.940924 | AN6: =SUM(AJ6:AM6) -> 1329.5191 | AO6: 03 | AP6: KAB. TRENGGALEK | AQ6: =BE6+BL6+BS6+BZ6+CG6+CN6+CU6+DB6+DI6+DP6 -> 300.53208 | AR6: =BF6+BM6+BT6+CA6+CH6+CO6+CV6+DC6+DJ6+DQ6 -> 87.578216 | AS6: =BG6+BN6+BU6+CB6+CI6+CP6+CW6+DD6+DK6+DR6 -> 33.220131 | AT6: =BH6+BO6+BV6+CC6+CJ6+CQ6+CX6+DE6+DL6+DS6 -> 10.89908 | AU6: =SUM(AQ6:AT6) -> 432.2295 | AV6: 03 | AW6: KAB. TRENGGALEK | AX6: =DW6+ED6 -> 862.08758 | AY6: =DX6+EE6 -> 29.467564 | AZ6: =DY6+EF6 -> 4.6926475 | BA6: =DZ6+EG6 -> 1.0418439 | BB6: =SUM(AX6:BA6) -> 897.28964 | BC6: 03 | BD6: KAB. TRENGGALEK | BE6: 0 | BF6: 0 | BG6: 0 | BH6: 0 | BI6: 0 | BJ6: 03 | BK6: KAB. TRENGGALEK | BL6: 41.296251 | BM6: 0 | BN6: 0 | BO6: 0 | BP6: 41.296251 | BQ6: 03 | BR6: KAB. TRENGGALEK | BS6: 0 | BT6: 0 | BU6: 0 | BV6: 3.1013295 | BW6: 3.1013295 | BX6: 03 | BY6: KAB. TRENGGALEK | BZ6: 1 | CA6: 25.476436 | CB6: 33.220131 | CC6: 7.7977509 | CD6: 67.494318 | CE6: 03 | CF6: KAB. TRENGGALEK | CG6: 0 | CH6: 0 | CI6: 0 | CJ6: 0 | CK6: 0 | CL6: 03 | CM6: KAB. TRENGGALEK | CN6: 0 | CO6: 0 | CP6: 0 | CQ6: 0 | CR6: 0 | CS6: 03 | CT6: KAB. TRENGGALEK | CU6: 249.91749 | CV6: 6.4793491 | CW6: 0 | CX6: 0 | CY6: 256.39684 | CZ6: 03 | DA6: KAB. TRENGGALEK | DB6: 1.0418439 | DC6: 55.622431 | DD6: 0 | DE6: 0 | DF6: 56.664275 | DG6: 03 | DH6: KAB. TRENGGALEK | DI6: 0 | DJ6: 0 | DK6: 0 | DL6: 0 | DM6: 0 | DN6: 03 | DO6: KAB. TRENGGALEK | DP6: 7.2764943 | DQ6: 0 | DR6: 0 | DS6: 0 | DT6: 7.2764943 | DU6: 03 | DV6: KAB. TRENGGALEK | DW6: 18.70062 | DX6: 6.2556065 | DY6: 3.6508036 | DZ6: 1.0418439 | EA6: 29.648874 | EB6: 03 | EC6: KAB. TRENGGALEK | ED6: 843.38696 | EE6: 23.211958 | EF6: 1.0418439 | EG6: 0 | EH6: 867.64076
A7: 04 | B7: KAB. TULUNGAGUNG | C7: =BI7 -> 0 | D7: =BP7 -> 33.601364 | E7: =BW7 -> 18.567992 | F7: =CD7 -> 54.758707 | G7: =CK7 -> 32.356852 | H7: =CR7 -> 0 | I7: =CY7 -> 635.01927 | J7: =DM7 -> 0 | K7: =DF7 -> 33.41379 | L7: =DT7 -> 67.981898 | M7: =EH7 -> 209.8322 | N7: =EA7 -> 79.173166 | O7: =SUM(C7:N7) -> 1164.7052 | P7: 04 | Q7: KAB. TULUNGAGUNG | R7: =C7 -> 0 | S7: =D7 -> 33.601364 | T7: =E7 -> 18.567992 | U7: =F7 -> 54.758707 | V7: =G7 -> 32.356852 | W7: =H7 -> 0 | X7: =I7 -> 635.01927 | Y7: =J7 -> 0 | ... AA7: =L7 -> 67.981898 | AB7: =SUM(R7:AA7) -> 875.69987 | AC7: 04 | AD7: KAB. TULUNGAGUNG | AE7: =M7 -> 209.8322 | AF7: =N7 -> 79.173166 | AG7: =SUM(AE7:AF7) -> 289.00536 | AH7: 04 | AI7: KAB. TULUNGAGUNG | AJ7: =AQ7+AX7 -> 806.29884 | AK7: =AR7+AY7 -> 344.73214 | AL7: =AS7+AZ7 -> 7.4213705 | AM7: =AT7+BA7 -> 6.2528786 | AN7: =SUM(AJ7:AM7) -> 1164.7052 | AO7: 04 | AP7: KAB. TULUNGAGUNG | AQ7: =BE7+BL7+BS7+BZ7+CG7+CN7+CU7+DB7+DI7+DP7 -> 580.72325 | AR7: =BF7+BM7+BT7+CA7+CH7+CO7+CV7+DC7+DJ7+DQ7 -> 287.59709 | AS7: =BG7+BN7+BU7+CB7+CI7+CP7+CW7+DD7+DK7+DR7 -> 7.3795266 | AT7: =BH7+BO7+BV7+CC7+CJ7+CQ7+CX7+DE7+DL7+DS7 -> 0 | AU7: =SUM(AQ7:AT7) -> 875.69987 | AV7: 04 | AW7: KAB. TULUNGAGUNG | AX7: =DW7+ED7 -> 225.57559 | AY7: =DX7+EE7 -> 57.135047 | AZ7: =DY7+EF7 -> 0.041843866 | BA7: =DZ7+EG7 -> 6.2528786 | BB7: =SUM(AX7:BA7) -> 289.00536 | BC7: 04 | BD7: KAB. TULUNGAGUNG | BE7: 0 | BF7: 0 | BG7: 0 | BH7: 0 | BI7: 0 | BJ7: 04 | BK7: KAB. TULUNGAGUNG | BL7: 33.601364 | BM7: 0 | BN7: 0 | BO7: 0 | BP7: 33.601364 | BQ7: 04 | BR7: KAB. TULUNGAGUNG | BS7: 2.067553 | BT7: 14.432886 | BU7: 2.067553 | BV7: 0 | BW7: 18.567992 | BX7: 04 | BY7: KAB. TULUNGAGUNG | BZ7: 39.163205 | CA7: 15.595502 | CB7: 0 | CC7: 0 | CD7: 54.758707 | CE7: 04 | CF7: KAB. TULUNGAGUNG | CG7: 26.598 | CH7: 5.7170088 | CI7: 0.041843866 | CJ7: 0 | CK7: 32.356852 | CL7: 04 | CM7: KAB. TULUNGAGUNG | CN7: 0 | CO7: 0 | CP7: 0 | CQ7: 0 | CR7: 0 | CS7: 04 | CT7: KAB. TULUNGAGUNG | CU7: 407.84221 | CV7: 221.90693 | CW7: 5.2701297 | CX7: 0 | CY7: 635.01927 | CZ7: 04 | DA7: KAB. TULUNGAGUNG | DB7: 33.41379 | DC7: 0 | DD7: 0 | DE7: 0 | DF7: 33.41379 | DG7: 04 | DH7: KAB. TULUNGAGUNG | DI7: 0 | DJ7: 0 | DK7: 0 | DL7: 0 | DM7: 0 | DN7: 04 | DO7: KAB. TULUNGAGUNG | DP7: 38.037131 | DQ7: 29.944766 | DR7: 0 | DS7: 0 | DT7: 67.981898 | DU7: 04 | DV7: KAB. TULUNGAGUNG | DW7: 71.750184 | DX7: 7.3811381 | DY7: 0.041843866 | DZ7: 0 | EA7: 79.173166 | EB7: 04 | EC7: KAB. TULUNGAGUNG | ED7: 153.82541 | EE7: 49.753909 | EF7: 0 | EG7: 6.2528786 | EH7: 209.8322
A8: 05 | B8: KAB. BLITAR | C8: =BI8 -> 0 | D8: =BP8 -> 3.8416242 | E8: =BW8 -> 0 | F8: =CD8 -> 0 | G8: =CK8 -> 5.1427463 | H8: =CR8 -> 0 | I8: =CY8 -> 82.964868 | J8: =DM8 -> 30.82511 | K8: =DF8 -> 0 | L8: =DT8 -> 18.48757 | M8: =EH8 -> 388.96972 | N8: =EA8 -> 88.231812 | O8: =SUM(C8:N8) -> 618.46345 | P8: 05 | Q8: KAB. BLITAR | R8: =C8 -> 0 | S8: =D8 -> 3.8416242 | T8: =E8 -> 0 | U8: =F8 -> 0 | V8: =G8 -> 5.1427463 | W8: =H8 -> 0 | X8: =I8 -> 82.964868 | Y8: =J8 -> 30.82511 | ... AA8: =L8 -> 18.48757 | AB8: =SUM(R8:AA8) -> 141.26192 | AC8: 05 | AD8: KAB. BLITAR | AE8: =M8 -> 388.96972 | AF8: =N8 -> 88.231812 | AG8: =SUM(AE8:AF8) -> 477.20154 | AH8: 05 | AI8: KAB. BLITAR | AJ8: =AQ8+AX8 -> 483.4339 | AK8: =AR8+AY8 -> 119.08822 | AL8: =AS8+AZ8 -> 15.941332 | AM8: =AT8+BA8 -> 0 | AN8: =SUM(AJ8:AM8) -> 618.46345 | AO8: 05 | AP8: KAB. BLITAR | AQ8: =BE8+BL8+BS8+BZ8+CG8+CN8+CU8+DB8+DI8+DP8 -> 67.117363 | AR8: =BF8+BM8+BT8+CA8+CH8+CO8+CV8+DC8+DJ8+DQ8 -> 62.285902 | AS8: =BG8+BN8+BU8+CB8+CI8+CP8+CW8+DD8+DK8+DR8 -> 11.858653 | AT8: =BH8+BO8+BV8+CC8+CJ8+CQ8+CX8+DE8+DL8+DS8 -> 0 | AU8: =SUM(AQ8:AT8) -> 141.26192 | AV8: 05 | AW8: KAB. BLITAR | AX8: =DW8+ED8 -> 416.31654 | AY8: =DX8+EE8 -> 56.802316 | AZ8: =DY8+EF8 -> 4.0826783 | BA8: =DZ8+EG8 -> 0 | BB8: =SUM(AX8:BA8) -> 477.20154 | BC8: 05 | BD8: KAB. BLITAR | BE8: 0 | BF8: 0 | BG8: 0 | BH8: 0 | BI8: 0 | BJ8: 05 | BK8: KAB. BLITAR | BL8: 0 | BM8: 0.041843866 | BN8: 3.7997804 | BO8: 0 | BP8: 3.8416242 | BQ8: 05 | BR8: KAB. BLITAR | BS8: 0 | BT8: 0 | BU8: 0 | BV8: 0 | BW8: 0 | BX8: 05 | BY8: KAB. BLITAR | BZ8: 0 | CA8: 0 | CB8: 0 | CC8: 0 | CD8: 0 | CE8: 05 | CF8: KAB. BLITAR | CG8: 4.1009024 | CH8: 1.0418439 | CI8: 0 | CJ8: 0 | CK8: 5.1427463 | CL8: 05 | CM8: KAB. BLITAR | CN8: 0 | CO8: 0 | CP8: 0 | CQ8: 0 | CR8: 0 | CS8: 05 | CT8: KAB. BLITAR | CU8: 34.637969 | CV8: 48.326899 | CW8: 0 | CX8: 0 | CY8: 82.964868 | CZ8: 05 | DA8: KAB. BLITAR | DB8: 0 | DC8: 0 | DD8: 0 | DE8: 0 | DF8: 0 | DG8: 05 | DH8: KAB. BLITAR | DI8: 22.766237 | DJ8: 0 | DK8: 8.0588731 | DL8: 0 | DM8: 30.82511 | DN8: 05 | DO8: KAB. BLITAR | DP8: 5.6122547 | DQ8: 12.875315 | DR8: 0 | DS8: 0 | DT8: 18.48757 | DU8: 05 | DV8: KAB. BLITAR | DW8: 63.513398 | DX8: 22.677074 | DY8: 2.0413391 | DZ8: 0 | EA8: 88.231812 | EB8: 05 | EC8: KAB. BLITAR | ED8: 352.80314 | EE8: 34.125242 | EF8: 2.0413391 | EG8: 0 | EH8: 388.96972
A9: 06 | B9: KAB. KEDIRI | C9: =BI9 -> 0 | D9: =BP9 -> 14.244808 | E9: =BW9 -> 0 | F9: =CD9 -> 0 | G9: =CK9 -> 0.041843866 | H9: =CR9 -> 0 | I9: =CY9 -> 5.4355373 | J9: =DM9 -> 8.1425608 | K9: =DF9 -> 0 | L9: =DT9 -> 53.775636 | M9: =EH9 -> 1192.9311 | N9: =EA9 -> 24.783924 | O9: =SUM(C9:N9) -> 1299.3554 | P9: 06 | Q9: KAB. KEDIRI | R9: =C9 -> 0 | S9: =D9 -> 14.244808 | T9: =E9 -> 0 | U9: =F9 -> 0 | V9: =G9 -> 0.041843866 | W9: =H9 -> 0 | X9: =I9 -> 5.4355373 | Y9: =J9 -> 8.1425608 | ... AA9: =L9 -> 53.775636 | AB9: =SUM(R9:AA9) -> 81.640386 | AC9: 06 | AD9: KAB. KEDIRI | AE9: =M9 -> 1192.9311 | AF9: =N9 -> 24.783924 | AG9: =SUM(AE9:AF9) -> 1217.715 | AH9: 06 | AI9: KAB. KEDIRI | AJ9: =AQ9+AX9 -> 1153.3038 | AK9: =AR9+AY9 -> 146.05157 | AL9: =AS9+AZ9 -> 0 | AM9: =AT9+BA9 -> 0 | AN9: =SUM(AJ9:AM9) -> 1299.3554 | AO9: 06 | AP9: KAB. KEDIRI | AQ9: =BE9+BL9+BS9+BZ9+CG9+CN9+CU9+DB9+DI9+DP9 -> 35.176086 | AR9: =BF9+BM9+BT9+CA9+CH9+CO9+CV9+DC9+DJ9+DQ9 -> 46.4643 | AS9: =BG9+BN9+BU9+CB9+CI9+CP9+CW9+DD9+DK9+DR9 -> 0 | AT9: =BH9+BO9+BV9+CC9+CJ9+CQ9+CX9+DE9+DL9+DS9 -> 0 | AU9: =SUM(AQ9:AT9) -> 81.640386 | AV9: 06 | AW9: KAB. KEDIRI | AX9: =DW9+ED9 -> 1118.1277 | AY9: =DX9+EE9 -> 99.587275 | AZ9: =DY9+EF9 -> 0 | BA9: =DZ9+EG9 -> 0 | BB9: =SUM(AX9:BA9) -> 1217.715 | BC9: 06 | BD9: KAB. KEDIRI | BE9: 0 | BF9: 0 | BG9: 0 | BH9: 0 | BI9: 0 | BJ9: 06 | BK9: KAB. KEDIRI | BL9: 10.952405 | BM9: 3.2924023 | BN9: 0 | BO9: 0 | BP9: 14.244808 | BQ9: 06 | BR9: KAB. KEDIRI | BS9: 0 | BT9: 0 | BU9: 0 | BV9: 0 | BW9: 0 | BX9: 06 | BY9: KAB. KEDIRI | BZ9: 0 | CA9: 0 | CB9: 0 | CC9: 0 | CD9: 0 | CE9: 06 | CF9: KAB. KEDIRI | CG9: 0.041843866 | CH9: 0 | CI9: 0 | CJ9: 0 | CK9: 0.041843866 | CL9: 06 | CM9: KAB. KEDIRI | CN9: 0 | CO9: 0 | CP9: 0 | CQ9: 0 | CR9: 0 | CS9: 06 | CT9: KAB. KEDIRI | CU9: 4.3518496 | CV9: 1.0836877 | CW9: 0 | CX9: 0 | CY9: 5.4355373 | CZ9: 06 | DA9: KAB. KEDIRI | DB9: 0 | DC9: 0 | DD9: 0 | DE9: 0 | DF9: 0 | DG9: 06 | DH9: KAB. KEDIRI | DI9: 0 | DJ9: 8.1425608 | DK9: 0 | DL9: 0 | DM9: 8.1425608 | DN9: 06 | DO9: KAB. KEDIRI | DP9: 19.829988 | DQ9: 33.945649 | DR9: 0 | DS9: 0 | DT9: 53.775636 | DU9: 06 | DV9: KAB. KEDIRI | DW9: 16.489503 | DX9: 8.2944215 | DY9: 0 | DZ9: 0 | EA9: 24.783924 | EB9: 06 | EC9: KAB. KEDIRI | ED9: 1101.6382 | EE9: 91.292854 | EF9: 0 | EG9: 0 | EH9: 1192.9311
A10: 07 | B10: KAB. MALANG | C10: =BI10 -> 0.041843866 | D10: =BP10 -> 8.8039605 | E10: =BW10 -> 11.307355 | F10: =CD10 -> 131.76746 | G10: =CK10 -> 6.2962026 | H10: =CR10 -> 0 | I10: =CY10 -> 17.161941 | J10: =DM10 -> 11.424962 | K10: =DF10 -> 8.6097994 | L10: =DT10 -> 21.546803 | M10: =EH10 -> 311.30181 | N10: =EA10 -> 30.786482 | O10: =SUM(C10:N10) -> 559.04862 | P10: 07 | Q10: KAB. MALANG | R10: =C10 -> 0.041843866 | S10: =D10 -> 8.8039605 | T10: =E10 -> 11.307355 | U10: =F10 -> 131.76746 | V10: =G10 -> 6.2962026 | W10: =H10 -> 0 | X10: =I10 -> 17.161941 | Y10: =J10 -> 11.424962 | ... AA10: =L10 -> 21.546803 | AB10: =SUM(R10:AA10) -> 216.96032 | AC10: 07 | AD10: KAB. MALANG | AE10: =M10 -> 311.30181 | AF10: =N10 -> 30.786482 | AG10: =SUM(AE10:AF10) -> 342.0883 | AH10: 07 | AI10: KAB. MALANG | AJ10: =AQ10+AX10 -> 512.5179 | AK10: =AR10+AY10 -> 29.667661 | AL10: =AS10+AZ10 -> 8.5005906 | AM10: =AT10+BA10 -> 8.3624714 | AN10: =SUM(AJ10:AM10) -> 559.04862 | AO10: 07 | AP10: KAB. MALANG | AQ10: =BE10+BL10+BS10+BZ10+CG10+CN10+CU10+DB10+DI10+DP10 -> 182.6461 | AR10: =BF10+BM10+BT10+CA10+CH10+CO10+CV10+DC10+DJ10+DQ10 -> 20.618535 | AS10: =BG10+BN10+BU10+CB10+CI10+CP10+CW10+DD10+DK10+DR10 -> 6.375059 | AT10: =BH10+BO10+BV10+CC10+CJ10+CQ10+CX10+DE10+DL10+DS10 -> 7.3206276 | AU10: =SUM(AQ10:AT10) -> 216.96032 | AV10: 07 | AW10: KAB. MALANG | AX10: =DW10+ED10 -> 329.87179 | AY10: =DX10+EE10 -> 9.0491255 | AZ10: =DY10+EF10 -> 2.1255316 | BA10: =DZ10+EG10 -> 1.0418439 | BB10: =SUM(AX10:BA10) -> 342.0883 | BC10: 07 | BD10: KAB. MALANG | BE10: 0.041843866 | BF10: 0 | BG10: 0 | BH10: 0 | BI10: 0.041843866 | BJ10: 07 | BK10: KAB. MALANG | BL10: 7.7621166 | BM10: 1.0418439 | BN10: 0 | BO10: 0 | BP10: 8.8039605 | BQ10: 07 | BR10: KAB. MALANG | BS10: 4.0909116 | BT10: 1.0418439 | BU10: 0 | BV10: 6.1745993 | BW10: 11.307355 | BX10: 07 | BY10: KAB. MALANG | BZ10: 122.6768 | CA10: 9.0906579 | CB10: 0 | CC10: 0 | CD10: 131.76746 | CE10: 07 | CF10: KAB. MALANG | CG10: 6.2962026 | CH10: 0 | CI10: 0 | CJ10: 0 | CK10: 6.2962026 | CL10: 07 | CM10: KAB. MALANG | CN10: 0 | CO10: 0 | CP10: 0 | CQ10: 0 | CR10: 0 | CS10: 07 | CT10: KAB. MALANG | CU10: 10.786882 | CV10: 0 | CW10: 6.375059 | CX10: 0 | CY10: 17.161941 | CZ10: 07 | DA10: KAB. MALANG | DB10: 8.6097994 | DC10: 0 | DD10: 0 | DE10: 0 | DF10: 8.6097994 | DG10: 07 | DH10: KAB. MALANG | DI10: 11.383118 | DJ10: 0.041843866 | DK10: 0 | DL10: 0 | DM10: 11.424962 | DN10: 07 | DO10: KAB. MALANG | DP10: 10.998429 | DQ10: 9.4023459 | DR10: 0 | DS10: 1.1460283 | DT10: 21.546803 | DU10: 07 | DV10: KAB. MALANG | DW10: 22.448702 | DX10: 5.1704043 | DY10: 2.1255316 | DZ10: 1.0418439 | EA10: 30.786482 | EB10: 07 | EC10: KAB. MALANG | ED10: 307.42309 | EE10: 3.8787212 | EF10: 0 | EG10: 0 | EH10: 311.30181
A11: 08 | B11: KAB. LUMAJANG | C11: =BI11 -> 6.6609683 | D11: =BP11 -> 9.2436045 | E11: =BW11 -> 0 | F11: =CD11 -> 105.72373 | G11: =CK11 -> 0 | H11: =CR11 -> 0 | I11: =CY11 -> 25.536361 | J11: =DM11 -> 19.465278 | K11: =DF11 -> 0 | L11: =DT11 -> 37.273111 | M11: =EH11 -> 289.30286 | N11: =EA11 -> 35.447344 | O11: =SUM(C11:N11) -> 528.65326 | P11: 08 | Q11: KAB. LUMAJANG | R11: =C11 -> 6.6609683 | S11: =D11 -> 9.2436045 | T11: =E11 -> 0 | U11: =F11 -> 105.72373 | V11: =G11 -> 0 | W11: =H11 -> 0 | X11: =I11 -> 25.536361 | Y11: =J11 -> 19.465278 | ... AA11: =L11 -> 37.273111 | AB11: =SUM(R11:AA11) -> 203.90306 | AC11: 08 | AD11: KAB. LUMAJANG | AE11: =M11 -> 289.30286 | AF11: =N11 -> 35.447344 | AG11: =SUM(AE11:AF11) -> 324.7502 | AH11: 08 | AI11: KAB. LUMAJANG | AJ11: =AQ11+AX11 -> 383.81864 | AK11: =AR11+AY11 -> 141.22566 | AL11: =AS11+AZ11 -> 3.6089597 | AM11: =AT11+BA11 -> 0 | AN11: =SUM(AJ11:AM11) -> 528.65326 | AO11: 08 | AP11: KAB. LUMAJANG | AQ11: =BE11+BL11+BS11+BZ11+CG11+CN11+CU11+DB11+DI11+DP11 -> 98.165125 | AR11: =BF11+BM11+BT11+CA11+CH11+CO11+CV11+DC11+DJ11+DQ11 -> 105.73793 | AS11: =BG11+BN11+BU11+CB11+CI11+CP11+CW11+DD11+DK11+DR11 -> 0 | AT11: =BH11+BO11+BV11+CC11+CJ11+CQ11+CX11+DE11+DL11+DS11 -> 0 | AU11: =SUM(AQ11:AT11) -> 203.90306 | AV11: 08 | AW11: KAB. LUMAJANG | AX11: =DW11+ED11 -> 285.65352 | AY11: =DX11+EE11 -> 35.487729 | AZ11: =DY11+EF11 -> 3.6089597 | BA11: =DZ11+EG11 -> 0 | BB11: =SUM(AX11:BA11) -> 324.7502 | BC11: 08 | BD11: KAB. LUMAJANG | BE11: 6.6609683 | BF11: 0 | BG11: 0 | BH11: 0 | BI11: 6.6609683 | BJ11: 08 | BK11: KAB. LUMAJANG | BL11: 5.4438241 | BM11: 3.7997804 | BN11: 0 | BO11: 0 | BP11: 9.2436045 | BQ11: 08 | BR11: KAB. LUMAJANG | BS11: 0 | BT11: 0 | BU11: 0 | BV11: 0 | BW11: 0 | BX11: 08 | BY11: KAB. LUMAJANG | BZ11: 26.662538 | CA11: 79.061196 | CB11: 0 | CC11: 0 | CD11: 105.72373 | CE11: 08 | CF11: KAB. LUMAJANG | CG11: 0 | CH11: 0 | CI11: 0 | CJ11: 0 | CK11: 0 | CL11: 08 | CM11: KAB. LUMAJANG | CN11: 0 | CO11: 0 | CP11: 0 | CQ11: 0 | CR11: 0 | CS11: 08 | CT11: KAB. LUMAJANG | CU11: 14.996101 | CV11: 10.540259 | CW11: 0 | CX11: 0 | CY11: 25.536361 | CZ11: 08 | DA11: KAB. LUMAJANG | DB11: 0 | DC11: 0 | DD11: 0 | DE11: 0 | DF11: 0 | DG11: 08 | DH11: KAB. LUMAJANG | DI11: 11.406405 | DJ11: 8.0588731 | DK11: 0 | DL11: 0 | DM11: 19.465278 | DN11: 08 | DO11: KAB. LUMAJANG | DP11: 32.995288 | DQ11: 4.2778237 | DR11: 0 | DS11: 0 | DT11: 37.273111 | DU11: 08 | DV11: KAB. LUMAJANG | DW11: 28.773347 | DX11: 3.0650374 | DY11: 3.6089597 | DZ11: 0 | EA11: 35.447344 | EB11: 08 | EC11: KAB. LUMAJANG | ED11: 256.88017 | EE11: 32.422691 | EF11: 0 | EG11: 0 | EH11: 289.30286
A12: 09 | B12: KAB. JEMBER | C12: =BI12 -> 35.733878 | D12: =BP12 -> 0.041843866 | E12: =BW12 -> 0 | F12: =CD12 -> 229.8648 | G12: =CK12 -> 46.337663 | H12: =CR12 -> 0 | I12: =CY12 -> 110.91902 | J12: =DM12 -> 0.041843866 | K12: =DF12 -> 85.140965 | L12: =DT12 -> 49.139408 | M12: =EH12 -> 294.48827 | N12: =EA12 -> 62.68096 | O12: =SUM(C12:N12) -> 914.38866 | P12: 09 | Q12: KAB. JEMBER | R12: =C12 -> 35.733878 | S12: =D12 -> 0.041843866 | T12: =E12 -> 0 | U12: =F12 -> 229.8648 | V12: =G12 -> 46.337663 | W12: =H12 -> 0 | X12: =I12 -> 110.91902 | Y12: =J12 -> 0.041843866 | ... AA12: =L12 -> 49.139408 | AB12: =SUM(R12:AA12) -> 557.21943 | AC12: 09 | AD12: KAB. JEMBER | AE12: =M12 -> 294.48827 | AF12: =N12 -> 62.68096 | AG12: =SUM(AE12:AF12) -> 357.16923 | AH12: 09 | AI12: KAB. JEMBER | AJ12: =AQ12+AX12 -> 562.8379 | AK12: =AR12+AY12 -> 303.94598 | AL12: =AS12+AZ12 -> 47.562924 | AM12: =AT12+BA12 -> 0.041843866 | AN12: =SUM(AJ12:AM12) -> 914.38866 | AO12: 09 | AP12: KAB. JEMBER | AQ12: =BE12+BL12+BS12+BZ12+CG12+CN12+CU12+DB12+DI12+DP12 -> 271.90556 | AR12: =BF12+BM12+BT12+CA12+CH12+CO12+CV12+DC12+DJ12+DQ12 -> 256.41893 | AS12: =BG12+BN12+BU12+CB12+CI12+CP12+CW12+DD12+DK12+DR12 -> 28.894937 | AT12: =BH12+BO12+BV12+CC12+CJ12+CQ12+CX12+DE12+DL12+DS12 -> 0 | AU12: =SUM(AQ12:AT12) -> 557.21943 | AV12: 09 | AW12: KAB. JEMBER | AX12: =DW12+ED12 -> 290.93235 | AY12: =DX12+EE12 -> 47.52705 | AZ12: =DY12+EF12 -> 18.667988 | BA12: =DZ12+EG12 -> 0.041843866 | BB12: =SUM(AX12:BA12) -> 357.16923 | BC12: 09 | BD12: KAB. JEMBER | BE12: 31.935928 | BF12: 3.7979494 | BG12: 0 | BH12: 0 | BI12: 35.733878 | BJ12: 09 | BK12: KAB. JEMBER | BL12: 0 | BM12: 0 | BN12: 0.041843866 | BO12: 0 | BP12: 0.041843866 | BQ12: 09 | BR12: KAB. JEMBER | BS12: 0 | BT12: 0 | BU12: 0 | BV12: 0 | BW12: 0 | BX12: 09 | BY12: KAB. JEMBER | BZ12: 82.604166 | CA12: 131.03098 | CB12: 16.22965 | CC12: 0 | CD12: 229.8648 | CE12: 09 | CF12: KAB. JEMBER | CG12: 37.912634 | CH12: 8.4250297 | CI12: 0 | CJ12: 0 | CK12: 46.337663 | CL12: 09 | CM12: KAB. JEMBER | CN12: 0 | CO12: 0 | CP12: 0 | CQ12: 0 | CR12: 0 | CS12: 09 | CT12: KAB. JEMBER | CU12: 22.179201 | CV12: 76.158225 | CW12: 12.581599 | CX12: 0 | CY12: 110.91902 | CZ12: 09 | DA12: KAB. JEMBER | DB12: 72.53842 | DC12: 12.5607 | DD12: 0.041843866 | DE12: 0 | DF12: 85.140965 | DG12: 09 | DH12: KAB. JEMBER | DI12: 0.041843866 | DJ12: 0 | DK12: 0 | DL12: 0 | DM12: 0.041843866 | DN12: 09 | DO12: KAB. JEMBER | DP12: 24.693362 | DQ12: 24.446046 | DR12: 0 | DS12: 0 | DT12: 49.139408 | DU12: 09 | DV12: KAB. JEMBER | DW12: 39.734173 | DX12: 10.360973 | DY12: 12.54397 | DZ12: 0.041843866 | EA12: 62.68096 | EB12: 09 | EC12: KAB. JEMBER | ED12: 251.19818 | EE12: 37.166076 | EF12: 6.1240174 | EG12: 0 | EH12: 294.48827
A13: 10 | B13: KAB. BANYUWANGI | C13: =BI13 -> 0 | D13: =BP13 -> 7.1599167 | E13: =BW13 -> 20.67553 | F13: =CD13 -> 96.646632 | G13: =CK13 -> 7.7342234 | H13: =CR13 -> 12.398889 | I13: =CY13 -> 61.397217 | J13: =DM13 -> 110.3221 | K13: =DF13 -> 74.337668 | L13: =DT13 -> 284.54839 | M13: =EH13 -> 1370.1907 | N13: =EA13 -> 50.765909 | O13: =SUM(C13:N13) -> 2096.1771 | P13: 10 | Q13: KAB. BANYUWANGI | R13: =C13 -> 0 | S13: =D13 -> 7.1599167 | T13: =E13 -> 20.67553 | U13: =F13 -> 96.646632 | V13: =G13 -> 7.7342234 | W13: =H13 -> 12.398889 | X13: =I13 -> 61.397217 | Y13: =J13 -> 110.3221 | ... AA13: =L13 -> 284.54839 | AB13: =SUM(R13:AA13) -> 675.22056 | AC13: 10 | AD13: KAB. BANYUWANGI | AE13: =M13 -> 1370.1907 | AF13: =N13 -> 50.765909 | AG13: =SUM(AE13:AF13) -> 1420.9566 | AH13: 10 | AI13: KAB. BANYUWANGI | AJ13: =AQ13+AX13 -> 1808.7114 | AK13: =AR13+AY13 -> 104.13306 | AL13: =AS13+AZ13 -> 30.265766 | AM13: =AT13+BA13 -> 153.06689 | AN13: =SUM(AJ13:AM13) -> 2096.1771 | AO13: 10 | AP13: KAB. BANYUWANGI | AQ13: =BE13+BL13+BS13+BZ13+CG13+CN13+CU13+DB13+DI13+DP13 -> 448.55789 | AR13: =BF13+BM13+BT13+CA13+CH13+CO13+CV13+DC13+DJ13+DQ13 -> 49.581085 | AS13: =BG13+BN13+BU13+CB13+CI13+CP13+CW13+DD13+DK13+DR13 -> 30.265766 | AT13: =BH13+BO13+BV13+CC13+CJ13+CQ13+CX13+DE13+DL13+DS13 -> 146.81583 | AU13: =SUM(AQ13:AT13) -> 675.22056 | AV13: 10 | AW13: KAB. BANYUWANGI | AX13: =DW13+ED13 -> 1360.1535 | AY13: =DX13+EE13 -> 54.551971 | AZ13: =DY13+EF13 -> 0 | BA13: =DZ13+EG13 -> 6.2510632 | BB13: =SUM(AX13:BA13) -> 1420.9566 | BC13: 10 | BD13: KAB. BANYUWANGI | BE13: 0 | BF13: 0 | BG13: 0 | BH13: 0 | BI13: 0 | BJ13: 10 | BK13: KAB. BANYUWANGI | BL13: 3.3601364 | BM13: 0 | BN13: 0 | BO13: 3.7997804 | BP13: 7.1599167 | BQ13: 10 | BR13: KAB. BANYUWANGI | BS13: 0 | BT13: 1.0337765 | BU13: 3.1013295 | BV13: 16.540424 | BW13: 20.67553 | BX13: 10 | BY13: KAB. BANYUWANGI | BZ13: 49.914376 | CA13: 23.339004 | CB13: 0 | CC13: 23.393253 | CD13: 96.646632 | CE13: 10 | CF13: KAB. BANYUWANGI | CG13: 3.0590585 | CH13: 4.6751649 | CI13: 0 | CJ13: 0 | CK13: 7.7342234 | CL13: 10 | CM13: KAB. BANYUWANGI | CN13: 0 | CO13: 0 | CP13: 5.011269 | CQ13: 7.3876201 | CR13: 12.398889 | CS13: 10 | CT13: KAB. BANYUWANGI | CU13: 59.271685 | CV13: 2.1255316 | CW13: 0 | CX13: 0 | CY13: 61.397217 | CZ13: 10 | DA13: KAB. BANYUWANGI | DB13: 41.191974 | DC13: 12.004253 | DD13: 14.094294 | DE13: 7.047147 | DF13: 74.337668 | DG13: 10 | DH13: KAB. BANYUWANGI | DI13: 11.531937 | DJ13: 2.0836877 | DK13: 8.0588731 | DL13: 88.647604 | DM13: 110.3221 | DN13: 10 | DO13: KAB. BANYUWANGI | DP13: 280.22872 | DQ13: 4.3196676 | DR13: 0 | DS13: 0 | DT13: 284.54839 | DU13: 10 | DV13: KAB. BANYUWANGI | DW13: 43.473002 | DX13: 1.0418439 | DY13: 0 | DZ13: 6.2510632 | EA13: 50.765909 | EB13: 10 | EC13: KAB. BANYUWANGI | ED13: 1316.6805 | EE13: 53.510127 | EF13: 0 | EG13: 0 | EH13: 1370.1907
A14: 11 | B14: KAB. BONDOWOSO | C14: =BI14 -> 0 | D14: =BP14 -> 6.7202727 | E14: =BW14 -> 0 | F14: =CD14 -> 4.8505694 | G14: =CK14 -> 0 | H14: =CR14 -> 0 | I14: =CY14 -> 0.041843866 | J14: =DM14 -> 0 | K14: =DF14 -> 0 | L14: =DT14 -> 39.608104 | M14: =EH14 -> 822.86793 | N14: =EA14 -> 31.358623 | O14: =SUM(C14:N14) -> 905.44734 | P14: 11 | Q14: KAB. BONDOWOSO | R14: =C14 -> 0 | S14: =D14 -> 6.7202727 | T14: =E14 -> 0 | U14: =F14 -> 4.8505694 | V14: =G14 -> 0 | W14: =H14 -> 0 | X14: =I14 -> 0.041843866 | Y14: =J14 -> 0 | ... AA14: =L14 -> 39.608104 | AB14: =SUM(R14:AA14) -> 51.22079 | AC14: 11 | AD14: KAB. BONDOWOSO | AE14: =M14 -> 822.86793 | AF14: =N14 -> 31.358623 | AG14: =SUM(AE14:AF14) -> 854.22655 | AH14: 11 | AI14: KAB. BONDOWOSO | AJ14: =AQ14+AX14 -> 905.44734 | AK14: =AR14+AY14 -> 0 | AL14: =AS14+AZ14 -> 0 | AM14: =AT14+BA14 -> 0 | AN14: =SUM(AJ14:AM14) -> 905.44734 | AO14: 11 | AP14: KAB. BONDOWOSO | AQ14: =BE14+BL14+BS14+BZ14+CG14+CN14+CU14+DB14+DI14+DP14 -> 51.22079 | AR14: =BF14+BM14+BT14+CA14+CH14+CO14+CV14+DC14+DJ14+DQ14 -> 0 | AS14: =BG14+BN14+BU14+CB14+CI14+CP14+CW14+DD14+DK14+DR14 -> 0 | AT14: =BH14+BO14+BV14+CC14+CJ14+CQ14+CX14+DE14+DL14+DS14 -> 0 | AU14: =SUM(AQ14:AT14) -> 51.22079 | AV14: 11 | AW14: KAB. BONDOWOSO | AX14: =DW14+ED14 -> 854.22655 | AY14: =DX14+EE14 -> 0 | AZ14: =DY14+EF14 -> 0 | BA14: =DZ14+EG14 -> 0 | BB14: =SUM(AX14:BA14) -> 854.22655 | BC14: 11 | BD14: KAB. BONDOWOSO | BE14: 0 | BF14: 0 | BG14: 0 | BH14: 0 | BI14: 0 | BJ14: 11 | BK14: KAB. BONDOWOSO | BL14: 6.7202727 | BM14: 0 | BN14: 0 | BO14: 0 | BP14: 6.7202727 | BQ14: 11 | BR14: KAB. BONDOWOSO | BS14: 0 | BT14: 0 | BU14: 0 | BV14: 0 | BW14: 0 | BX14: 11 | BY14: KAB. BONDOWOSO | BZ14: 4.8505694 | CA14: 0 | CB14: 0 | CC14: 0 | CD14: 4.8505694 | CE14: 11 | CF14: KAB. BONDOWOSO | CG14: 0 | CH14: 0 | CI14: 0 | CJ14: 0 | CK14: 0 | CL14: 11 | CM14: KAB. BONDOWOSO | CN14: 0 | CO14: 0 | CP14: 0 | CQ14: 0 | CR14: 0 | CS14: 11 | CT14: KAB. BONDOWOSO | CU14: 0.041843866 | CV14: 0 | CW14: 0 | CX14: 0 | CY14: 0.041843866 | CZ14: 11 | DA14: KAB. BONDOWOSO | DB14: 0 | DC14: 0 | DD14: 0 | DE14: 0 | DF14: 0 | DG14: 11 | DH14: KAB. BONDOWOSO | DI14: 0 | DJ14: 0 | DK14: 0 | DL14: 0 | DM14: 0 | DN14: 11 | DO14: KAB. BONDOWOSO | DP14: 39.608104 | DQ14: 0 | DR14: 0 | DS14: 0 | DT14: 39.608104 | DU14: 11 | DV14: KAB. BONDOWOSO | DW14: 31.358623 | DX14: 0 | DY14: 0 | DZ14: 0 | EA14: 31.358623 | EB14: 11 | EC14: KAB. BONDOWOSO | ED14: 822.86793 | EE14: 0 | EF14: 0 | EG14: 0 | EH14: 822.86793
A15: 12 | B15: KAB. SITUBONDO | C15: =BI15 -> 0 | D15: =BP15 -> 0 | E15: =BW15 -> 3.1013295 | F15: =CD15 -> 92.893063 | G15: =CK15 -> 10.175116 | H15: =CR15 -> 0 | I15: =CY15 -> 0 | J15: =DM15 -> 21.770966 | K15: =DF15 -> 214.51783 | L15: =DT15 -> 18.817941 | M15: =EH15 -> 390.03586 | N15: =EA15 -> 152.60252 | O15: =SUM(C15:N15) -> 903.91462 | P15: 12 | Q15: KAB. SITUBONDO | R15: =C15 -> 0 | S15: =D15 -> 0 | T15: =E15 -> 3.1013295 | U15: =F15 -> 92.893063 | V15: =G15 -> 10.175116 | W15: =H15 -> 0 | X15: =I15 -> 0 | Y15: =J15 -> 21.770966 | ... AA15: =L15 -> 18.817941 | AB15: =SUM(R15:AA15) -> 361.27625 | AC15: 12 | AD15: KAB. SITUBONDO | AE15: =M15 -> 390.03586 | AF15: =N15 -> 152.60252 | AG15: =SUM(AE15:AF15) -> 542.63837 | AH15: 12 | AI15: KAB. SITUBONDO | AJ15: =AQ15+AX15 -> 342.63771 | AK15: =AR15+AY15 -> 546.51864 | AL15: =AS15+AZ15 -> 9.5732572 | AM15: =AT15+BA15 -> 5.1850172 | AN15: =SUM(AJ15:AM15) -> 903.91462 | AO15: 12 | AP15: KAB. SITUBONDO | AQ15: =BE15+BL15+BS15+BZ15+CG15+CN15+CU15+DB15+DI15+DP15 -> 197.49997 | AR15: =BF15+BM15+BT15+CA15+CH15+CO15+CV15+DC15+DJ15+DQ15 -> 155.26907 | AS15: =BG15+BN15+BU15+CB15+CI15+CP15+CW15+DD15+DK15+DR15 -> 5.4058818 | AT15: =BH15+BO15+BV15+CC15+CJ15+CQ15+CX15+DE15+DL15+DS15 -> 3.1013295 | AU15: =SUM(AQ15:AT15) -> 361.27625 | AV15: 12 | AW15: KAB. SITUBONDO | AX15: =DW15+ED15 -> 145.13774 | AY15: =DX15+EE15 -> 391.24957 | AZ15: =DY15+EF15 -> 4.1673755 | BA15: =DZ15+EG15 -> 2.0836877 | BB15: =SUM(AX15:BA15) -> 542.63837 | BC15: 12 | BD15: KAB. SITUBONDO | BE15: 0 | BF15: 0 | BG15: 0 | BH15: 0 | BI15: 0 | BJ15: 12 | BK15: KAB. SITUBONDO | BL15: 0 | BM15: 0 | BN15: 0 | BO15: 0 | BP15: 0 | BQ15: 12 | BR15: KAB. SITUBONDO | BS15: 0 | BT15: 0 | BU15: 0 | BV15: 3.1013295 | BW15: 3.1013295 | BX15: 12 | BY15: KAB. SITUBONDO | BZ15: 60.086114 | CA15: 32.59773 | CB15: 0.20921933 | CC15: 0 | CD15: 92.893063 | CE15: 12 | CF15: KAB. SITUBONDO | CG15: 8.0688586 | CH15: 2.1062574 | CI15: 0 | CJ15: 0 | CK15: 10.175116 | CL15: 12 | CM15: KAB. SITUBONDO | CN15: 0 | CO15: 0 | CP15: 0 | CQ15: 0 | CR15: 0 | CS15: 12 | CT15: KAB. SITUBONDO | CU15: 0 | CV15: 0 | CW15: 0 | CX15: 0 | CY15: 0 | CZ15: 12 | DA15: KAB. SITUBONDO | DB15: 88.756092 | DC15: 120.56508 | DD15: 5.1966624 | DE15: 0 | DF15: 214.51783 | DG15: 12 | DH15: KAB. SITUBONDO | DI15: 21.770966 | DJ15: 0 | DK15: 0 | DL15: 0 | DM15: 21.770966 | DN15: 12 | DO15: KAB. SITUBONDO | DP15: 18.817941 | DQ15: 0 | DR15: 0 | DS15: 0 | DT15: 18.817941 | DU15: 12 | DV15: KAB. SITUBONDO | DW15: 34.348169 | DX15: 112.00328 | DY15: 4.1673755 | DZ15: 2.0836877 | EA15: 152.60252 | EB15: 12 | EC15: KAB. SITUBONDO | ED15: 110.78957 | EE15: 279.24629 | EF15: 0 | EG15: 0 | EH15: 390.03586
... A41: 79 | B41: KOTA BATU | C41: =BI41 -> 0 | D41: =BP41 -> 2.2092193 | E41: =BW41 -> 0 | F41: =CD41 -> 4.8505694 | G41: =CK41 -> 3.1009024 | H41: =CR41 -> 0 | I41: =CY41 -> 0 | J41: =DM41 -> 0 | K41: =DF41 -> 27.844825 | L41: =DT41 -> 58.103924 | M41: =EH41 -> 257.57633 | N41: =EA41 -> 0 | O41: =SUM(C41:N41) -> 353.68577 | P41: 79 | Q41: KOTA BATU | R41: =C41 -> 0 | S41: =D41 -> 2.2092193 | T41: =E41 -> 0 | U41: =F41 -> 4.8505694 | V41: =G41 -> 3.1009024 | W41: =H41 -> 0 | X41: =I41 -> 0 | Y41: =J41 -> 0 | ... AA41: =L41 -> 58.103924 | AB41: =SUM(R41:AA41) -> 96.10944 | AC41: 79 | AD41: KOTA BATU | AE41: =M41 -> 257.57633 | AF41: =N41 -> 0 | AG41: =SUM(AE41:AF41) -> 257.57633 | AH41: 79 | AI41: KOTA BATU | AJ41: =AQ41+AX41 -> 320.41998 | AK41: =AR41+AY41 -> 33.26579 | AL41: =AS41+AZ41 -> 0 | AM41: =AT41+BA41 -> 0 | AN41: =SUM(AJ41:AM41) -> 353.68577 | AO41: 79 | AP41: KOTA BATU | AQ41: =BE41+BL41+BS41+BZ41+CG41+CN41+CU41+DB41+DI41+DP41 -> 87.511948 | AR41: =BF41+BM41+BT41+CA41+CH41+CO41+CV41+DC41+DJ41+DQ41 -> 8.5974913 | AS41: =BG41+BN41+BU41+CB41+CI41+CP41+CW41+DD41+DK41+DR41 -> 0 | AT41: =BH41+BO41+BV41+CC41+CJ41+CQ41+CX41+DE41+DL41+DS41 -> 0 | AU41: =SUM(AQ41:AT41) -> 96.10944 | AV41: 79 | AW41: KOTA BATU | AX41: =DW41+ED41 -> 232.90803 | AY41: =DX41+EE41 -> 24.668299 | AZ41: =DY41+EF41 -> 0 | BA41: =DZ41+EG41 -> 0 | BB41: =SUM(AX41:BA41) -> 257.57633 | BC41: 79 | BD41: KOTA BATU | BE41: 0 | BF41: 0 | BG41: 0 | BH41: 0 | BI41: 0 | BJ41: 79 | BK41: KOTA BATU | BL41: 2.2092193 | BM41: 0 | BN41: 0 | BO41: 0 | BP41: 2.2092193 | BQ41: 79 | BR41: KOTA BATU | BS41: 0 | BT41: 0 | BU41: 0 | BV41: 0 | BW41: 0 | BX41: 79 | BY41: KOTA BATU | BZ41: 4.8505694 | CA41: 0 | CB41: 0 | CC41: 0 | CD41: 4.8505694 | CE41: 79 | CF41: KOTA BATU | CG41: 3.0590585 | CH41: 0.041843866 | CI41: 0 | CJ41: 0 | CK41: 3.1009024 | CL41: 79 | CM41: KOTA BATU | CN41: 0 | CO41: 0 | CP41: 0 | CQ41: 0 | CR41: 0 | CS41: 79 | CT41: KOTA BATU | CU41: 0 | CV41: 0 | CW41: 0 | CX41: 0 | CY41: 0 | CZ41: 79 | DA41: KOTA BATU | DB41: 27.844825 | DC41: 0 | DD41: 0 | DE41: 0 | DF41: 27.844825 | DG41: 79 | DH41: KOTA BATU | DI41: 0 | DJ41: 0 | DK41: 0 | DL41: 0 | DM41: 0 | DN41: 79 | DO41: KOTA BATU | DP41: 49.548276 | DQ41: 8.5556475 | DR41: 0 | DS41: 0 | DT41: 58.103924 | DU41: 79 | DV41: KOTA BATU | DW41: 0 | DX41: 0 | DY41: 0 | DZ41: 0 | EA41: 0 | EB41: 79 | EC41: KOTA BATU | ED41: 232.90803 | EE41: 24.668299 | EF41: 0 | EG41: 0 | EH41: 257.57633
B42: Grand Total | C42: =SUM(C4:C41) -> 269.27677 | D42: =SUM(D4:D41) -> 689.8816 | E42: =SUM(E4:E41) -> 167.58291 | F42: =SUM(F4:F41) -> 2047.3629 | G42: =SUM(G4:G41) -> 606.75368 | H42: =SUM(H4:H41) -> 21.264033 | I42: =SUM(I4:I41) -> 2479.9703 | J42: =SUM(J4:J41) -> 545.34213 | ... O42: =SUM(O4:O41) -> 32420.135 | Q42: Grand Total | R42: =SUM(R4:R41) -> 269.27677 | S42: =SUM(S4:S41) -> 689.8816 | T42: =SUM(T4:T41) -> 167.58291 | U42: =SUM(U4:U41) -> 2047.3629 | V42: =SUM(V4:V41) -> 606.75368 | W42: =SUM(W4:W41) -> 21.264033 | X42: =SUM(X4:X41) -> 2479.9703 | Y42: =SUM(Y4:Y41) -> 545.34213 | ... AB42: =SUM(AB4:AB41) -> 10841.182 | AD42: Grand Total | AE42: =SUM(AE4:AE41) -> 19906.21 | AF42: =SUM(AF4:AF41) -> 1672.7435 | AG42: =SUM(AG4:AG41) -> 21578.953 | AI42: Grand Total | AJ42: =SUM(AJ4:AJ41) -> 26449.072 | AK42: =SUM(AK4:AK41) -> 4914.1461 | AL42: =SUM(AL4:AL41) -> 710.84105 | AM42: =SUM(AM4:AM41) -> 346.07666 | AN42: =SUM(AN4:AN41) -> 32420.135 | AP42: Grand Total | AQ42: =SUM(AQ4:AQ41) -> 6958.3411 | AR42: =SUM(AR4:AR41) -> 3068.7028 | AS42: =SUM(AS4:AS41) -> 502.65366 | AT42: =SUM(AT4:AT41) -> 311.48477 | AU42: =SUM(AU4:AU41) -> 10841.182 | AW42: Grand Total | AX42: =SUM(AX4:AX41) -> 19490.731 | AY42: =SUM(AY4:AY41) -> 1845.4433 | AZ42: =SUM(AZ4:AZ41) -> 208.18739 | BA42: =SUM(BA4:BA41) -> 34.591882 | BB42: =SUM(BB4:BB41) -> 21578.953 | BD42: Grand Total | BE42: 215.35979 | BF42: 40.322094 | BG42: 13.594889 | BH42: 0 | BI42: 269.27677 | BK42: Grand Total | BL42: 475.35057 | BM42: 140.58495 | BN42: 58.746956 | BO42: 15.199122 | BP42: 689.8816 | BR42: Grand Total | BS42: 20.658904 | BT42: 33.070782 | BU42: 45.652034 | BV42: 68.201189 | BW42: 167.58291 | BY42: Grand Total | BZ42: 1045.2106 | CA42: 866.09786 | CB42: 97.065689 | CC42: 38.988754 | CD42: 2047.3629 | CF42: Grand Total | CG42: 449.29776 | CH42: 136.6666 | CI42: 14.665302 | CJ42: 6.1240174 | CK42: 606.75368 | CM42: Grand Total | CN42: 0 | CO42: 0 | CP42: 9.4438411 | CQ42: 11.820192 | CR42: 21.264033 | CT42: Grand Total | CU42: 1738.5958 | CV42: 692.95705 | CW42: 48.417482 | CX42: 0 | CY42: 2479.9703 | DA42: Grand Total | DB42: 1108.7962 | DC42: 653.58885 | DD42: 85.874667 | DE42: 42.282882 | DF42: 1890.5426 | DH42: Grand Total | DI42: 289.54666 | DJ42: 95.404541 | DK42: 47.56671 | DL42: 112.82422 | DM42: 545.34213 | DO42: Grand Total | DP42: 1615.5249 | DQ42: 410.01005 | DR42: 81.626093 | DS42: 16.044396 | DT42: 2123.2054 | DV42: Grand Total | DW42: 1071.8664 | DX42: 423.28264 | DY42: 149.42288 | DZ42: 28.171628 | EA42: 1672.7435 | EC42: Grand Total | ED42: 18418.864 | EE42: 1422.1607 | EF42: 58.76451 | EG42: 6.4202541 | EH42: 19906.21
O43: =AB42+AG42 -> 32420.135 | AJ43: =AJ42*4% -> 1057.9629 | AK43: =AK42*4% -> 196.56584 | AL43: =AL42*4% -> 28.433642 | AM43: =AM42*4% -> 13.843066 | AN43: =O42 -> 32420.135 | AU43: =AB42 -> 10841.182 | BB43: =AG42 -> 21578.953
B47: =A1 -> Tabel 1 Jumlah Unit Usaha Aktif berdasarkan Jenis Kegiatan
B48: =P1 -> Tabel 2 Jumlah Unit Usaha Aktif berdasarkan Jenis Kegiatan Pengolahan
B49: =AC1 -> Tabel 3 Jumlah Unit Usaha Aktif berdasarkan Jenis Kegiatan Pemasaran
B50: =AH1 -> Tabel 4 Jumlah Unit Usaha Aktif berdasarkan Skala Usaha
B51: =AO1 -> Tabel 5 Jumlah Unit Usaha Aktif berdasarkan Skala Usaha pada Kegiatan Pengolahan
B52: =AV1 -> Tabel 6 Jumlah Unit Usaha Aktif berdasarkan Skala Usaha pada Kegiatan Pemasaran
B53: =BC1 -> Tabel 7 Jumlah Unit Usaha Aktif berdasarkan Skala Usaha pada Jenis Kegiatan Fermentasi
B54: =BJ1 -> Tabel 8 Jumlah Unit Usaha Aktif berdasarkan Skala Usaha pada Jenis Kegiatan Pelumatan Daging Ikan
B55: =BQ1 -> Tabel 9 Jumlah Unit Usaha Aktif berdasarkan Skala Usaha pada Jenis Kegiatan Pembekuan
B56: =BX1 -> Tabel 10 Jumlah Unit Usaha Aktif berdasarkan Skala Usaha pada Jenis Kegiatan Pemindangan
B57: =CE1 -> Tabel 11 Jumlah Unit Usaha Aktif berdasarkan Skala Usaha pada Jenis Kegiatan Penanganan Produk Segar
B58: =CL1 -> Tabel 12 Jumlah Unit Usaha Aktif berdasarkan Skala Usaha pada Jenis Kegiatan Pengalengan
B59: =CS1 -> Tabel 13 Jumlah Unit Usaha Aktif berdasarkan Skala Usaha pada Jenis Kegiatan Pengasapan / Pemanggangan
B60: =CZ1 -> Tabel 14 Jumlah Unit Usaha Aktif berdasarkan Skala Usaha pada Jenis Kegiatan Penggaraman / Pengeringan
B61: =DG1 -> Tabel 15 Jumlah Unit Usaha Aktif berdasarkan Skala Usaha pada Jenis Kegiatan Pereduksian/Ekstraksi
B62: =DN1 -> Tabel 16 Jumlah Unit Usaha Aktif berdasarkan Skala Usaha pada Jenis Kegiatan Pengolahan Lainnya
B63: =DU1 -> Tabel 17 Jumlah Unit Usaha Aktif berdasarkan Skala Usaha pada Jenis Kegiatan Pengumpul/Pedagang Besar/Distributor
B64: =EB1 -> Tabel 18 Jumlah Unit Usaha Aktif berdasarkan Skala Usaha pada Jenis Kegiatan Pengecer
A67: No | B67: Jenis Kegiatan | C67: Jumlah (Unit)
A68: 1 | B68: Fermentasi | C68: =C42 -> 269.27677
A69: 2 | B69: Pelumatan Daging Ikan | C69: =D42 -> 689.8816
A70: 3 | B70: Pembekuan | C70: =E42 -> 167.58291
...

Sheet Kapasitas
A1: Tabel 19 Jumlah Kapasitas (Kg) berdasarkan Jenis Kegiatan | P1: Tabel 20 Jumlah Kapasitas (Kg) berdasarkan Jenis Kegiatan Pengolahan | AC1: Tabel 21 Jumlah Kapasitas (Kg) berdasarkan Jenis Kegiatan Pemasaran | AH1: Tabel 22 Jumlah Kapasitas (Kg) berdasarkan Skala Usaha | AO1: Tabel 23 Jumlah Kapasitas (Kg) berdasarkan Skala Usaha pada Kegiatan Pengolahan | AV1: Tabel 24 Jumlah Kapasitas (Kg) berdasarkan Skala Usaha pada Kegiatan Pemasaran | BC1: Tabel 25 Jumlah Kapasitas (Kg) berdasarkan Skala Usaha pada Jenis Kegiatan Fermentasi | BJ1: Tabel 26 Jumlah Kapasitas (Kg) berdasarkan Skala Usaha pada Jenis Kegiatan Pelumatan Daging Ikan | BQ1: Tabel 27 Jumlah Kapasitas (Kg) berdasarkan Skala Usaha pada Jenis Kegiatan Pembekuan | BX1: Tabel 28 Jumlah Kapasitas (Kg) berdasarkan Skala Usaha pada Jenis Kegiatan Pemindangan | CE1: Tabel 29 Jumlah Kapasitas (Kg) berdasarkan Skala Usaha pada Jenis Kegiatan Penanganan Produk Segar | CL1: Tabel 30 Jumlah Kapasitas (Kg) berdasarkan Skala Usaha pada Jenis Kegiatan Pengalengan | CS1: Tabel 31 Jumlah Kapasitas (Kg) berdasarkan Skala Usaha pada Jenis Kegiatan Pengasapan / Pemanggangan | CZ1: Tabel 32 Jumlah Kapasitas (Kg) berdasarkan Skala Usaha pada Jenis Kegiatan Penggaraman / Pengeringan | DG1: Tabel 33 Jumlah Kapasitas (Kg) berdasarkan Skala Usaha pada Jenis Kegiatan Pereduksian/Ekstraksi | DN1: Tabel 34 Jumlah Kapasitas (Kg) berdasarkan Skala Usaha pada Jenis Kegiatan Pengolahan Lainnya | DU1: Tabel 35 Jumlah Kapasitas (Kg) berdasarkan Skala Usaha pada Jenis Kegiatan Pengumpul/Pedagang Besar/Distributor | EB1: Tabel 36 Jumlah Kapasitas (Kg) berdasarkan Skala Usaha pada Jenis Kegiatan Pengecer
A2: No | B2: Kabupaten/Kota | C2: Jenis Kegiatan | O2: Jumlah Total | P2: No | Q2: Kabupaten/Kota | R2: Jenis Kegiatan | AB2: Jumlah Total | AC2: No | AD2: Kabupaten/Kota | AE2: Jenis Kegiatan | AG2: Jumlah Total | AH2: No | AI2: Kabupaten/Kota | AJ2: Skala Usaha | AN2: Jumlah Total | AO2: No | AP2: Kabupaten/Kota | AQ2: Skala Usaha | AU2: Jumlah Total | AV2: No | AW2: Kabupaten/Kota | AX2: Skala Usaha | BB2: Jumlah Total | BC2: No | BD2: Kabupaten/Kota | BE2: Skala Usaha | BI2: Jumlah Total | BJ2: No | BK2: Kabupaten/Kota | BL2: Skala Usaha | BP2: Jumlah Total | BQ2: No | BR2: Kabupaten/Kota | BS2: Skala Usaha | BW2: Jumlah Total | BX2: No | BY2: Kabupaten/Kota | BZ2: Skala Usaha | CD2: Jumlah Total | CE2: No | CF2: Kabupaten/Kota | CG2: Skala Usaha | CK2: Jumlah Total | CL2: No | CM2: Kabupaten/Kota | CN2: Skala Usaha | CR2: Jumlah Total | CS2: No | CT2: Kabupaten/Kota | CU2: Skala Usaha | CY2: Jumlah Total | CZ2: No | DA2: Kabupaten/Kota | DB2: Skala Usaha | DF2: Jumlah Total | DG2: No | DH2: Kabupaten/Kota | DI2: Skala Usaha | DM2: Jumlah Total | DN2: No | DO2: Kabupaten/Kota | DP2: Skala Usaha | DT2: Jumlah Total | DU2: No | DV2: Kabupaten/Kota | DW2: Skala Usaha | EA2: Jumlah Total | EB2: No | EC2: Kabupaten/Kota | ED2: Skala Usaha | EH2: Jumlah Total
C3: Fermentasi | D3: Pelumatan Daging Ikan | E3: Pembekuan | F3: Pemindangan | G3: Penanganan Produk Segar | H3: Pengalengan | I3: Pengasapan/ Pemanggangan | J3: Pereduksian/ Ekstraksi | K3: Penggaraman/ Pengeringan | L3: Pengolahan Lainnya | M3: Pengecer | N3: Pengumpul/ Pedagang Besar/ Distributor | R3: Fermentasi | S3: Pelumatan Daging Ikan | T3: Pembekuan | U3: Pemindangan | V3: Penanganan Produk Segar | W3: Pengalengan | X3: Pengasapan/ Pemanggangan | Y3: Pereduksian/ Ekstraksi | Z3: Penggaraman/ Pengeringan | AA3: Pengolahan Lainnya | AE3: Pengecer | AF3: Pengumpul/Pedagang Besar/Distributor | AJ3: Mikro | AK3: Kecil | AL3: Menengah | AM3: Besar | AQ3: Mikro | AR3: Kecil | AS3: Menengah | AT3: Besar | AX3: Mikro | AY3: Kecil | AZ3: Menengah | BA3: Besar | BE3: Mikro | BF3: Kecil | BG3: Menengah | BH3: Besar | BL3: Mikro | BM3: Kecil | BN3: Menengah | BO3: Besar | BS3: Mikro | BT3: Kecil | BU3: Menengah | BV3: Besar | BZ3: Mikro | CA3: Kecil | CB3: Menengah | CC3: Besar | CG3: Mikro | CH3: Kecil | CI3: Menengah | CJ3: Besar | CN3: Mikro | CO3: Kecil | CP3: Menengah | CQ3: Besar | CU3: Mikro | CV3: Kecil | CW3: Menengah | CX3: Besar | DB3: Mikro | DC3: Kecil | DD3: Menengah | DE3: Besar | DI3: Mikro | DJ3: Kecil | DK3: Menengah | DL3: Besar | DP3: Mikro | DQ3: Kecil | DR3: Menengah | DS3: Besar | DW3: Mikro | DX3: Kecil | DY3: Menengah | DZ3: Besar | ED3: Mikro | EE3: Kecil | EF3: Menengah | EG3: Besar
A4: 01 | B4: KAB. PACITAN | C4: =BI4 -> 40019.128 | D4: =BP4 -> 1811718.1 | E4: =BW4 -> 2733668.2 | F4: =CD4 -> 13344.48 | G4: =CK4 -> 1.4934163e+08 | H4: =CR4 -> 0 | I4: =CY4 -> 17517.568 | J4: =DM4 -> 8403.9889 | K4: =DF4 -> 11569.168 | L4: =DT4 -> 42522.761 | M4: =EH4 -> 63971.377 | N4: =EA4 -> 4303.8455 | O4: =SUM(C4:N4) -> 1.5408867e+08 | P4: 01 | Q4: KAB. PACITAN | R4: =C4 -> 40019.128 | S4: =D4 -> 1811718.1 | T4: =E4 -> 2733668.2 | U4: =F4 -> 13344.48 | V4: =G4 -> 1.4934163e+08 | W4: =H4 -> 0 | X4: =I4 -> 17517.568 | Y4: =J4 -> 8403.9889 | ... AA4: =L4 -> 42522.761 | AB4: =SUM(R4:AA4) -> 1.5402039e+08 | AC4: 01 | AD4: KAB. PACITAN | AE4: =M4 -> 63971.377 | AF4: =N4 -> 4303.8455 | AG4: =SUM(AE4:AF4) -> 68275.223 | AH4: 01 | AI4: KAB. PACITAN | AJ4: =AQ4+AX4 -> 1.5223342e+08 | AK4: =AR4+AY4 -> 1717480.4 | AL4: =AS4+AZ4 -> 137765.55 | AM4: =AT4+BA4 -> 0 | AN4: =SUM(AJ4:AM4) -> 1.5408867e+08 | AO4: 01 | AP4: KAB. PACITAN | AQ4: =BE4+BL4+BS4+BZ4+CG4+CN4+CU4+DB4+DI4+DP4 -> 1.5216758e+08 | AR4: =BF4+BM4+BT4+CA4+CH4+CO4+CV4+DC4+DJ4+DQ4 -> 1715047.3 | AS4: =BG4+BN4+BU4+CB4+CI4+CP4+CW4+DD4+DK4+DR4 -> 137765.55 | AT4: =BH4+BO4+BV4+CC4+CJ4+CQ4+CX4+DE4+DL4+DS4 -> 0 | AU4: =SUM(AQ4:AT4) -> 1.5402039e+08 | AV4: 01 | AW4: KAB. PACITAN | AX4: =DW4+ED4 -> 65842.175 | AY4: =DX4+EE4 -> 2433.0482 | AZ4: =DY4+EF4 -> 0 | BA4: =DZ4+EG4 -> 0 | BB4: =SUM(AX4:BA4) -> 68275.223 | BC4: 01 | BD4: KAB. PACITAN | BE4: 40019.128 | BF4: 0 | BG4: 0 | BH4: 0 | BI4: 40019.128 | BJ4: 01 | BK4: KAB. PACITAN | BL4: 93609.314 | BM4: 1580343.2 | BN4: 137765.55 | BO4: 0 | BP4: 1811718.1 | BQ4: 01 | BR4: KAB. PACITAN | BS4: 2733668.2 | BT4: 0 | BU4: 0 | BV4: 0 | BW4: 2733668.2 | BX4: 01 | BY4: KAB. PACITAN | BZ4: 13344.48 | CA4: 0 | CB4: 0 | CC4: 0 | CD4: 13344.48 | CE4: 01 | CF4: KAB. PACITAN | CG4: 1.4920693e+08 | CH4: 134704.1 | CI4: 0 | CJ4: 0 | CK4: 1.4934163e+08 | CL4: 01 | CM4: KAB. PACITAN | CN4: 0 | CO4: 0 | CP4: 0 | CQ4: 0 | CR4: 0 | CS4: 01 | CT4: KAB. PACITAN | CU4: 17517.568 | CV4: 0 | CW4: 0 | CX4: 0 | CY4: 17517.568 | CZ4: 01 | DA4: KAB. PACITAN | DB4: 11569.168 | DC4: 0 | DD4: 0 | DE4: 0 | DF4: 11569.168 | DG4: 01 | DH4: KAB. PACITAN | DI4: 8403.9889 | DJ4: 0 | DK4: 0 | DL4: 0 | DM4: 8403.9889 | DN4: 01 | DO4: KAB. PACITAN | DP4: 42522.761 | DQ4: 0 | DR4: 0 | DS4: 0 | DT4: 42522.761 | DU4: 01 | DV4: KAB. PACITAN | DW4: 1870.7972 | DX4: 2433.0482 | DY4: 0 | DZ4: 0 | EA4: 4303.8455 | EB4: 01 | EC4: KAB. PACITAN | ED4: 63971.377 | EE4: 0 | EF4: 0 | EG4: 0 | EH4: 63971.377
A5: 02 | B5: KAB. PONOROGO | C5: =BI5 -> 0 | D5: =BP5 -> 27586.032 | E5: =BW5 -> 0 | F5: =CD5 -> 0 | G5: =CK5 -> 803.63239 | H5: =CR5 -> 0 | I5: =CY5 -> 0 | J5: =DM5 -> 0 | K5: =DF5 -> 0 | L5: =DT5 -> 775129.51 | M5: =EH5 -> 112758.24 | N5: =EA5 -> 1629878.2 | O5: =SUM(C5:N5) -> 2546155.7 | P5: 02 | Q5: KAB. PONOROGO | R5: =C5 -> 0 | S5: =D5 -> 27586.032 | T5: =E5 -> 0 | U5: =F5 -> 0 | V5: =G5 -> 803.63239 | W5: =H5 -> 0 | X5: =I5 -> 0 | Y5: =J5 -> 0 | ... AA5: =L5 -> 775129.51 | AB5: =SUM(R5:AA5) -> 803519.18 | AC5: 02 | AD5: KAB. PONOROGO | AE5: =M5 -> 112758.24 | AF5: =N5 -> 1629878.2 | AG5: =SUM(AE5:AF5) -> 1742636.5 | AH5: 02 | AI5: KAB. PONOROGO | AJ5: =AQ5+AX5 -> 921320.92 | AK5: =AR5+AY5 -> 322273.55 | AL5: =AS5+AZ5 -> 1302561.2 | AM5: =AT5+BA5 -> 0 | AN5: =SUM(AJ5:AM5) -> 2546155.7 | AO5: 02 | AP5: KAB. PONOROGO | AQ5: =BE5+BL5+BS5+BZ5+CG5+CN5+CU5+DB5+DI5+DP5 -> 802204.42 | AR5: =BF5+BM5+BT5+CA5+CH5+CO5+CV5+DC5+DJ5+DQ5 -> 1314.7545 | AS5: =BG5+BN5+BU5+CB5+CI5+CP5+CW5+DD5+DK5+DR5 -> 0 | AT5: =BH5+BO5+BV5+CC5+CJ5+CQ5+CX5+DE5+DL5+DS5 -> 0 | AU5: =SUM(AQ5:AT5) -> 803519.18 | AV5: 02 | AW5: KAB. PONOROGO | AX5: =DW5+ED5 -> 119116.49 | AY5: =DX5+EE5 -> 320958.79 | AZ5: =DY5+EF5 -> 1302561.2 | BA5: =DZ5+EG5 -> 0 | BB5: =SUM(AX5:BA5) -> 1742636.5 | BC5: 02 | BD5: KAB. PONOROGO | BE5: 0 | BF5: 0 | BG5: 0 | BH5: 0 | BI5: 0 | BJ5: 02 | BK5: KAB. PONOROGO | BL5: 26334.895 | BM5: 1251.1373 | BN5: 0 | BO5: 0 | BP5: 27586.032 | BQ5: 02 | BR5: KAB. PONOROGO | BS5: 0 | BT5: 0 | BU5: 0 | BV5: 0 | BW5: 0 | BX5: 02 | BY5: KAB. PONOROGO | BZ5: 0 | CA5: 0 | CB5: 0 | CC5: 0 | CD5: 0 | CE5: 02 | CF5: KAB. PONOROGO | CG5: 803.63239 | CH5: 0 | CI5: 0 | CJ5: 0 | CK5: 803.63239 | CL5: 02 | CM5: KAB. PONOROGO | CN5: 0 | CO5: 0 | CP5: 0 | CQ5: 0 | CR5: 0 | CS5: 02 | CT5: KAB. PONOROGO | CU5: 0 | CV5: 0 | CW5: 0 | CX5: 0 | CY5: 0 | CZ5: 02 | DA5: KAB. PONOROGO | DB5: 0 | DC5: 0 | DD5: 0 | DE5: 0 | DF5: 0 | DG5: 02 | DH5: KAB. PONOROGO | DI5: 0 | DJ5: 0 | DK5: 0 | DL5: 0 | DM5: 0 | DN5: 02 | DO5: KAB. PONOROGO | DP5: 775065.89 | DQ5: 63.617152 | DR5: 0 | DS5: 0 | DT5: 775129.51 | DU5: 02 | DV5: KAB. PONOROGO | DW5: 21626.376 | DX5: 305690.68 | DY5: 1302561.2 | DZ5: 0 | EA5: 1629878.2 | EB5: 02 | EC5: KAB. PONOROGO | ED5: 97490.119 | EE5: 15268.117 | EF5: 0 | EG5: 0 | EH5: 112758.24
A6: 03 | B6: KAB. TRENGGALEK | C6: =BI6 -> 0 | D6: =BP6 -> 17785.392 | E6: =BW6 -> 7649326.4 | F6: =CD6 -> 6513279.2 | G6: =CK6 -> 0 | H6: =CR6 -> 0 | I6: =CY6 -> 745701.69 | J6: =DM6 -> 0 | K6: =DF6 -> 1082926.8 | L6: =DT6 -> 2445.9911 | M6: =EH6 -> 3702769.7 | N6: =EA6 -> 3351243.2 | O6: =SUM(C6:N6) -> 23065478 | P6: 03 | Q6: KAB. TRENGGALEK | R6: =C6 -> 0 | S6: =D6 -> 17785.392 | T6: =E6 -> 7649326.4 | U6: =F6 -> 6513279.2 | V6: =G6 -> 0 | W6: =H6 -> 0 | X6: =I6 -> 745701.69 | Y6: =J6 -> 0 | ... AA6: =L6 -> 2445.9911 | AB6: =SUM(R6:AA6) -> 16011465 | AC6: 03 | AD6: KAB. TRENGGALEK | AE6: =M6 -> 3702769.7 | AF6: =N6 -> 3351243.2 | AG6: =SUM(AE6:AF6) -> 7054012.8 | AH6: 03 | AI6: KAB. TRENGGALEK | AJ6: =AQ6+AX6 -> 2631404.4 | AK6: =AR6+AY6 -> 3742598.1 | AL6: =AS6+AZ6 -> 8215126.4 | AM6: =AT6+BA6 -> 8476349.3 | AN6: =SUM(AJ6:AM6) -> 23065478 | AO6: 03 | AP6: KAB. TRENGGALEK | AQ6: =BE6+BL6+BS6+BZ6+CG6+CN6+CU6+DB6+DI6+DP6 -> 773861.41 | AR6: =BF6+BM6+BT6+CA6+CH6+CO6+CV6+DC6+DJ6+DQ6 -> 1681435.4 | AS6: =BG6+BN6+BU6+CB6+CI6+CP6+CW6+DD6+DK6+DR6 -> 5525139.3 | AT6: =BH6+BO6+BV6+CC6+CJ6+CQ6+CX6+DE6+DL6+DS6 -> 8031029.3 | AU6: =SUM(AQ6:AT6) -> 16011465 | AV6: 03 | AW6: KAB. TRENGGALEK | AX6: =DW6+ED6 -> 1857543 | AY6: =DX6+EE6 -> 2061162.7 | AZ6: =DY6+EF6 -> 2689987.1 | BA6: =DZ6+EG6 -> 445320.06 | BB6: =SUM(AX6:BA6) -> 7054012.8 | BC6: 03 | BD6: KAB. TRENGGALEK | BE6: 0 | BF6: 0 | BG6: 0 | BH6: 0 | BI6: 0 | BJ6: 03 | BK6: KAB. TRENGGALEK | BL6: 17785.392 | BM6: 0 | BN6: 0 | BO6: 0 | BP6: 17785.392 | BQ6: 03 | BR6: KAB. TRENGGALEK | BS6: 0 | BT6: 0 | BU6: 0 | BV6: 7649326.4 | BW6: 7649326.4 | BX6: 03 | BY6: KAB. TRENGGALEK | BZ6: 16800 | CA6: 589636.93 | CB6: 5525139.3 | CC6: 381702.91 | CD6: 6513279.2 | CE6: 03 | CF6: KAB. TRENGGALEK | CG6: 0 | CH6: 0 | CI6: 0 | CJ6: 0 | CK6: 0 | CL6: 03 | CM6: KAB. TRENGGALEK | CN6: 0 | CO6: 0 | CP6: 0 | CQ6: 0 | CR6: 0 | CS6: 03 | CT6: KAB. TRENGGALEK | CU6: 705553.16 | CV6: 40148.531 | CW6: 0 | CX6: 0 | CY6: 745701.69 | CZ6: 03 | DA6: KAB. TRENGGALEK | DB6: 31276.869 | DC6: 1051649.9 | DD6: 0 | DE6: 0 | DF6: 1082926.8 | DG6: 03 | DH6: KAB. TRENGGALEK | DI6: 0 | DJ6: 0 | DK6: 0 | DL6: 0 | DM6: 0 | DN6: 03 | DO6: KAB. TRENGGALEK | DP6: 2445.9911 | DQ6: 0 | DR6: 0 | DS6: 0 | DT6: 2445.9911 | DU6: 03 | DV6: KAB. TRENGGALEK | DW6: 0 | DX6: 236787.25 | DY6: 2669135.9 | DZ6: 445320.06 | EA6: 3351243.2 | EB6: 03 | EC6: KAB. TRENGGALEK | ED6: 1857543 | EE6: 1824375.4 | EF6: 20851.246 | EG6: 0 | EH6: 3702769.7
