Workbook

Sheet LAUT
A1: Kabupaten/Kota | B1: PERAIRAN PANTAI | C1: TOTAL | D1: NILAI PRODUKSI | E1: JANUARI | F1: NILAI PRODUKSI | G1: FEBRUARI | H1: NILAI PRODUKSI | I1: MARET | J1: NILAI PRODUKSI | K1: TW I | L1: NILAI PRODUKSI | M1: APRIL | N1: NILAI PRODUKSI | O1: MEI | P1: NILAI PRODUKSI | Q1: JUNI | R1: NILAI PRODUKSI | S1: TW II | T1: NILAI PRODUKSI | U1: JULI | V1: NILAI PRODUKSI | W1: AGUSTUS | X1: NILAI PRODUKSI | Y1: SEPTEMBER | Z1: NILAI PRODUKSI | AA1: TW III | AB1: NILAI PRODUKSI | AC1: OKTOBER | AD1: NILAI PRODUKSI | AE1: NOVEMBER | AF1: NILAI PRODUKSI | AG1: DESEMBER | AH1: NILAI PRODUKSI | AI1: TWIV | AJ1: NILAI PRODUKSI
A2: Pacitan | B2: Selatan Jawa | C2: =K2+S2+AA2+AI2 -> 7681.115 | D2: =L2+T2+AB2+AJ2 -> 145941185 | E2: 188.696 | F2: =E2*19000 -> 3585224 | G2: 231.34 | H2: =G2*19000 -> 4395460 | I2: 321.078 | J2: =I2*19000 -> 6100482 | K2: =E2+G2+I2 -> 741.114 | L2: =K2*19000 -> 14081166 | M2: 638.547 | N2: =M2*19000 -> 12132393 | O2: 737.298 | P2: =O2*19000 -> 14008662 | Q2: 666.262 | R2: =Q2*19000 -> 12658978 | S2: =M2+O2+Q2 -> 2042.107 | T2: =S2*19000 -> 38800033 | U2: 937.3 | V2: =U2*19000 -> 17808700 | W2: 1622.1 | X2: =W2*19000 -> 30819900 | Y2: 1135.6 | Z2: =Y2*19000 -> 21576400 | AA2: =U2+W2+Y2 -> 3695 | AB2: =AA2*19000 -> 70205000 | AC2: 614.244 | AD2: =AC2*19000 -> 11670636 | AE2: 318.26 | AF2: =AE2*19000 -> 6046940 | AG2: 270.39 | AH2: =AG2*19000 -> 5137410 | AI2: =AC2+AE2+AG2 -> 1202.894 | AJ2: =AI2*19000 -> 22854986
A3: PPP Tamperan | B3: Selatan Jawa | C3: =K3+S3+AA3+AI3 -> 6150.9 | D3: =L3+T3+AB3+AJ3 -> 116867100 | E3: 273.81 | F3: =E3*19000 -> 5202390 | G3: 212.63 | H3: =G3*19000 -> 4039970 | I3: 337.55 | J3: =I3*19000 -> 6413450 | K3: =E3+G3+I3 -> 823.99 | L3: =K3*19000 -> 15655810 | M3: 366.99 | N3: =M3*19000 -> 6972810 | O3: 676.4 | P3: =O3*19000 -> 12851600 | Q3: 948.06 | R3: =Q3*19000 -> 18013140 | S3: =M3+O3+Q3 -> 1991.45 | T3: =S3*19000 -> 37837550 | U3: 785.06 | V3: =U3*19000 -> 14916140 | W3: 775.52 | X3: =W3*19000 -> 14734880 | Y3: 574.18 | Z3: =Y3*19000 -> 10909420 | AA3: =U3+W3+Y3 -> 2134.76 | AB3: =AA3*19000 -> 40560440 | AC3: 476.06 | AD3: =AC3*19000 -> 9045140 | AE3: 321.54 | AF3: =AE3*19000 -> 6109260 | AG3: 403.1 | AH3: =AG3*19000 -> 7658900 | AI3: =AC3+AE3+AG3 -> 1200.7 | AJ3: =AI3*19000 -> 22813300
A4: Trenggalek | B4: Selatan Jawa | C4: =K4+S4+AA4+AI4 -> 290.985 | D4: =L4+T4+AB4+AJ4 -> 5528715 | E4: 40.255 | F4: =E4*19000 -> 764845 | G4: 30.67 | H4: =G4*19000 -> 582730 | I4: 39.759 | J4: =I4*19000 -> 755421 | K4: =E4+G4+I4 -> 110.684 | L4: =K4*19000 -> 2102996 | M4: 115.512 | N4: =M4*19000 -> 2194728 | O4: 45.522 | P4: =O4*19000 -> 864918 | Q4: 19.267 | R4: =Q4*19000 -> 366073 | S4: =M4+O4+Q4 -> 180.301 | T4: =S4*19000 -> 3425719 | V4: =U4*19000 -> 0 | X4: =W4*19000 -> 0 | Z4: =Y4*19000 -> 0 | AA4: =U4+W4+Y4 -> 0 | AB4: =AA4*19000 -> 0 | AD4: =AC4*19000 -> 0 | AF4: =AE4*19000 -> 0 | AH4: =AG4*19000 -> 0 | AI4: =AC4+AE4+AG4 -> 0 | AJ4: =AI4*19000 -> 0
A5: PPN Prigi | B5: Selatan Jawa | C5: =K5+S5+AA5+AI5 -> 11910.61 | D5: =L5+T5+AB5+AJ5 -> 226301590 | E5: 248.12 | F5: =E5*19000 -> 4714280 | G5: 98.99 | H5: =G5*19000 -> 1880810 | I5: 596.51 | J5: =I5*19000 -> 11333690 | K5: =E5+G5+I5 -> 943.62 | L5: =K5*19000 -> 17928780 | M5: 1401.66 | N5: =M5*19000 -> 26631540 | O5: 697.17 | P5: =O5*19000 -> 13246230 | Q5: 373.86 | R5: =Q5*19000 -> 7103340 | S5: =M5+O5+Q5 -> 2472.69 | T5: =S5*19000 -> 46981110 | U5: 4039.07 | V5: =U5*19000 -> 76742330 | W5: 1158.93 | X5: =W5*19000 -> 22019670 | Y5: 2002.21 | Z5: =Y5*19000 -> 38041990 | AA5: =U5+W5+Y5 -> 7200.21 | AB5: =AA5*19000 -> 136803990 | AC5: 975.22 | AD5: =AC5*19000 -> 18529180 | AE5: 202.08 | AF5: =AE5*19000 -> 3839520 | AG5: 116.79 | AH5: =AG5*19000 -> 2219010 | AI5: =AC5+AE5+AG5 -> 1294.09 | AJ5: =AI5*19000 -> 24587710
A6: Tulungagung | B6: Selatan Jawa | C6: =K6+S6+AA6+AI6 -> 9791.2 | D6: =L6+T6+AB6+AJ6 -> 186032800 | E6: 1197.3 | F6: =E6*19000 -> 22748700 | G6: 821.5 | H6: =G6*19000 -> 15608500 | I6: 607 | J6: =I6*19000 -> 11533000 | K6: =E6+G6+I6 -> 2625.8 | L6: =K6*19000 -> 49890200 | M6: 560.5 | N6: =M6*19000 -> 10649500 | O6: 985.8 | P6: =O6*19000 -> 18730200 | Q6: 905.9 | R6: =Q6*19000 -> 17212100 | S6: =M6+O6+Q6 -> 2452.2 | T6: =S6*19000 -> 46591800 | U6: 796.8 | V6: =U6*19000 -> 15139200 | W6: 994.6 | X6: =W6*19000 -> 18897400 | Y6: 706.6 | Z6: =Y6*19000 -> 13425400 | AA6: =U6+W6+Y6 -> 2498 | AB6: =AA6*19000 -> 47462000 | AC6: 1121.7 | AD6: =AC6*19000 -> 21312300 | AE6: 545 | AF6: =AE6*19000 -> 10355000 | AG6: 548.5 | AH6: =AG6*19000 -> 10421500 | AI6: =AC6+AE6+AG6 -> 2215.2 | AJ6: =AI6*19000 -> 42088800
A7: PPP Popoh | B7: Selatan Jawa | C7: =K7+S7+AA7+AI7 -> 6596.66 | D7: =L7+T7+AB7+AJ7 -> 125336540 | E7: 306.14 | F7: =E7*19000 -> 5816660 | G7: 215.62 | H7: =G7*19000 -> 4096780 | I7: 322.4 | J7: =I7*19000 -> 6125600 | K7: =E7+G7+I7 -> 844.16 | L7: =K7*19000 -> 16039040 | M7: 313.57 | N7: =M7*19000 -> 5957830 | O7: 514.66 | P7: =O7*19000 -> 9778540 | Q7: 517.17 | R7: =Q7*19000 -> 9826230 | S7: =M7+O7+Q7 -> 1345.4 | T7: =S7*19000 -> 25562600 | U7: 1114.67 | V7: =U7*19000 -> 21178730 | W7: 832.11 | X7: =W7*19000 -> 15810090 | Y7: 928.46 | Z7: =Y7*19000 -> 17640740 | AA7: =U7+W7+Y7 -> 2875.24 | AB7: =AA7*19000 -> 54629560 | AC7: 753.1 | AD7: =AC7*19000 -> 14308900 | AE7: 376.8 | AF7: =AE7*19000 -> 7159200 | AG7: 401.96 | AH7: =AG7*19000 -> 7637240 | AI7: =AC7+AE7+AG7 -> 1531.86 | AJ7: =AI7*19000 -> 29105340
A8: IPP Sine | B8: Selatan Jawa | C8: =K8+S8+AA8+AI8 -> 4105.39 | D8: =L8+T8+AB8+AJ8 -> 78002410 | E8: 289.02 | F8: =E8*19000 -> 5491380 | G8: 254.06 | H8: =G8*19000 -> 4827140 | I8: 195.52 | J8: =I8*19000 -> 3714880 | K8: =E8+G8+I8 -> 738.6 | L8: =K8*19000 -> 14033400 | M8: 289.37 | N8: =M8*19000 -> 5498030 | O8: 313.49 | P8: =O8*19000 -> 5956310 | Q8: 236.59 | R8: =Q8*19000 -> 4495210 | S8: =M8+O8+Q8 -> 839.45 | T8: =S8*19000 -> 15949550 | U8: 526.99 | V8: =U8*19000 -> 10012810 | W8: 483.47 | X8: =W8*19000 -> 9185930 | Y8: 448.08 | Z8: =Y8*19000 -> 8513520 | AA8: =U8+W8+Y8 -> 1458.54 | AB8: =AA8*19000 -> 27712260 | AC8: 375.35 | AD8: =AC8*19000 -> 7131650 | AE8: 340.92 | AF8: =AE8*19000 -> 6477480 | AG8: 352.53 | AH8: =AG8*19000 -> 6698070 | AI8: =AC8+AE8+AG8 -> 1068.8 | AJ8: =AI8*19000 -> 20307200
A9: Blitar | B9: Selatan Jawa | C9: =K9+S9+AA9+AI9 -> 591.5 | D9: =L9+T9+AB9+AJ9 -> 11238500 | E9: 25.5 | F9: =E9*19000 -> 484500 | G9: 38.2 | H9: =G9*19000 -> 725800 | I9: 54.7 | J9: =I9*19000 -> 1039300 | K9: =E9+G9+I9 -> 118.4 | L9: =K9*19000 -> 2249600 | M9: 62.4 | N9: =M9*19000 -> 1185600 | O9: 47.3 | P9: =O9*19000 -> 898700 | Q9: 29.4 | R9: =Q9*19000 -> 558600 | S9: =M9+O9+Q9 -> 139.1 | T9: =S9*19000 -> 2642900 | U9: 59.2 | V9: =U9*19000 -> 1124800 | W9: 63.6 | X9: =W9*19000 -> 1208400 | Y9: 68.7 | Z9: =Y9*19000 -> 1305300 | AA9: =U9+W9+Y9 -> 191.5 | AB9: =AA9*19000 -> 3638500 | AC9: 50 | AD9: =AC9*19000 -> 950000 | AE9: 47.7 | AF9: =AE9*19000 -> 906300 | AG9: 44.8 | AH9: =AG9*19000 -> 851200 | AI9: =AC9+AE9+AG9 -> 142.5 | AJ9: =AI9*19000 -> 2707500
A10: IPP Tambakrejo | B10: Selatan Jawa | C10: =K10+S10+AA10+AI10 -> 2953.65 | D10: =L10+T10+AB10+AJ10 -> 56119350 | E10: 98.01 | F10: =E10*19000 -> 1862190 | G10: 98.36 | H10: =G10*19000 -> 1868840 | I10: 48.31 | J10: =I10*19000 -> 917890 | K10: =E10+G10+I10 -> 244.68 | L10: =K10*19000 -> 4648920 | M10: 174.18 | N10: =M10*19000 -> 3309420 | O10: 110.85 | P10: =O10*19000 -> 2106150 | Q10: 163.29 | R10: =Q10*19000 -> 3102510 | S10: =M10+O10+Q10 -> 448.32 | T10: =S10*19000 -> 8518080 | U10: 471.04 | V10: =U10*19000 -> 8949760 | W10: 419.21 | X10: =W10*19000 -> 7964990 | Y10: 336.85 | Z10: =Y10*19000 -> 6400150 | AA10: =U10+W10+Y10 -> 1227.1 | AB10: =AA10*19000 -> 23314900 | AC10: 370 | AD10: =AC10*19000 -> 7030000 | AE10: 363.55 | AF10: =AE10*19000 -> 6907450 | AG10: 300 | AH10: =AG10*19000 -> 5700000 | AI10: =AC10+AE10+AG10 -> 1033.55 | AJ10: =AI10*19000 -> 19637450
A11: Malang | B11: Selatan Jawa | C11: =K11+S11+AA11+AI11 -> 8592.423 | D11: =L11+T11+AB11+AJ11 -> 163256037 | E11: 1167.465 | F11: =E11*19000 -> 22181835 | G11: 639.33 | H11: =G11*19000 -> 12147270 | I11: 1382.284 | J11: =I11*19000 -> 26263396 | K11: =E11+G11+I11 -> 3189.079 | L11: =K11*19000 -> 60592501 | M11: 1129.343 | N11: =M11*19000 -> 21457517 | O11: 883.275 | P11: =O11*19000 -> 16782225 | Q11: 896.166 | R11: =Q11*19000 -> 17027154 | S11: =M11+O11+Q11 -> 2908.784 | T11: =S11*19000 -> 55266896 | U11: 925.357 | V11: =U11*19000 -> 17581783 | W11: 791.525 | X11: =W11*19000 -> 15038975 | Y11: 334.547 | Z11: =Y11*19000 -> 6356393 | AA11: =U11+W11+Y11 -> 2051.429 | AB11: =AA11*19000 -> 38977151 | AC11: 199.03 | AD11: =AC11*19000 -> 3781570 | AE11: 144.05 | AF11: =AE11*19000 -> 2736950 | AG11: 100.051 | AH11: =AG11*19000 -> 1900969 | AI11: =AC11+AE11+AG11 -> 443.131 | AJ11: =AI11*19000 -> 8419489
A12: PPP Pondokdadap | B12: Selatan Jawa | C12: =K12+S12+AA12+AI12 -> 20895.1 | D12: =L12+T12+AB12+AJ12 -> 397006900 | E12: 43.71 | F12: =E12*19000 -> 830490 | G12: 763.88 | H12: =G12*19000 -> 14513720 | I12: 1575.94 | J12: =I12*19000 -> 29942860 | K12: =E12+G12+I12 -> 2383.53 | L12: =K12*19000 -> 45287070 | M12: 1532.39 | N12: =M12*19000 -> 29115410 | O12: 1950.31 | P12: =O12*19000 -> 37055890 | Q12: 2475.56 | R12: =Q12*19000 -> 47035640 | S12: =M12+O12+Q12 -> 5958.26 | T12: =S12*19000 -> 113206940 | U12: 2753.87 | V12: =U12*19000 -> 52323530 | W12: 2991.79 | X12: =W12*19000 -> 56844010 | Y12: 2431.71 | Z12: =Y12*19000 -> 46202490 | AA12: =U12+W12+Y12 -> 8177.37 | AB12: =AA12*19000 -> 155370030 | AC12: 1955.45 | AD12: =AC12*19000 -> 37153550 | AE12: 1320.35 | AF12: =AE12*19000 -> 25086650 | AG12: 1100.14 | AH12: =AG12*19000 -> 20902660 | AI12: =AC12+AE12+AG12 -> 4375.94 | AJ12: =AI12*19000 -> 83142860
A13: Lumajang | B13: Selatan Jawa | C13: =K13+S13+AA13+AI13 -> 6365.4 | D13: =L13+T13+AB13+AJ13 -> 120942600 | E13: 509 | F13: =E13*19000 -> 9671000 | G13: 488.9 | H13: =G13*19000 -> 9289100 | I13: 621.2 | J13: =I13*19000 -> 11802800 | K13: =E13+G13+I13 -> 1619.1 | L13: =K13*19000 -> 30762900 | M13: 311.5 | N13: =M13*19000 -> 5918500 | O13: 336.4 | P13: =O13*19000 -> 6391600 | Q13: 336.4 | R13: =Q13*19000 -> 6391600 | S13: =M13+O13+Q13 -> 984.3 | T13: =S13*19000 -> 18701700 | U13: 430.5 | V13: =U13*19000 -> 8179500 | W13: 612 | X13: =W13*19000 -> 11628000 | Y13: 871.2 | Z13: =Y13*19000 -> 16552800 | AA13: =U13+W13+Y13 -> 1913.7 | AB13: =AA13*19000 -> 36360300 | AC13: 511.4 | AD13: =AC13*19000 -> 9716600 | AE13: 649.4 | AF13: =AE13*19000 -> 12338600 | AG13: 687.5 | AH13: =AG13*19000 -> 13062500 | AI13: =AC13+AE13+AG13 -> 1848.3 | AJ13: =AI13*19000 -> 35117700
A14: Jember | B14: Selatan Jawa | C14: =K14+S14+AA14+AI14 -> 14517.2 | D14: =L14+T14+AB14+AJ14 -> 275826800 | E14: 199.7 | F14: =E14*19000 -> 3794300 | G14: 207.5 | H14: =G14*19000 -> 3942500 | I14: 331.8 | J14: =I14*19000 -> 6304200 | K14: =E14+G14+I14 -> 739 | L14: =K14*19000 -> 14041000 | M14: 418 | N14: =M14*19000 -> 7942000 | O14: 583.2 | P14: =O14*19000 -> 11080800 | Q14: 761.1 | R14: =Q14*19000 -> 14460900 | S14: =M14+O14+Q14 -> 1762.3 | T14: =S14*19000 -> 33483700 | U14: 1254.8 | V14: =U14*19000 -> 23841200 | W14: 1832.7 | X14: =W14*19000 -> 34821300 | Y14: 2835.4 | Z14: =Y14*19000 -> 53872600 | AA14: =U14+W14+Y14 -> 5922.9 | AB14: =AA14*19000 -> 112535100 | AC14: 2547.5 | AD14: =AC14*19000 -> 48402500 | AE14: 2132 | AF14: =AE14*19000 -> 40508000 | AG14: 1413.5 | AH14: =AG14*19000 -> 26856500 | AI14: =AC14+AE14+AG14 -> 6093 | AJ14: =AI14*19000 -> 115767000
A15: IPP Puger | B15: Selatan Jawa | C15: =K15+S15+AA15+AI15 -> 6964.54 | D15: =L15+T15+AB15+AJ15 -> 132326260 | E15: 244.51 | F15: =E15*19000 -> 4645690 | G15: 252.17 | H15: =G15*19000 -> 4791230 | I15: 277.05 | J15: =I15*19000 -> 5263950 | K15: =E15+G15+I15 -> 773.73 | L15: =K15*19000 -> 14700870 | M15: 342.51 | N15: =M15*19000 -> 6507690 | O15: 683.91 | P15: =O15*19000 -> 12994290 | Q15: 776.24 | R15: =Q15*19000 -> 14748560 | S15: =M15+O15+Q15 -> 1802.66 | T15: =S15*19000 -> 34250540 | U15: 950.44 | V15: =U15*19000 -> 18058360 | W15: 876.17 | X15: =W15*19000 -> 16647230 | Y15: 760.6 | Z15: =Y15*19000 -> 14451400 | AA15: =U15+W15+Y15 -> 2587.21 | AB15: =AA15*19000 -> 49156990 | AC15: 612.91 | AD15: =AC15*19000 -> 11645290 | AE15: 637.92 | AF15: =AE15*19000 -> 12120480 | AG15: 550.11 | AH15: =AG15*19000 -> 10452090 | AI15: =AC15+AE15+AG15 -> 1800.94 | AJ15: =AI15*19000 -> 34217860
A16: Banyuwangi | B16: Selatan Jawa | C16: =K16+S16+AA16+AI16 -> 52157.3 | D16: =L16+T16+AB16+AJ16 -> 990988700 | E16: 6202.7 | F16: =E16*19000 -> 117851300 | G16: 3903.7 | H16: =G16*19000 -> 74170300 | I16: 3114.4 | J16: =I16*19000 -> 59173600 | K16: =E16+G16+I16 -> 13220.8 | L16: =K16*19000 -> 251195200 | M16: 4436 | N16: =M16*19000 -> 84284000 | O16: 4907.2 | P16: =O16*19000 -> 93236800 | Q16: 5346.5 | R16: =Q16*19000 -> 101583500 | S16: =M16+O16+Q16 -> 14689.7 | T16: =S16*19000 -> 279104300 | U16: 5532.7 | V16: =U16*19000 -> 105121300 | W16: 3630.6 | X16: =W16*19000 -> 68981400 | Y16: 4316.7 | Z16: =Y16*19000 -> 82017300 | AA16: =U16+W16+Y16 -> 13480 | AB16: =AA16*19000 -> 256120000 | AC16: 5041.1 | AD16: =AC16*19000 -> 95780900 | AE16: 5725.7 | AF16: =AE16*19000 -> 108788300 | AH16: =AG16*19000 -> 0 | AI16: =AC16+AE16+AG16 -> 10766.8 | AJ16: =AI16*19000 -> 204569200
A17: IPP Pancer | B17: Selatan Jawa | C17: =K17+S17+AA17+AI17 -> 4947.11 | D17: =L17+T17+AB17+AJ17 -> 93995090 | E17: 8.87 | F17: =E17*19000 -> 168530 | G17: 22.73 | H17: =G17*19000 -> 431870 | I17: 17.92 | J17: =I17*19000 -> 340480 | K17: =E17+G17+I17 -> 49.52 | L17: =K17*19000 -> 940880 | M17: 35.31 | N17: =M17*19000 -> 670890 | O17: 33.41 | P17: =O17*19000 -> 634790 | Q17: 707.59 | R17: =Q17*19000 -> 13444210 | S17: =M17+O17+Q17 -> 776.31 | T17: =S17*19000 -> 14749890 | U17: 1077.84 | V17: =U17*19000 -> 20478960 | W17: 814.72 | X17: =W17*19000 -> 15479680 | Y17: 508.98 | Z17: =Y17*19000 -> 9670620 | AA17: =U17+W17+Y17 -> 2401.54 | AB17: =AA17*19000 -> 45629260 | AC17: 469.93 | AD17: =AC17*19000 -> 8928670 | AE17: 625 | AF17: =AE17*19000 -> 11875000 | AG17: 624.81 | AH17: =AG17*19000 -> 11871390 | AI17: =AC17+AE17+AG17 -> 1719.74 | AJ17: =AI17*19000 -> 32675060
A18: IPP Grajagan | B18: Selatan Jawa | C18: =K18+S18+AA18+AI18 -> 4426.32 | D18: =L18+T18+AB18+AJ18 -> 84100080 | E18: 117.17 | F18: =E18*19000 -> 2226230 | G18: 67.4 | H18: =G18*19000 -> 1280600 | I18: 112.47 | J18: =I18*19000 -> 2136930 | K18: =E18+G18+I18 -> 297.04 | L18: =K18*19000 -> 5643760 | M18: 60.91 | N18: =M18*19000 -> 1157290 | O18: 112.75 | P18: =O18*19000 -> 2142250 | Q18: 508.94 | R18: =Q18*19000 -> 9669860 | S18: =M18+O18+Q18 -> 682.6 | T18: =S18*19000 -> 12969400 | U18: 612.86 | V18: =U18*19000 -> 11644340 | W18: 872.26 | X18: =W18*19000 -> 16572940 | Y18: 470.05 | Z18: =Y18*19000 -> 8930950 | AA18: =U18+W18+Y18 -> 1955.17 | AB18: =AA18*19000 -> 37148230 | AC18: 325.2 | AD18: =AC18*19000 -> 6178800 | AE18: 559.11 | AF18: =AE18*19000 -> 10623090 | AG18: 607.2 | AH18: =AG18*19000 -> 11536800 | AI18: =AC18+AE18+AG18 -> 1491.51 | AJ18: =AI18*19000 -> 28338690
A19: PPP Muncar | B19: Utara Jawa | C19: =K19+S19+AA19+AI19 -> 10579.62 | D19: =L19+T19+AB19+AJ19 -> 201012780 | E19: 586.21 | F19: =E19*19000 -> 11137990 | G19: 683.91 | H19: =G19*19000 -> 12994290 | I19: 683.91 | J19: =I19*19000 -> 12994290 | K19: =E19+G19+I19 -> 1954.03 | L19: =K19*19000 -> 37126570 | M19: 781.61 | N19: =M19*19000 -> 14850590 | O19: 879.31 | P19: =O19*19000 -> 16706890 | Q19: 977.01 | R19: =Q19*19000 -> 18563190 | S19: =M19+O19+Q19 -> 2637.93 | T19: =S19*19000 -> 50120670 | U19: 1074.72 | V19: =U19*19000 -> 20419680 | W19: 1074.72 | X19: =W19*19000 -> 20419680 | Y19: 977.02 | Z19: =Y19*19000 -> 18563380 | AA19: =U19+W19+Y19 -> 3126.46 | AB19: =AA19*19000 -> 59402740 | AC19: 898.86 | AD19: =AC19*19000 -> 17078340 | AE19: 1082.34 | AF19: =AE19*19000 -> 20564460 | AG19: 880 | AH19: =AG19*19000 -> 16720000 | AI19: =AC19+AE19+AG19 -> 2861.2 | AJ19: =AI19*19000 -> 54362800
A20: Situbondo | B20: Utara Jawa | C20: =K20+S20+AA20+AI20 -> 19607.55 | D20: =L20+T20+AB20+AJ20 -> 372543450 | E20: 1481.4 | F20: =E20*19000 -> 28146600 | G20: 1304.5 | H20: =G20*19000 -> 24785500 | I20: 1423.65 | J20: =I20*19000 -> 27049350 | K20: =E20+G20+I20 -> 4209.55 | L20: =K20*19000 -> 79981450 | M20: 1613.2 | N20: =M20*19000 -> 30650800 | O20: 1528.8 | P20: =O20*19000 -> 29047200 | Q20: 1591.7 | R20: =Q20*19000 -> 30242300 | S20: =M20+O20+Q20 -> 4733.7 | T20: =S20*19000 -> 89940300 | U20: 2003.8 | V20: =U20*19000 -> 38072200 | W20: 1710.2 | X20: =W20*19000 -> 32493800 | Y20: 2032.4 | Z20: =Y20*19000 -> 38615600 | AA20: =U20+W20+Y20 -> 5746.4 | AB20: =AA20*19000 -> 109181600 | AC20: 1616.7 | AD20: =AC20*19000 -> 30717300 | AE20: 1601.6 | AF20: =AE20*19000 -> 30430400 | AG20: 1699.6 | AH20: =AG20*19000 -> 32292400 | AI20: =AC20+AE20+AG20 -> 4917.9 | AJ20: =AI20*19000 -> 93440100
A21: Tuban | B21: Utara Jawa | C21: =K21+S21+AA21+AI21 -> 35233.4 | D21: =L21+T21+AB21+AJ21 -> 669434600 | E21: 3019.7 | F21: =E21*19000 -> 57374300 | G21: 3342.9 | H21: =G21*19000 -> 63515100 | I21: 3112.8 | J21: =I21*19000 -> 59143200 | K21: =E21+G21+I21 -> 9475.4 | L21: =K21*19000 -> 1.800326e+08 | M21: 2919.3 | N21: =M21*19000 -> 55466700 | O21: 2953.2 | P21: =O21*19000 -> 56110800 | Q21: 2755.4 | R21: =Q21*19000 -> 52352600 | S21: =M21+O21+Q21 -> 8627.9 | T21: =S21*19000 -> 163930100 | U21: 2909.8 | V21: =U21*19000 -> 55286200 | W21: 3057.2 | X21: =W21*19000 -> 58086800 | Y21: 3184.1 | Z21: =Y21*19000 -> 60497900 | AA21: =U21+W21+Y21 -> 9151.1 | AB21: =AA21*19000 -> 173870900 | AC21: 2964.8 | AD21: =AC21*19000 -> 56331200 | AE21: 2599.7 | AF21: =AE21*19000 -> 49394300 | AG21: 2414.5 | AH21: =AG21*19000 -> 45875500 | AI21: =AC21+AE21+AG21 -> 7979 | AJ21: =AI21*19000 -> 151601000
A22: PPP Bulu | B22: Utara Jawa | C22: =K22+S22+AA22+AI22 -> 8005.97 | D22: =L22+T22+AB22+AJ22 -> 152113430 | E22: 251.05 | F22: =E22*19000 -> 4769950 | G22: 273.22 | H22: =G22*19000 -> 5191180 | I22: 318.04 | J22: =I22*19000 -> 6042760 | K22: =E22+G22+I22 -> 842.31 | L22: =K22*19000 -> 16003890 | M22: 431.72 | N22: =M22*19000 -> 8202680 | O22: 471.02 | P22: =O22*19000 -> 8949380 | Q22: 727.21 | R22: =Q22*19000 -> 13816990 | S22: =M22+O22+Q22 -> 1629.95 | T22: =S22*19000 -> 30969050 | U22: 903.51 | V22: =U22*19000 -> 17166690 | W22: 977.93 | X22: =W22*19000 -> 18580670 | Y22: 941.17 | Z22: =Y22*19000 -> 17882230 | AA22: =U22+W22+Y22 -> 2822.61 | AB22: =AA22*19000 -> 53629590 | AC22: 947.8 | AD22: =AC22*19000 -> 18008200 | AE22: 913.2 | AF22: =AE22*19000 -> 17350800 | AG22: 850.1 | AH22: =AG22*19000 -> 16151900 | AI22: =AC22+AE22+AG22 -> 2711.1 | AJ22: =AI22*19000 -> 51510900
A23: Lamongan | B23: Utara Jawa | C23: =K23+S23+AA23+AI23 -> 47886.64 | D23: =L23+T23+AB23+AJ23 -> 909846160 | E23: 3867.5 | F23: =E23*19000 -> 73482500 | G23: 4652.5 | H23: =G23*19000 -> 88397500 | I23: 4694.54 | J23: =I23*19000 -> 89196260 | K23: =E23+G23+I23 -> 13214.54 | L23: =K23*19000 -> 2.5107626e+08 | M23: 3944.36 | N23: =M23*19000 -> 74942840 | O23: 4380.58 | P23: =O23*19000 -> 83231020 | Q23: 4811.41 | R23: =Q23*19000 -> 91416790 | S23: =M23+O23+Q23 -> 13136.35 | T23: =S23*19000 -> 249590650 | U23: 3947.37 | V23: =U23*19000 -> 75000030 | W23: 4587.99 | X23: =W23*19000 -> 87171810 | Y23: 4569.55 | Z23: =Y23*19000 -> 86821450 | AA23: =U23+W23+Y23 -> 13104.91 | AB23: =AA23*19000 -> 248993290 | AC23: 4138.69 | AD23: =AC23*19000 -> 78635110 | AE23: 4292.15 | AF23: =AE23*19000 -> 81550850 | AH23: =AG23*19000 -> 0 | AI23: =AC23+AE23+AG23 -> 8430.84 | AJ23: =AI23*19000 -> 160185960
A24: PPN Brondong | B24: Utara Jawa | C24: =K24+S24+AA24+AI24 -> 55988.1 | D24: =L24+T24+AB24+AJ24 -> 1063773900 | E24: 4830.23 | F24: =E24*19000 -> 91774370 | G24: 3997 | H24: =G24*19000 -> 75943000 | I24: 5393 | J24: =I24*19000 -> 102467000 | K24: =E24+G24+I24 -> 14220.23 | L24: =K24*19000 -> 270184370 | M24: 3328 | N24: =M24*19000 -> 63232000 | O24: 4380 | P24: =O24*19000 -> 83220000 | Q24: 2801 | R24: =Q24*19000 -> 53219000 | S24: =M24+O24+Q24 -> 10509 | T24: =S24*19000 -> 199671000 | U24: 3528 | V24: =U24*19000 -> 67032000 | W24: 4588 | X24: =W24*19000 -> 87172000 | Y24: 4929 | Z24: =Y24*19000 -> 93651000 | AA24: =U24+W24+Y24 -> 13045 | AB24: =AA24*19000 -> 247855000 | AC24: 5280 | AD24: =AC24*19000 -> 100320000 | AE24: 6398 | AF24: =AE24*19000 -> 121562000 | AG24: 6535.87 | AH24: =AG24*19000 -> 124181530 | AI24: =AC24+AE24+AG24 -> 18213.87 | AJ24: =AI24*19000 -> 346063530
A25: Gresik | B25: Utara Jawa | C25: =K25+S25+AA25+AI25 -> 9905.3 | D25: =L25+T25+AB25+AJ25 -> 188200700 | E25: 469.4 | F25: =E25*19000 -> 8918600 | G25: 605.5 | H25: =G25*19000 -> 11504500 | I25: 847.4 | J25: =I25*19000 -> 16100600 | K25: =E25+G25+I25 -> 1922.3 | L25: =K25*19000 -> 36523700 | M25: 819.7 | N25: =M25*19000 -> 15574300 | O25: 814.2 | P25: =O25*19000 -> 15469800 | Q25: 570.6 | R25: =Q25*19000 -> 10841400 | S25: =M25+O25+Q25 -> 2204.5 | T25: =S25*19000 -> 41885500 | U25: 636.3 | V25: =U25*19000 -> 12089700 | W25: 951 | X25: =W25*19000 -> 18069000 | Y25: 1273.9 | Z25: =Y25*19000 -> 24204100 | AA25: =U25+W25+Y25 -> 2861.2 | AB25: =AA25*19000 -> 54362800 | AC25: 1069.7 | AD25: =AC25*19000 -> 20324300 | AE25: 971.1 | AF25: =AE25*19000 -> 18450900 | AG25: 876.5 | AH25: =AG25*19000 -> 16653500 | AI25: =AC25+AE25+AG25 -> 2917.3 | AJ25: =AI25*19000 -> 55428700
A26: IPP Bawean | B26: Utara Jawa | C26: =K26+S26+AA26+AI26 -> 5174.03 | D26: =L26+T26+AB26+AJ26 -> 98306570 | E26: 205.87 | F26: =E26*19000 -> 3911530 | G26: 276.84 | H26: =G26*19000 -> 5259960 | I26: 291.59 | J26: =I26*19000 -> 5540210 | K26: =E26+G26+I26 -> 774.3 | L26: =K26*19000 -> 14711700 | M26: 391.15 | N26: =M26*19000 -> 7431850 | O26: 443.48 | P26: =O26*19000 -> 8426120 | Q26: 402.57 | R26: =Q26*19000 -> 7648830 | S26: =M26+O26+Q26 -> 1237.2 | T26: =S26*19000 -> 23506800 | U26: 520.16 | V26: =U26*19000 -> 9883040 | W26: 535.31 | X26: =W26*19000 -> 10170890 | Y26: 516.76 | Z26: =Y26*19000 -> 9818440 | AA26: =U26+W26+Y26 -> 1572.23 | AB26: =AA26*19000 -> 29872370 | AC26: 636.18 | AD26: =AC26*19000 -> 12087420 | AE26: 501.29 | AF26: =AE26*19000 -> 9524510 | AG26: 452.83 | AH26: =AG26*19000 -> 8603770 | AI26: =AC26+AE26+AG26 -> 1590.3 | AJ26: =AI26*19000 -> 30215700
A27: IPP Campurejo | B27: Utara Jawa | C27: =K27+S27+AA27+AI27 -> 3651.07 | D27: =L27+T27+AB27+AJ27 -> 69370330 | E27: 163.31 | F27: =E27*19000 -> 3102890 | G27: 286.74 | H27: =G27*19000 -> 5448060 | I27: 341.02 | J27: =I27*19000 -> 6479380 | K27: =E27+G27+I27 -> 791.07 | L27: =K27*19000 -> 15030330 | M27: 278.35 | N27: =M27*19000 -> 5288650 | O27: 219.07 | P27: =O27*19000 -> 4162330 | Q27: 235.03 | R27: =Q27*19000 -> 4465570 | S27: =M27+O27+Q27 -> 732.45 | T27: =S27*19000 -> 13916550 | U27: 270.94 | V27: =U27*19000 -> 5147860 | W27: 365.93 | X27: =W27*19000 -> 6952670 | Y27: 258.83 | Z27: =Y27*19000 -> 4917770 | AA27: =U27+W27+Y27 -> 895.7 | AB27: =AA27*19000 -> 17018300 | AC27: 535.43 | AD27: =AC27*19000 -> 10173170 | AE27: 444.87 | AF27: =AE27*19000 -> 8452530 | AG27: 251.55 | AH27: =AG27*19000 -> 4779450 | AI27: =AC27+AE27+AG27 -> 1231.85 | AJ27: =AI27*19000 -> 23405150
A28: Kota Surabaya | B28: Utara Jawa | C28: =K28+S28+AA28+AI28 -> 8998.2 | D28: =L28+T28+AB28+AJ28 -> 170965800 | E28: 246.5 | F28: =E28*19000 -> 4683500 | G28: 271 | H28: =G28*19000 -> 5149000 | I28: 505.5 | J28: =I28*19000 -> 9604500 | K28: =E28+G28+I28 -> 1023 | L28: =K28*19000 -> 19437000 | M28: 1078.6 | N28: =M28*19000 -> 20493400 | O28: 1186.6 | P28: =O28*19000 -> 22545400 | Q28: 448.6 | R28: =Q28*19000 -> 8523400 | S28: =M28+O28+Q28 -> 2713.8 | T28: =S28*19000 -> 51562200 | U28: 1460.9 | V28: =U28*19000 -> 27757100 | W28: 1617.4 | X28: =W28*19000 -> 30730600 | Y28: 943.4 | Z28: =Y28*19000 -> 17924600 | AA28: =U28+W28+Y28 -> 4021.7 | AB28: =AA28*19000 -> 76412300 | AC28: 451.2 | AD28: =AC28*19000 -> 8572800 | AE28: 446.9 | AF28: =AE28*19000 -> 8491100 | AG28: 341.6 | AH28: =AG28*19000 -> 6490400 | AI28: =AC28+AE28+AG28 -> 1239.7 | AJ28: =AI28*19000 -> 23554300
A29: Sidoarjo | B29: Utara Jawa | C29: =K29+S29+AA29+AI29 -> 14695.2 | D29: =L29+T29+AB29+AJ29 -> 279208800 | E29: 1354.4 | F29: =E29*19000 -> 25733600 | G29: 1372.3 | H29: =G29*19000 -> 26073700 | I29: 1372.5 | J29: =I29*19000 -> 26077500 | K29: =E29+G29+I29 -> 4099.2 | L29: =K29*19000 -> 77884800 | M29: 1292.5 | N29: =M29*19000 -> 24557500 | O29: 1291.2 | P29: =O29*19000 -> 24532800 | Q29: 1289.6 | R29: =Q29*19000 -> 24502400 | S29: =M29+O29+Q29 -> 3873.3 | T29: =S29*19000 -> 73592700 | U29: 1343.5 | V29: =U29*19000 -> 25526500 | W29: 1345.7 | X29: =W29*19000 -> 25568300 | Y29: 1345.4 | Z29: =Y29*19000 -> 25562600 | AA29: =U29+W29+Y29 -> 4034.6 | AB29: =AA29*19000 -> 76657400 | AC29: 1343.6 | AD29: =AC29*19000 -> 25528400 | AE29: 1344.5 | AF29: =AE29*19000 -> 25545500 | AH29: =AG29*19000 -> 0 | AI29: =AC29+AE29+AG29 -> 2688.1 | AJ29: =AI29*19000 -> 51073900
A30: Pasuruan | B30: Utara Jawa | C30: =K30+S30+AA30+AI30 -> 23946.8 | D30: =L30+T30+AB30+AJ30 -> 454989200 | E30: 2002.9 | F30: =E30*19000 -> 38055100 | G30: 2051.1 | H30: =G30*19000 -> 38970900 | I30: 1387.8 | J30: =I30*19000 -> 26368200 | K30: =E30+G30+I30 -> 5441.8 | L30: =K30*19000 -> 103394200 | M30: 3924.7 | N30: =M30*19000 -> 74569300 | O30: 1668.7 | P30: =O30*19000 -> 31705300 | Q30: 2266.3 | R30: =Q30*19000 -> 43059700 | S30: =M30+O30+Q30 -> 7859.7 | T30: =S30*19000 -> 149334300 | U30: 1500.5 | V30: =U30*19000 -> 28509500 | W30: 1955.8 | X30: =W30*19000 -> 37160200 | Y30: 1781.1 | Z30: =Y30*19000 -> 33840900 | AA30: =U30+W30+Y30 -> 5237.4 | AB30: =AA30*19000 -> 99510600 | AC30: 1880.6 | AD30: =AC30*19000 -> 35731400 | AE30: 1940 | AF30: =AE30*19000 -> 36860000 | AG30: 1587.3 | AH30: =AG30*19000 -> 30158700 | AI30: =AC30+AE30+AG30 -> 5407.9 | AJ30: =AI30*19000 -> 102750100
A31: IPP Lekok | B31: Utara Jawa | C31: =K31+S31+AA31+AI31 -> 2375.7 | D31: =L31+T31+AB31+AJ31 -> 45138300 | E31: 117.64 | F31: =E31*19000 -> 2235160 | G31: 105.76 | H31: =G31*19000 -> 2009440 | I31: 135.36 | J31: =I31*19000 -> 2571840 | K31: =E31+G31+I31 -> 358.76 | L31: =K31*19000 -> 6816440 | M31: 176.69 | N31: =M31*19000 -> 3357110 | O31: 232.8 | P31: =O31*19000 -> 4423200 | Q31: 222.9 | R31: =Q31*19000 -> 4235100 | S31: =M31+O31+Q31 -> 632.39 | T31: =S31*19000 -> 12015410 | U31: 224.74 | V31: =U31*19000 -> 4270060 | W31: 227.51 | X31: =W31*19000 -> 4322690 | Y31: 243.47 | Z31: =Y31*19000 -> 4625930 | AA31: =U31+W31+Y31 -> 695.72 | AB31: =AA31*19000 -> 13218680 | AC31: 241.62 | AD31: =AC31*19000 -> 4590780 | AE31: 247.21 | AF31: =AE31*19000 -> 4696990 | AG31: 200 | AH31: =AG31*19000 -> 3800000 | AI31: =AC31+AE31+AG31 -> 688.83 | AJ31: =AI31*19000 -> 13087770
A32: Kota Pasuruan | B32: Utara Jawa | C32: =K32+S32+AA32+AI32 -> 11036.6 | D32: =L32+T32+AB32+AJ32 -> 209695400 | E32: 730.3 | F32: =E32*19000 -> 13875700 | G32: 843.5 | H32: =G32*19000 -> 16026500 | I32: 1444.8 | J32: =I32*19000 -> 27451200 | K32: =E32+G32+I32 -> 3018.6 | L32: =K32*19000 -> 57353400 | M32: 1690.4 | N32: =M32*19000 -> 32117600 | O32: 1023.8 | P32: =O32*19000 -> 19452200 | Q32: 903 | R32: =Q32*19000 -> 17157000 | S32: =M32+O32+Q32 -> 3617.2 | T32: =S32*19000 -> 68726800 | U32: 843.3 | V32: =U32*19000 -> 16022700 | W32: 823.9 | X32: =W32*19000 -> 15654100 | Y32: 821.5 | Z32: =Y32*19000 -> 15608500 | AA32: =U32+W32+Y32 -> 2488.7 | AB32: =AA32*19000 -> 47285300 | AC32: 672 | AD32: =AC32*19000 -> 12768000 | AE32: 645.5 | AF32: =AE32*19000 -> 12264500 | AG32: 594.6 | AH32: =AG32*19000 -> 11297400 | AI32: =AC32+AE32+AG32 -> 1912.1 | AJ32: =AI32*19000 -> 36329900
A33: IPP Ngemplakrejo | B33: Utara Jawa | C33: =K33+S33+AA33+AI33 -> 4350.77 | D33: =L33+T33+AB33+AJ33 -> 82664630 | E33: 383.85 | F33: =E33*19000 -> 7293150 | G33: 199 | H33: =G33*19000 -> 3781000 | I33: 212.1 | J33: =I33*19000 -> 4029900 | K33: =E33+G33+I33 -> 794.95 | L33: =K33*19000 -> 15104050 | M33: 379.56 | N33: =M33*19000 -> 7211640 | O33: 245.13 | P33: =O33*19000 -> 4657470 | Q33: 217.09 | R33: =Q33*19000 -> 4124710 | S33: =M33+O33+Q33 -> 841.78 | T33: =S33*19000 -> 15993820 | U33: 389.93 | V33: =U33*19000 -> 7408670 | W33: 506.15 | X33: =W33*19000 -> 9616850 | Y33: 506.69 | Z33: =Y33*19000 -> 9627110 | AA33: =U33+W33+Y33 -> 1402.77 | AB33: =AA33*19000 -> 26652630 | AC33: 352.59 | AD33: =AC33*19000 -> 6699210 | AE33: 488.04 | AF33: =AE33*19000 -> 9272760 | AG33: 470.64 | AH33: =AG33*19000 -> 8942160 | AI33: =AC33+AE33+AG33 -> 1311.27 | AJ33: =AI33*19000 -> 24914130
A34: Probolinggo | B34: Utara Jawa | C34: =K34+S34+AA34+AI34 -> 28800.1 | D34: =L34+T34+AB34+AJ34 -> 547201900 | E34: 2152.9 | F34: =E34*19000 -> 40905100 | G34: 2205.6 | H34: =G34*19000 -> 41906400 | I34: 2506.8 | J34: =I34*19000 -> 47629200 | K34: =E34+G34+I34 -> 6865.3 | L34: =K34*19000 -> 130440700 | M34: 3814.4 | N34: =M34*19000 -> 72473600 | O34: 3745.1 | P34: =O34*19000 -> 71156900 | Q34: 2745.1 | R34: =Q34*19000 -> 52156900 | S34: =M34+O34+Q34 -> 10304.6 | T34: =S34*19000 -> 195787400 | U34: 2305.3 | V34: =U34*19000 -> 43800700 | W34: 1902.5 | X34: =W34*19000 -> 36147500 | Y34: 2615.1 | Z34: =Y34*19000 -> 49686900 | AA34: =U34+W34+Y34 -> 6822.9 | AB34: =AA34*19000 -> 129635100 | AC34: 2389.2 | AD34: =AC34*19000 -> 45394800 | AE34: 2418.1 | AF34: =AE34*19000 -> 45943900 | AH34: =AG34*19000 -> 0 | AI34: =AC34+AE34+AG34 -> 4807.3 | AJ34: =AI34*19000 -> 91338700
A35: IPP Paiton | B35: Utara Jawa | C35: =K35+S35+AA35+AI35 -> 1390.57 | D35: =L35+T35+AB35+AJ35 -> 26420830 | E35: 44.03 | F35: =E35*19000 -> 836570 | G35: 142.76 | H35: =G35*19000 -> 2712440 | I35: 37.42 | J35: =I35*19000 -> 710980 | K35: =E35+G35+I35 -> 224.21 | L35: =K35*19000 -> 4259990 | M35: 226.95 | N35: =M35*19000 -> 4312050 | O35: 166.82 | P35: =O35*19000 -> 3169580 | Q35: 239.55 | R35: =Q35*19000 -> 4551450 | S35: =M35+O35+Q35 -> 633.32 | T35: =S35*19000 -> 12033080 | U35: 60.15 | V35: =U35*19000 -> 1142850 | W35: 71.23 | X35: =W35*19000 -> 1353370 | Y35: 45.68 | Z35: =Y35*19000 -> 867920 | AA35: =U35+W35+Y35 -> 177.06 | AB35: =AA35*19000 -> 3364140 | AC35: 108.9 | AD35: =AC35*19000 -> 2069100 | AE35: 123.26 | AF35: =AE35*19000 -> 2341940 | AG35: 123.82 | AH35: =AG35*19000 -> 2352580 | AI35: =AC35+AE35+AG35 -> 355.98 | AJ35: =AI35*19000 -> 6763620
A36: Kota Probolinggo | B36: Utara Jawa | C36: =K36+S36+AA36+AI36 -> 924.14 | D36: =L36+T36+AB36+AJ36 -> 17558660 | E36: 56.1 | F36: =E36*19000 -> 1065900 | G36: 68.8 | H36: =G36*19000 -> 1307200 | I36: 82.2 | J36: =I36*19000 -> 1561800 | K36: =E36+G36+I36 -> 207.1 | L36: =K36*19000 -> 3934900 | M36: 90.9 | N36: =M36*19000 -> 1727100 | O36: 96.52 | P36: =O36*19000 -> 1833880 | Q36: 107.73 | R36: =Q36*19000 -> 2046870 | S36: =M36+O36+Q36 -> 295.15 | T36: =S36*19000 -> 5607850 | U36: 77.52 | V36: =U36*19000 -> 1472880 | W36: 56.9 | X36: =W36*19000 -> 1081100 | Y36: 54.3 | Z36: =Y36*19000 -> 1031700 | AA36: =U36+W36+Y36 -> 188.72 | AB36: =AA36*19000 -> 3585680 | AC36: 65.35 | AD36: =AC36*19000 -> 1241650 | AE36: 78 | AF36: =AE36*19000 -> 1482000 | AG36: 89.82 | AH36: =AG36*19000 -> 1706580 | AI36: =AC36+AE36+AG36 -> 233.17 | AJ36: =AI36*19000 -> 4430230
A37: PPP Mayangan | B37: Utara Jawa | C37: =K37+S37+AA37+AI37 -> 30418.92 | D37: =L37+T37+AB37+AJ37 -> 577959480 | E37: 4690.5 | F37: =E37*19000 -> 89119500 | G37: 591.37 | H37: =G37*19000 -> 11236030 | I37: 1994.42 | J37: =I37*19000 -> 37893980 | K37: =E37+G37+I37 -> 7276.29 | L37: =K37*19000 -> 138249510 | M37: 1448.53 | N37: =M37*19000 -> 27522070 | O37: 3178.08 | P37: =O37*19000 -> 60383520 | Q37: 1895.76 | R37: =Q37*19000 -> 36019440 | S37: =M37+O37+Q37 -> 6522.37 | T37: =S37*19000 -> 123925030 | U37: 3296.02 | V37: =U37*19000 -> 62624380 | W37: 953.64 | X37: =W37*19000 -> 18119160 | Y37: 3389.57 | Z37: =Y37*19000 -> 64401830 | AA37: =U37+W37+Y37 -> 7639.23 | AB37: =AA37*19000 -> 145145370 | AC37: 3408.89 | AD37: =AC37*19000 -> 64768910 | AE37: 3253.58 | AF37: =AE37*19000 -> 61818020 | AG37: 2318.56 | AH37: =AG37*19000 -> 44052640 | AI37: =AC37+AE37+AG37 -> 8981.03 | AJ37: =AI37*19000 -> 1.7063957e+08
A38: Bangkalan | B38: Utara Jawa | C38: =K38+S38+AA38+AI38 -> 25712.1 | D38: =L38+T38+AB38+AJ38 -> 488529900 | E38: 1033.4 | F38: =E38*19000 -> 19634600 | G38: 1173.7 | H38: =G38*19000 -> 22300300 | I38: 1015.2 | J38: =I38*19000 -> 19288800 | K38: =E38+G38+I38 -> 3222.3 | L38: =K38*19000 -> 61223700 | M38: 1665.1 | N38: =M38*19000 -> 31636900 | O38: 2844.7 | P38: =O38*19000 -> 54049300 | Q38: 3079.2 | R38: =Q38*19000 -> 58504800 | S38: =M38+O38+Q38 -> 7589 | T38: =S38*19000 -> 1.44191e+08 | U38: 3314.5 | V38: =U38*19000 -> 62975500 | W38: 3610.3 | X38: =W38*19000 -> 68595700 | Y38: 3006.2 | Z38: =Y38*19000 -> 57117800 | AA38: =U38+W38+Y38 -> 9931 | AB38: =AA38*19000 -> 188689000 | AC38: 2074.2 | AD38: =AC38*19000 -> 39409800 | AE38: 1581.4 | AF38: =AE38*19000 -> 30046600 | AG38: 1314.2 | AH38: =AG38*19000 -> 24969800 | AI38: =AC38+AE38+AG38 -> 4969.8 | AJ38: =AI38*19000 -> 94426200
A39: IPP Banyusangka | B39: Utara Jawa | C39: =K39+S39+AA39+AI39 -> 1935.29 | D39: =L39+T39+AB39+AJ39 -> 36770510 | E39: 155.74 | F39: =E39*19000 -> 2959060 | G39: 52.53 | H39: =G39*19000 -> 998070 | I39: 57.22 | J39: =I39*19000 -> 1087180 | K39: =E39+G39+I39 -> 265.49 | L39: =K39*19000 -> 5044310 | M39: 100.26 | N39: =M39*19000 -> 1904940 | O39: 92.65 | P39: =O39*19000 -> 1760350 | Q39: 91.69 | R39: =Q39*19000 -> 1742110 | S39: =M39+O39+Q39 -> 284.6 | T39: =S39*19000 -> 5407400 | U39: 254.12 | V39: =U39*19000 -> 4828280 | W39: 232.07 | X39: =W39*19000 -> 4409330 | Y39: 316.51 | Z39: =Y39*19000 -> 6013690 | AA39: =U39+W39+Y39 -> 802.7 | AB39: =AA39*19000 -> 15251300 | AC39: 250.11 | AD39: =AC39*19000 -> 4752090 | AE39: 180.46 | AF39: =AE39*19000 -> 3428740 | AG39: 151.93 | AH39: =AG39*19000 -> 2886670 | AI39: =AC39+AE39+AG39 -> 582.5 | AJ39: =AI39*19000 -> 11067500
A40: Sampang | B40: Utara Jawa | C40: =K40+S40+AA40+AI40 -> 16783.1 | D40: =L40+T40+AB40+AJ40 -> 318878900 | E40: 1061.8 | F40: =E40*19000 -> 20174200 | G40: 1150.9 | H40: =G40*19000 -> 21867100 | I40: 1191.9 | J40: =I40*19000 -> 22646100 | K40: =E40+G40+I40 -> 3404.6 | L40: =K40*19000 -> 64687400 | M40: 1472.8 | N40: =M40*19000 -> 27983200 | O40: 1625.2 | P40: =O40*19000 -> 30878800 | Q40: 1745.6 | R40: =Q40*19000 -> 33166400 | S40: =M40+O40+Q40 -> 4843.6 | T40: =S40*19000 -> 92028400 | U40: 1677.6 | V40: =U40*19000 -> 31874400 | W40: 1601.8 | X40: =W40*19000 -> 30434200 | Y40: 1492.5 | Z40: =Y40*19000 -> 28357500 | AA40: =U40+W40+Y40 -> 4771.9 | AB40: =AA40*19000 -> 90666100 | AC40: 1313.7 | AD40: =AC40*19000 -> 24960300 | AE40: 1253.8 | AF40: =AE40*19000 -> 23822200 | AG40: 1195.5 | AH40: =AG40*19000 -> 22714500 | AI40: =AC40+AE40+AG40 -> 3763 | AJ40: =AI40*19000 -> 71497000
...

Sheet PUD
A1: Kabupaten/Kota | B1: TOTAL | C1: NILAI PRODUKSI | D1: JANUARI | E1: NILAI PRODUKSI | F1: FEBRUARI | G1: NILAI PRODUKSI | H1: MARET | I1: NILAI PRODUKSI | J1: TW I | K1: NILAI PRODUKSI | L1: APRIL | M1: NILAI PRODUKSI | N1: MEI | O1: NILAI PRODUKSI | P1: JUNI | Q1: NILAI PRODUKSI | R1: TW II | S1: NILAI PRODUKSI | T1: JULI | U1: NILAI PRODUKSI | V1: AGUSTUS | W1: NILAI PRODUKSI | X1: SEPTEMBER | Y1: NILAI PRODUKSI | Z1: TW III | AA1: NILAI PRODUKSI | AB1: OKTOBER | AC1: NILAI PRODUKSI | AD1: NOVEMBER | AE1: NILAI PRODUKSI | AF1: DESEMBER | AG1: NILAI PRODUKSI | AH1: TW IV | AI1: NILAI PRODUKSI
A2: Pacitan | B2: =J2+R2+Z2+AH2 -> 821.438 | C2: =B2*19000 -> 15607322 | D2: 5.864 | E2: =D2*19000 -> 111416 | F2: 34.582 | G2: =F2*19000 -> 657058 | H2: 37.954 | I2: =H2*19000 -> 721126 | J2: =D2+F2+H2 -> 78.4 | K2: =J2*19000 -> 1489600 | L2: 36.174 | M2: =L2*19000 -> 687306 | N2: 46.882 | O2: =N2*19000 -> 890758 | P2: 105.906 | Q2: =P2*19000 -> 2012214 | R2: =L2+N2+P2 -> 188.962 | S2: =R2*19000 -> 3590278 | T2: 51.394 | U2: =T2*19000 -> 976486 | V2: =12.445+78.09+15.5 -> 106.035 | W2: =V2*19000 -> 2014665 | X2: =9.975+81.339+12.6 -> 103.914 | Y2: =X2*19000 -> 1974366 | Z2: =T2+V2+X2 -> 261.343 | AA2: =Z2*19000 -> 4965517 | AB2: =77.925+10.318+11.84 -> 100.083 | AC2: =AB2*19000 -> 1901577 | AD2: 90.46 | AE2: =AD2*19000 -> 1718740 | AF2: 102.19 | AG2: =AF2*19000 -> 1941610 | AH2: =AB2+AD2+AF2 -> 292.733 | AI2: =AH2*19000 -> 5561927
A3: Trenggalek | B3: =J3+R3+Z3+AH3 -> 11 | C3: =B3*19000 -> 209000 | D3: 2.1 | E3: =D3*19000 -> 39900 | F3: 1.8 | G3: =F3*19000 -> 34200 | H3: 1.7 | I3: =H3*19000 -> 32300 | J3: =D3+F3+H3 -> 5.6 | K3: =J3*19000 -> 106400 | L3: 2.1 | M3: =L3*19000 -> 39900 | N3: 1.8 | O3: =N3*19000 -> 34200 | P3: 1.5 | Q3: =P3*19000 -> 28500 | R3: =L3+N3+P3 -> 5.4 | S3: =R3*19000 -> 102600 | U3: =T3*19000 -> 0 | W3: =V3*19000 -> 0 | Y3: =X3*19000 -> 0 | Z3: =T3+V3+X3 -> 0 | AA3: =Z3*19000 -> 0 | AC3: =AB3*19000 -> 0 | AE3: =AD3*19000 -> 0 | AG3: =AF3*19000 -> 0 | AH3: =AB3+AD3+AF3 -> 0 | AI3: =AH3*19000 -> 0
A4: Tulungagung | B4: =J4+R4+Z4+AH4 -> 27.765 | C4: =B4*19000 -> 527535 | D4: 4.87 | E4: =D4*19000 -> 92530 | F4: 5.76 | G4: =F4*19000 -> 109440 | H4: 7.7 | I4: =H4*19000 -> 146300 | J4: =D4+F4+H4 -> 18.33 | K4: =J4*19000 -> 348270 | L4: 3.65 | M4: =L4*19000 -> 69350 | N4: 3.23 | O4: =N4*19000 -> 61370 | P4: 2 | Q4: =P4*19000 -> 38000 | R4: =L4+N4+P4 -> 8.88 | S4: =R4*19000 -> 168720 | T4: 0.082 | U4: =T4*19000 -> 1558 | V4: 0.147 | W4: =V4*19000 -> 2793 | X4: 0.08 | Y4: =X4*19000 -> 1520 | Z4: =T4+V4+X4 -> 0.309 | AA4: =Z4*19000 -> 5871 | AB4: 0.099 | AC4: =AB4*19000 -> 1881 | AD4: 0.082 | AE4: =AD4*19000 -> 1558 | AF4: 0.065 | AG4: =AF4*19000 -> 1235 | AH4: =AB4+AD4+AF4 -> 0.246 | AI4: =AH4*19000 -> 4674
A5: Blitar | B5: =J5+R5+Z5+AH5 -> 283.1 | C5: =B5*19000 -> 5378900 | D5: =11.1+16.8 -> 27.9 | E5: =D5*19000 -> 530100 | F5: =9.3+14.1 -> 23.4 | G5: =F5*19000 -> 444600 | H5: =10.8+8.7 -> 19.5 | I5: =H5*19000 -> 370500 | J5: =D5+F5+H5 -> 70.8 | K5: =J5*19000 -> 1345200 | L5: =17.9+10.3 -> 28.2 | M5: =L5*19000 -> 535800 | N5: =11.2+6.7 -> 17.9 | O5: =N5*19000 -> 340100 | P5: =5.6+10 -> 15.6 | Q5: =P5*19000 -> 296400 | R5: =L5+N5+P5 -> 61.7 | S5: =R5*19000 -> 1172300 | T5: =4.1+7 -> 11.1 | U5: =T5*19000 -> 210900 | V5: =3.7+10.5 -> 14.2 | W5: =V5*19000 -> 269800 | X5: 14.4 | Y5: =X5*19000 -> 273600 | Z5: =T5+V5+X5 -> 39.7 | AA5: =Z5*19000 -> 754300 | AB5: 24.4 | AC5: =AB5*19000 -> 463600 | AD5: =31.8+17.7 -> 49.5 | AE5: =AD5*19000 -> 940500 | AF5: =27+10 -> 37 | AG5: =AF5*19000 -> 703000 | AH5: =AB5+AD5+AF5 -> 110.9 | AI5: =AH5*19000 -> 2107100
A6: Malang | B6: =J6+R6+Z6+AH6 -> 111.77607 | C6: =B6*19000 -> 2123745.3 | D6: =4.743+0.9486+3.7944 -> 9.486 | E6: =D6*19000 -> 180234 | F6: =4.6035+0.9207+3.6828 -> 9.207 | G6: =F6*19000 -> 174933 | H6: =4.64953+0.9207+3.6828 -> 9.25303 | I6: =H6*19000 -> 175807.57 | J6: =D6+F6+H6 -> 27.94603 | K6: =J6*19000 -> 530974.57 | L6: =4.57707+0.91541+3.66166 -> 9.15414 | M6: =L6*19000 -> 173928.66 | N6: 9.25 | O6: =N6*19000 -> 175750 | P6: 9.126 | Q6: =P6*19000 -> 173394 | R6: =L6+N6+P6 -> 27.53014 | S6: =R6*19000 -> 523072.66 | T6: =4.756+0.9513+3.805 -> 9.5123 | U6: =T6*19000 -> 180733.7 | V6: =4.705+0.9411+3.764 -> 9.4101 | W6: =V6*19000 -> 178791.9 | X6: =4.711+0.9422+3.769 -> 9.4222 | Y6: =X6*19000 -> 179021.8 | Z6: =T6+V6+X6 -> 28.3446 | AA6: =Z6*19000 -> 538547.4 | AB6: =4.997+0.9994+3.9976 -> 9.994 | AC6: =AB6*19000 -> 189886 | AD6: =4.6965+0.9393+3.7572 -> 9.393 | AE6: =AD6*19000 -> 178467 | AF6: =4.2842+0.8568+3.4273 -> 8.5683 | AG6: =AF6*19000 -> 162797.7 | AH6: =AB6+AD6+AF6 -> 27.9553 | AI6: =AH6*19000 -> 531150.7
A7: Lumajang | B7: =J7+R7+Z7+AH7 -> 905.058 | C7: =B7*19000 -> 17196102 | D7: =31.4+18.7+17.8 -> 67.9 | E7: =D7*19000 -> 1290100 | F7: =36.1+31.3+17.4 -> 84.8 | G7: =F7*19000 -> 1611200 | H7: =34.1+29.3+17.6 -> 81 | I7: =H7*19000 -> 1539000 | J7: =D7+F7+H7 -> 233.7 | K7: =J7*19000 -> 4440300 | L7: =24.3+19.6+19.8 -> 63.7 | M7: =L7*19000 -> 1210300 | N7: =14.805+24.064+23.831 -> 62.7 | O7: =N7*19000 -> 1191300 | P7: =14.805+24.043+23.81 -> 62.658 | Q7: =P7*19000 -> 1190502 | R7: =L7+N7+P7 -> 189.058 | S7: =R7*19000 -> 3592102 | T7: =34+36.7+15.4 -> 86.1 | U7: =T7*19000 -> 1635900 | V7: =39.4+27.9+14.2 -> 81.5 | W7: =V7*19000 -> 1548500 | X7: =35.3+22.7+15.7 -> 73.7 | Y7: =X7*19000 -> 1400300 | Z7: =T7+V7+X7 -> 241.3 | AA7: =Z7*19000 -> 4584700 | AB7: =30.2+30.3+17 -> 77.5 | AC7: =AB7*19000 -> 1472500 | AD7: =27.8+35.2+14.4 -> 77.4 | AE7: =AD7*19000 -> 1470600 | AF7: =33.7+33.8+18.6 -> 86.1 | AG7: =AF7*19000 -> 1635900 | AH7: =AB7+AD7+AF7 -> 241 | AI7: =AH7*19000 -> 4579000
A8: Jember | B8: =J8+R8+Z8+AH8 -> 229.01 | C8: =B8*19000 -> 4351190 | D8: 8.5 | E8: =D8*19000 -> 161500 | F8: 9.3 | G8: =F8*19000 -> 176700 | H8: 14.5 | I8: =H8*19000 -> 275500 | J8: =D8+F8+H8 -> 32.3 | K8: =J8*19000 -> 613700 | L8: 15.1 | M8: =L8*19000 -> 286900 | N8: 18.9 | O8: =N8*19000 -> 359100 | P8: 22.3 | Q8: =P8*19000 -> 423700 | R8: =L8+N8+P8 -> 56.3 | S8: =R8*19000 -> 1069700 | T8: 20.9 | U8: =T8*19000 -> 397100 | V8: 28 | W8: =V8*19000 -> 532000 | X8: 27.5 | Y8: =X8*19000 -> 522500 | Z8: =T8+V8+X8 -> 76.4 | AA8: =Z8*19000 -> 1451600 | AB8: 24.4 | AC8: =AB8*19000 -> 463600 | AD8: 21.01 | AE8: =AD8*19000 -> 399190 | AF8: 18.6 | AG8: =AF8*19000 -> 353400 | AH8: =AB8+AD8+AF8 -> 64.01 | AI8: =AH8*19000 -> 1216190
A9: Banyuwangi | B9: =J9+R9+Z9+AH9 -> 1043.8 | C9: =B9*19000 -> 19832200 | D9: =42+34.8 -> 76.8 | E9: =D9*19000 -> 1459200 | F9: =44.1+36.2 -> 80.3 | G9: =F9*19000 -> 1525700 | H9: =43.6+39 -> 82.6 | I9: =H9*19000 -> 1569400 | J9: =D9+F9+H9 -> 239.7 | K9: =J9*19000 -> 4554300 | L9: =47+40.2 -> 87.2 | M9: =L9*19000 -> 1656800 | N9: =46.9+41.8 -> 88.7 | O9: =N9*19000 -> 1685300 | P9: =48.7+49.4 -> 98.1 | Q9: =P9*19000 -> 1863900 | R9: =L9+N9+P9 -> 274 | S9: =R9*19000 -> 5206000 | T9: =48.7+44.3 -> 93 | U9: =T9*19000 -> 1767000 | V9: =56.5+46 -> 102.5 | W9: =V9*19000 -> 1947500 | X9: =58.4+50.8 -> 109.2 | Y9: =X9*19000 -> 2074800 | Z9: =T9+V9+X9 -> 304.7 | AA9: =Z9*19000 -> 5789300 | AB9: =58.8+49.9 -> 108.7 | AC9: =AB9*19000 -> 2065300 | AD9: =67.1+49.6 -> 116.7 | AE9: =AD9*19000 -> 2217300 | AG9: =AF9*19000 -> 0 | AH9: =AB9+AD9+AF9 -> 225.4 | AI9: =AH9*19000 -> 4282600
A10: Tuban | B10: =J10+R10+Z10+AH10 -> 1688.6 | C10: =B10*19000 -> 32083400 | D10: =117.5+117.5 -> 235 | E10: =D10*19000 -> 4465000 | F10: =111.2+21.2 -> 132.4 | G10: =F10*19000 -> 2515600 | H10: =113.5+113.5 -> 227 | I10: =H10*19000 -> 4313000 | J10: =D10+F10+H10 -> 594.4 | K10: =J10*19000 -> 11293600 | L10: =116+20.5 -> 136.5 | M10: =L10*19000 -> 2593500 | N10: =119.8+21.2 -> 141 | O10: =N10*19000 -> 2679000 | P10: =14.3+110.7 -> 125 | Q10: =P10*19000 -> 2375000 | R10: =L10+N10+P10 -> 402.5 | S10: =R10*19000 -> 7647500 | T10: =101.8+11.7 -> 113.5 | U10: =T10*19000 -> 2156500 | V10: =102.5+12.4 -> 114.9 | W10: =V10*19000 -> 2183100 | X10: =106.4+12.4 -> 118.8 | Y10: =X10*19000 -> 2257200 | Z10: =T10+V10+X10 -> 347.2 | AA10: =Z10*19000 -> 6596800 | AB10: =102.6+12.8 -> 115.4 | AC10: =AB10*19000 -> 2192600 | AD10: =104.1+12.3 -> 116.4 | AE10: =AD10*19000 -> 2211600 | AF10: =102.5+10.2 -> 112.7 | AG10: =AF10*19000 -> 2141300 | AH10: =AB10+AD10+AF10 -> 344.5 | AI10: =AH10*19000 -> 6545500
A11: Lamongan | B11: =J11+R11+Z11+AH11 -> 2848.19 | C11: =B11*19000 -> 54115610 | D11: 187.38 | E11: =D11*19000 -> 3560220 | F11: 301.5 | G11: =F11*19000 -> 5728500 | H11: 412.52 | I11: =H11*19000 -> 7837880 | J11: =D11+F11+H11 -> 901.4 | K11: =J11*19000 -> 17126600 | L11: 480.41 | M11: =L11*19000 -> 9127790 | N11: 490.6 | O11: =N11*19000 -> 9321400 | P11: 277.88 | Q11: =P11*19000 -> 5279720 | R11: =L11+N11+P11 -> 1248.89 | S11: =R11*19000 -> 23728910 | T11: 180.1 | U11: =T11*19000 -> 3421900 | V11: 154.4 | W11: =V11*19000 -> 2933600 | X11: 136.6 | Y11: =X11*19000 -> 2595400 | Z11: =T11+V11+X11 -> 471.1 | AA11: =Z11*19000 -> 8950900 | AB11: 112.2 | AC11: =AB11*19000 -> 2131800 | AD11: 71.8 | AE11: =AD11*19000 -> 1364200 | AF11: 42.8 | AG11: =AF11*19000 -> 813200 | AH11: =AB11+AD11+AF11 -> 226.8 | AI11: =AH11*19000 -> 4309200
A12: Gresik | B12: =J12+R12+Z12+AH12 -> 937.7 | C12: =B12*19000 -> 17816300 | D12: 71 | E12: =D12*19000 -> 1349000 | F12: 82.8 | G12: =F12*19000 -> 1573200 | H12: 82.8 | I12: =H12*19000 -> 1573200 | J12: =D12+F12+H12 -> 236.6 | K12: =J12*19000 -> 4495400 | L12: 85.7 | M12: =L12*19000 -> 1628300 | N12: 84.8 | O12: =N12*19000 -> 1611200 | P12: 80.3 | Q12: =P12*19000 -> 1525700 | R12: =L12+N12+P12 -> 250.8 | S12: =R12*19000 -> 4765200 | T12: 45.3 | U12: =T12*19000 -> 860700 | V12: 61.1 | W12: =V12*19000 -> 1160900 | X12: 96.1 | Y12: =X12*19000 -> 1825900 | Z12: =T12+V12+X12 -> 202.5 | AA12: =Z12*19000 -> 3847500 | AB12: 81 | AC12: =AB12*19000 -> 1539000 | AD12: 79 | AE12: =AD12*19000 -> 1501000 | AF12: 87.8 | AG12: =AF12*19000 -> 1668200 | AH12: =AB12+AD12+AF12 -> 247.8 | AI12: =AH12*19000 -> 4708200
A13: Kota Surabaya | B13: =J13+R13+Z13+AH13 -> 144.35 | C13: =B13*19000 -> 2742650 | D13: 9.2 | E13: =D13*19000 -> 174800 | F13: 8.4 | G13: =F13*19000 -> 159600 | H13: 9.9 | I13: =H13*19000 -> 188100 | J13: =D13+F13+H13 -> 27.5 | K13: =J13*19000 -> 522500 | L13: 13.6 | M13: =L13*19000 -> 258400 | N13: 15.5 | O13: =N13*19000 -> 294500 | P13: 12.1 | Q13: =P13*19000 -> 229900 | R13: =L13+N13+P13 -> 41.2 | S13: =R13*19000 -> 782800 | T13: 13.6 | U13: =T13*19000 -> 258400 | V13: 15.65 | W13: =V13*19000 -> 297350 | X13: 9.9 | Y13: =X13*19000 -> 188100 | Z13: =T13+V13+X13 -> 39.15 | AA13: =Z13*19000 -> 743850 | AB13: 12.5 | AC13: =AB13*19000 -> 237500 | AD13: 13.3 | AE13: =AD13*19000 -> 252700 | AF13: 10.7 | AG13: =AF13*19000 -> 203300 | AH13: =AB13+AD13+AF13 -> 36.5 | AI13: =AH13*19000 -> 693500
A14: Sidoarjo | B14: =J14+R14+Z14+AH14 -> 564.1 | C14: =B14*19000 -> 10717900 | D14: 48.9 | E14: =D14*19000 -> 929100 | F14: 49 | G14: =F14*19000 -> 931000 | H14: 48.8 | I14: =H14*19000 -> 927200 | J14: =D14+F14+H14 -> 146.7 | K14: =J14*19000 -> 2787300 | L14: 45.4 | M14: =L14*19000 -> 862600 | N14: 45.1 | O14: =N14*19000 -> 856900 | P14: 44.9 | Q14: =P14*19000 -> 853100 | R14: =L14+N14+P14 -> 135.4 | S14: =R14*19000 -> 2572600 | T14: 45 | U14: =T14*19000 -> 855000 | V14: 45.2 | W14: =V14*19000 -> 858800 | X14: 45.2 | Y14: =X14*19000 -> 858800 | Z14: =T14+V14+X14 -> 135.4 | AA14: =Z14*19000 -> 2572600 | AB14: 48.8 | AC14: =AB14*19000 -> 927200 | AD14: 48.8 | AE14: =AD14*19000 -> 927200 | AF14: 49 | AG14: =AF14*19000 -> 931000 | AH14: =AB14+AD14+AF14 -> 146.6 | AI14: =AH14*19000 -> 2785400
A15: Pasuruan | B15: =J15+R15+Z15+AH15 -> 283.7 | C15: =B15*19000 -> 5390300 | D15: =4.1+14.3 -> 18.4 | E15: =D15*19000 -> 349600 | F15: =3.7+18.1 -> 21.8 | G15: =F15*19000 -> 414200 | H15: =3.2+24.1 -> 27.3 | I15: =H15*19000 -> 518700 | J15: =D15+F15+H15 -> 67.5 | K15: =J15*19000 -> 1282500 | L15: =6.7+18.7 -> 25.4 | M15: =L15*19000 -> 482600 | N15: =5.4+22.3 -> 27.7 | O15: =N15*19000 -> 526300 | P15: =7.3+17.2 -> 24.5 | Q15: =P15*19000 -> 465500 | R15: =L15+N15+P15 -> 77.6 | S15: =R15*19000 -> 1474400 | T15: =4.9+20.3 -> 25.2 | U15: =T15*19000 -> 478800 | V15: =5.7+17.2 -> 22.9 | W15: =V15*19000 -> 435100 | X15: =22.7+5.2 -> 27.9 | Y15: =X15*19000 -> 530100 | Z15: =T15+V15+X15 -> 76 | AA15: =Z15*19000 -> 1444000 | AB15: 22.6 | AC15: =AB15*19000 -> 429400 | AD15: 20.1 | AE15: =AD15*19000 -> 381900 | AF15: 19.9 | AG15: =AF15*19000 -> 378100 | AH15: =AB15+AD15+AF15 -> 62.6 | AI15: =AH15*19000 -> 1189400
A16: Probolinggo | B16: =J16+R16+Z16+AH16 -> 175.5 | C16: =B16*19000 -> 3334500 | D16: =11.7+1.2+4.2 -> 17.1 | E16: =D16*19000 -> 324900 | F16: =12+1.2+4.5 -> 17.7 | G16: =F16*19000 -> 336300 | H16: =12.5+1.3+5.2 -> 19 | I16: =H16*19000 -> 361000 | J16: =D16+F16+H16 -> 53.8 | K16: =J16*19000 -> 1022200 | L16: =12+1.3+4.3 -> 17.6 | M16: =L16*19000 -> 334400 | N16: =12.2+1.3+5.3 -> 18.8 | O16: =N16*19000 -> 357200 | P16: =11.6+0.6+4.2 -> 16.4 | Q16: =P16*19000 -> 311600 | R16: =L16+N16+P16 -> 52.8 | S16: =R16*19000 -> 1003200 | T16: =11.4+0.6+2.6 -> 14.6 | U16: =T16*19000 -> 277400 | V16: =7.1+0.5+2.5 -> 10.1 | W16: =V16*19000 -> 191900 | X16: =6.4+0.5+2.2 -> 9.1 | Y16: =X16*19000 -> 172900 | Z16: =T16+V16+X16 -> 33.8 | AA16: =Z16*19000 -> 642200 | AB16: =9.4+1.8+4 -> 15.2 | AC16: =AB16*19000 -> 288800 | AD16: 19.9 | AE16: =AD16*19000 -> 378100 | AG16: =AF16*19000 -> 0 | AH16: =AB16+AD16+AF16 -> 35.1 | AI16: =AH16*19000 -> 666900
A17: Kota Probolinggo | B17: =J17+R17+Z17+AH17 -> 14.937 | C17: =B17*19000 -> 283803 | D17: =0.06+0.386+0.865 -> 1.311 | E17: =D17*19000 -> 24909 | F17: =0.064+0.402+0.937 -> 1.403 | G17: =F17*19000 -> 26657 | H17: =0.073+0.426+0.974 -> 1.473 | I17: =H17*19000 -> 27987 | J17: =D17+F17+H17 -> 4.187 | K17: =J17*19000 -> 79553 | L17: =0.077+0.448+1.022 -> 1.547 | M17: =L17*19000 -> 29393 | N17: =0.08+0.453+1.032 -> 1.565 | O17: =N17*19000 -> 29735 | P17: =0.082+0.459+1.044 -> 1.585 | Q17: =P17*19000 -> 30115 | R17: =L17+N17+P17 -> 4.697 | S17: =R17*19000 -> 89243 | T17: =0.065+0.25+0.635 -> 0.95 | U17: =T17*19000 -> 18050 | V17: =0.05+0.181+0.487 -> 0.718 | W17: =V17*19000 -> 13642 | X17: =0.06+0.232+0.598 -> 0.89 | Y17: =X17*19000 -> 16910 | Z17: =T17+V17+X17 -> 2.558 | AA17: =Z17*19000 -> 48602 | AB17: 1.03 | AC17: =AB17*19000 -> 19570 | AD17: 1.13 | AE17: =AD17*19000 -> 21470 | AF17: =0.935+0.085+0.315 -> 1.335 | AG17: =AF17*19000 -> 25365 | AH17: =AB17+AD17+AF17 -> 3.495 | AI17: =AH17*19000 -> 66405
A18: Bangkalan | B18: =J18+R18+Z18+AH18 -> 63.8 | C18: =B18*19000 -> 1212200 | D18: 6 | E18: =D18*19000 -> 114000 | F18: 4.9 | G18: =F18*19000 -> 93100 | H18: 6.2 | I18: =H18*19000 -> 117800 | J18: =D18+F18+H18 -> 17.1 | K18: =J18*19000 -> 324900 | L18: 7.9 | M18: =L18*19000 -> 150100 | N18: 8.5 | O18: =N18*19000 -> 161500 | P18: 7.7 | Q18: =P18*19000 -> 146300 | R18: =L18+N18+P18 -> 24.1 | S18: =R18*19000 -> 457900 | T18: 7 | U18: =T18*19000 -> 133000 | V18: 3.6 | W18: =V18*19000 -> 68400 | X18: 3.7 | Y18: =X18*19000 -> 70300 | Z18: =T18+V18+X18 -> 14.3 | AA18: =Z18*19000 -> 271700 | AB18: 3.1 | AC18: =AB18*19000 -> 58900 | AD18: 2.5 | AE18: =AD18*19000 -> 47500 | AF18: 2.7 | AG18: =AF18*19000 -> 51300 | AH18: =AB18+AD18+AF18 -> 8.3 | AI18: =AH18*19000 -> 157700
A19: Sampang | B19: =J19+R19+Z19+AH19 -> 22.2 | C19: =B19*19000 -> 421800 | D19: 1.2 | E19: =D19*19000 -> 22800 | F19: 1.3 | G19: =F19*19000 -> 24700 | H19: 1.5 | I19: =H19*19000 -> 28500 | J19: =D19+F19+H19 -> 4 | K19: =J19*19000 -> 76000 | L19: 1.6 | M19: =L19*19000 -> 30400 | N19: 1.8 | O19: =N19*19000 -> 34200 | P19: 1.8 | Q19: =P19*19000 -> 34200 | R19: =L19+N19+P19 -> 5.2 | S19: =R19*19000 -> 98800 | T19: 1.6 | U19: =T19*19000 -> 30400 | V19: 1.5 | W19: =V19*19000 -> 28500 | X19: 2.8 | Y19: =X19*19000 -> 53200 | Z19: =T19+V19+X19 -> 5.9 | AA19: =Z19*19000 -> 112100 | AB19: 2.5 | AC19: =AB19*19000 -> 47500 | AD19: 2.4 | AE19: =AD19*19000 -> 45600 | AF19: 2.2 | AG19: =AF19*19000 -> 41800 | AH19: =AB19+AD19+AF19 -> 7.1 | AI19: =AH19*19000 -> 134900
A20: Sumenep | B20: =J20+R20+Z20+AH20 -> 64.889 | C20: =B20*19000 -> 1232891 | D20: 9.2 | E20: =D20*19000 -> 174800 | F20: 8.6 | G20: =F20*19000 -> 163400 | H20: 4.5 | I20: =H20*19000 -> 85500 | J20: =D20+F20+H20 -> 22.3 | K20: =J20*19000 -> 423700 | L20: 4.4 | M20: =L20*19000 -> 83600 | N20: 6.1 | O20: =N20*19000 -> 115900 | P20: =1.52+5.76 -> 7.28 | Q20: =P20*19000 -> 138320 | R20: =L20+N20+P20 -> 17.78 | S20: =R20*19000 -> 337820 | T20: =1.1+5.6 -> 6.7 | U20: =T20*19000 -> 127300 | V20: =1.2+5.4 -> 6.6 | W20: =V20*19000 -> 125400 | X20: =0.8+5.5 -> 6.3 | Y20: =X20*19000 -> 119700 | Z20: =T20+V20+X20 -> 19.6 | AA20: =Z20*19000 -> 372400 | AB20: =3.909+1.3 -> 5.209 | AC20: =AB20*19000 -> 98971 | AE20: =AD20*19000 -> 0 | AG20: =AF20*19000 -> 0 | AH20: =AB20+AD20+AF20 -> 5.209 | AI20: =AH20*19000 -> 98971
A21: Mojokerto | B21: =J21+R21+Z21+AH21 -> 162.39 | C21: =B21*19000 -> 3085410 | D21: 13.33 | E21: =D21*19000 -> 253270 | F21: 13.95 | G21: =F21*19000 -> 265050 | H21: 19.2 | I21: =H21*19000 -> 364800 | J21: =D21+F21+H21 -> 46.48 | K21: =J21*19000 -> 883120 | L21: 13.7 | M21: =L21*19000 -> 260300 | N21: 22.2 | O21: =N21*19000 -> 421800 | P21: 22.4 | Q21: =P21*19000 -> 425600 | R21: =L21+N21+P21 -> 58.3 | S21: =R21*19000 -> 1107700 | T21: 14.84 | U21: =T21*19000 -> 281960 | V21: 11.46 | W21: =V21*19000 -> 217740 | X21: 15.73 | Y21: =X21*19000 -> 298870 | Z21: =T21+V21+X21 -> 42.03 | AA21: =Z21*19000 -> 798570 | AB21: 15.58 | AC21: =AB21*19000 -> 296020 | AE21: =AD21*19000 -> 0 | AG21: =AF21*19000 -> 0 | AH21: =AB21+AD21+AF21 -> 15.58 | AI21: =AH21*19000 -> 296020
A22: Jombang | B22: =J22+R22+Z22+AH22 -> 151.4 | C22: =B22*19000 -> 2876600 | D22: 20.5 | E22: =D22*19000 -> 389500 | F22: 12.4 | G22: =F22*19000 -> 235600 | H22: 9.8 | I22: =H22*19000 -> 186200 | J22: =D22+F22+H22 -> 42.7 | K22: =J22*19000 -> 811300 | L22: 15.4 | M22: =L22*19000 -> 292600 | N22: 12.6 | O22: =N22*19000 -> 239400 | P22: 9.7 | Q22: =P22*19000 -> 184300 | R22: =L22+N22+P22 -> 37.7 | S22: =R22*19000 -> 716300 | T22: 9.9 | U22: =T22*19000 -> 188100 | V22: 14.1 | W22: =V22*19000 -> 267900 | X22: 12.9 | Y22: =X22*19000 -> 245100 | Z22: =T22+V22+X22 -> 36.9 | AA22: =Z22*19000 -> 701100 | AB22: 11.8 | AC22: =AB22*19000 -> 224200 | AD22: 10.6 | AE22: =AD22*19000 -> 201400 | AF22: 11.7 | AG22: =AF22*19000 -> 222300 | AH22: =AB22+AD22+AF22 -> 34.1 | AI22: =AH22*19000 -> 647900
A23: Nganjuk | B23: =J23+R23+Z23+AH23 -> 679.95 | C23: =B23*19000 -> 12919050 | D23: 70 | E23: =D23*19000 -> 1330000 | F23: 68.75 | G23: =F23*19000 -> 1306250 | H23: 68 | I23: =H23*19000 -> 1292000 | J23: =D23+F23+H23 -> 206.75 | K23: =J23*19000 -> 3928250 | L23: 60 | M23: =L23*19000 -> 1140000 | N23: 57 | O23: =N23*19000 -> 1083000 | P23: 54 | Q23: =P23*19000 -> 1026000 | R23: =L23+N23+P23 -> 171 | S23: =R23*19000 -> 3249000 | T23: 49.2 | U23: =T23*19000 -> 934800 | V23: 45 | W23: =V23*19000 -> 855000 | X23: 42 | Y23: =X23*19000 -> 798000 | Z23: =T23+V23+X23 -> 136.2 | AA23: =Z23*19000 -> 2587800 | AB23: 45 | AC23: =AB23*19000 -> 855000 | AD23: 56 | AE23: =AD23*19000 -> 1064000 | AF23: 65 | AG23: =AF23*19000 -> 1235000 | AH23: =AB23+AD23+AF23 -> 166 | AI23: =AH23*19000 -> 3154000
A24: Madiun | B24: =J24+R24+Z24+AH24 -> 510.1 | C24: =B24*19000 -> 9691900 | D24: 41.2 | E24: =D24*19000 -> 782800 | F24: 41.1 | G24: =F24*19000 -> 780900 | H24: 42.4 | I24: =H24*19000 -> 805600 | J24: =D24+F24+H24 -> 124.7 | K24: =J24*19000 -> 2369300 | L24: 42.7 | M24: =L24*19000 -> 811300 | N24: 43.8 | O24: =N24*19000 -> 832200 | P24: 44.4 | Q24: =P24*19000 -> 843600 | R24: =L24+N24+P24 -> 130.9 | S24: =R24*19000 -> 2487100 | T24: 43.9 | U24: =T24*19000 -> 834100 | V24: 43.5 | W24: =V24*19000 -> 826500 | X24: 42.5 | Y24: =X24*19000 -> 807500 | Z24: =T24+V24+X24 -> 129.9 | AA24: =Z24*19000 -> 2468100 | AB24: 42 | AC24: =AB24*19000 -> 798000 | AD24: 41.5 | AE24: =AD24*19000 -> 788500 | AF24: 41.1 | AG24: =AF24*19000 -> 780900 | AH24: =AB24+AD24+AF24 -> 124.6 | AI24: =AH24*19000 -> 2367400
A25: Magetan | B25: =J25+R25+Z25+AH25 -> 47 | C25: =B25*19000 -> 893000 | D25: 4.1 | E25: =D25*19000 -> 77900 | F25: 4.1 | G25: =F25*19000 -> 77900 | H25: 4.1 | I25: =H25*19000 -> 77900 | J25: =D25+F25+H25 -> 12.3 | K25: =J25*19000 -> 233700 | L25: 4 | M25: =L25*19000 -> 76000 | N25: 3.9 | O25: =N25*19000 -> 74100 | P25: 3.8 | Q25: =P25*19000 -> 72200 | R25: =L25+N25+P25 -> 11.7 | S25: =R25*19000 -> 222300 | T25: 3.4 | U25: =T25*19000 -> 64600 | V25: 3.4 | W25: =V25*19000 -> 64600 | X25: 3.2 | Y25: =X25*19000 -> 60800 | Z25: =T25+V25+X25 -> 10 | AA25: =Z25*19000 -> 190000 | AB25: 4 | AC25: =AB25*19000 -> 76000 | AD25: 4.1 | AE25: =AD25*19000 -> 77900 | AF25: 4.9 | AG25: =AF25*19000 -> 93100 | AH25: =AB25+AD25+AF25 -> 13 | AI25: =AH25*19000 -> 247000
A26: Ngawi | B26: =J26+R26+Z26+AH26 -> 888.4 | C26: =B26*19000 -> 16879600 | D26: 73.9 | E26: =D26*19000 -> 1404100 | F26: 76.2 | G26: =F26*19000 -> 1447800 | H26: 78.6 | I26: =H26*19000 -> 1493400 | J26: =D26+F26+H26 -> 228.7 | K26: =J26*19000 -> 4345300 | L26: 81 | M26: =L26*19000 -> 1539000 | N26: 81.5 | O26: =N26*19000 -> 1548500 | P26: 83.1 | Q26: =P26*19000 -> 1578900 | R26: =L26+N26+P26 -> 245.6 | S26: =R26*19000 -> 4666400 | T26: 80.7 | U26: =T26*19000 -> 1533300 | V26: 77 | W26: =V26*19000 -> 1463000 | X26: 70 | Y26: =X26*19000 -> 1330000 | Z26: =T26+V26+X26 -> 227.7 | AA26: =Z26*19000 -> 4326300 | AB26: 68.2 | AC26: =AB26*19000 -> 1295800 | AD26: 60.5 | AE26: =AD26*19000 -> 1149500 | AF26: 57.7 | AG26: =AF26*19000 -> 1096300 | AH26: =AB26+AD26+AF26 -> 186.4 | AI26: =AH26*19000 -> 3541600
A27: Bojonegoro | B27: =J27+R27+Z27+AH27 -> 1293.7 | C27: =B27*19000 -> 24580300 | D27: 103.3 | E27: =D27*19000 -> 1962700 | F27: 103 | G27: =F27*19000 -> 1957000 | H27: 103.1 | I27: =H27*19000 -> 1958900 | J27: =D27+F27+H27 -> 309.4 | K27: =J27*19000 -> 5878600 | L27: 105.6 | M27: =L27*19000 -> 2006400 | N27: 103.2 | O27: =N27*19000 -> 1960800 | P27: 103.1 | Q27: =P27*19000 -> 1958900 | R27: =L27+N27+P27 -> 311.9 | S27: =R27*19000 -> 5926100 | T27: 103.2 | U27: =T27*19000 -> 1960800 | V27: 102.8 | W27: =V27*19000 -> 1953200 | X27: 103.6 | Y27: =X27*19000 -> 1968400 | Z27: =T27+V27+X27 -> 309.6 | AA27: =Z27*19000 -> 5882400 | AB27: 123.8 | AC27: =AB27*19000 -> 2352200 | AD27: 119.4 | AE27: =AD27*19000 -> 2268600 | AF27: 119.6 | AG27: =AF27*19000 -> 2272400 | AH27: =AB27+AD27+AF27 -> 362.8 | AI27: =AH27*19000 -> 6893200
A28: Kota Kediri | B28: =J28+R28+Z28+AH28 -> 30.4 | C28: =B28*19000 -> 577600 | D28: 2.7 | E28: =D28*19000 -> 51300 | F28: 2.8 | G28: =F28*19000 -> 53200 | H28: 2.8 | I28: =H28*19000 -> 53200 | J28: =D28+F28+H28 -> 8.3 | K28: =J28*19000 -> 157700 | L28: 3.3 | M28: =L28*19000 -> 62700 | N28: 3.1 | O28: =N28*19000 -> 58900 | P28: 2.6 | Q28: =P28*19000 -> 49400 | R28: =L28+N28+P28 -> 9 | S28: =R28*19000 -> 171000 | T28: 2.7 | U28: =T28*19000 -> 51300 | V28: 2.6 | W28: =V28*19000 -> 49400 | X28: 2.6 | Y28: =X28*19000 -> 49400 | Z28: =T28+V28+X28 -> 7.9 | AA28: =Z28*19000 -> 150100 | AB28: 2.5 | AC28: =AB28*19000 -> 47500 | AD28: 2.7 | AE28: =AD28*19000 -> 51300 | AG28: =AF28*19000 -> 0 | AH28: =AB28+AD28+AF28 -> 5.2 | AI28: =AH28*19000 -> 98800
A29: Kota Mojokerto | B29: =J29+R29+Z29+AH29 -> 6.485 | C29: =B29*19000 -> 123215 | D29: 0.57 | E29: =D29*19000 -> 10830 | F29: 0.55 | G29: =F29*19000 -> 10450 | H29: 0.53 | I29: =H29*19000 -> 10070 | J29: =D29+F29+H29 -> 1.65 | K29: =J29*19000 -> 31350 | L29: 0.54 | M29: =L29*19000 -> 10260 | N29: 0.5 | O29: =N29*19000 -> 9500 | P29: 0.51 | Q29: =P29*19000 -> 9690 | R29: =L29+N29+P29 -> 1.55 | S29: =R29*19000 -> 29450 | T29: 0.52 | U29: =T29*19000 -> 9880 | V29: 0.54 | W29: =V29*19000 -> 10260 | X29: 0.5 | Y29: =X29*19000 -> 9500 | Z29: =T29+V29+X29 -> 1.56 | AA29: =Z29*19000 -> 29640 | AB29: 0.545 | AC29: =AB29*19000 -> 10355 | AD29: 0.56 | AE29: =AD29*19000 -> 10640 | AF29: 0.62 | AG29: =AF29*19000 -> 11780 | AH29: =AB29+AD29+AF29 -> 1.725 | AI29: =AH29*19000 -> 32775
A30: Kota Madiun | B30: =J30+R30+Z30+AH30 -> 96.8 | C30: =B30*19000 -> 1839200 | D30: 8.4 | E30: =D30*19000 -> 159600 | F30: 8.3 | G30: =F30*19000 -> 157700 | H30: 8.5 | I30: =H30*19000 -> 161500 | J30: =D30+F30+H30 -> 25.2 | K30: =J30*19000 -> 478800 | L30: 8.8 | M30: =L30*19000 -> 167200 | N30: 9.2 | O30: =N30*19000 -> 174800 | P30: 9 | Q30: =P30*19000 -> 171000 | R30: =L30+N30+P30 -> 27 | S30: =R30*19000 -> 513000 | T30: 8.9 | U30: =T30*19000 -> 169100 | V30: 8.7 | W30: =V30*19000 -> 165300 | X30: 8.2 | Y30: =X30*19000 -> 155800 | Z30: =T30+V30+X30 -> 25.8 | AA30: =Z30*19000 -> 490200 | AB30: 6.7 | AC30: =AB30*19000 -> 127300 | AD30: 6.1 | AE30: =AD30*19000 -> 115900 | AF30: 6 | AG30: =AF30*19000 -> 114000 | AH30: =AB30+AD30+AF30 -> 18.8 | AI30: =AH30*19000 -> 357200
A31: Ponogoro | B31: =J31+R31+Z31+AH31 -> 52.5 | C31: =B31*19000 -> 997500 | D31: 4.6 | E31: =D31*19000 -> 87400 | F31: 1.5 | G31: =F31*19000 -> 28500 | H31: 3.7 | I31: =H31*19000 -> 70300 | J31: =D31+F31+H31 -> 9.8 | K31: =J31*19000 -> 186200 | L31: 3.3 | M31: =L31*19000 -> 62700 | N31: 4.3 | O31: =N31*19000 -> 81700 | P31: 4.1 | Q31: =P31*19000 -> 77900 | R31: =L31+N31+P31 -> 11.7 | S31: =R31*19000 -> 222300 | T31: 1.5 | U31: =T31*19000 -> 28500 | V31: 3.8 | W31: =V31*19000 -> 72200 | X31: 6.5 | Y31: =X31*19000 -> 123500 | Z31: =T31+V31+X31 -> 11.8 | AA31: =Z31*19000 -> 224200 | AB31: 6.4 | AC31: =AB31*19000 -> 121600 | AD31: 6.4 | AE31: =AD31*19000 -> 121600 | AF31: 6.4 | AG31: =AF31*19000 -> 121600 | AH31: =AB31+AD31+AF31 -> 19.2 | AI31: =AH31*19000 -> 364800
