Workbook

Sheet BUDIDAYA
A1: PRODUKSI BUDIDAYA JAWA TIMUR MENURUT JENIS USAHA
B3: JENIS USAHA | C3: SATUAN | D3: JUMLAH | E3: TRIWULAN 2025
E4: Januari | F4: Februari | G4: Maret | H4: TW I | I4: April | J4: Mei | K4: Juni | L4: TW II | M4: Juli | N4: Agustus | O4: September | P4: TW III | Q4: Oktober | R4: November | S4: Desember | T4: TW IV
C5: TON | D5: =SUM(D6:D11) -> 1442333 | E5: =SUM(E6:E11) -> 100101.99 | F5: =SUM(F6:F11) -> 109536.39 | G5: =SUM(G6:G11) -> 120474.07 | H5: =SUM(E5:G5) -> 330112.46 | I5: =SUM(I6:I11) -> 117859.12 | J5: =SUM(J6:J11) -> 120777.12 | K5: =SUM(K6:K11) -> 112310.71 | L5: =SUM(I5:K5) -> 350946.95 | M5: =SUM(M6:M11) -> 125106.38 | N5: =SUM(N6:N11) -> 125340.13 | O5: =SUM(O6:O11) -> 134190.05 | P5: =SUM(M5:O5) -> 384636.55 | Q5: =SUM(Q6:Q11) -> 119766.41 | R5: =SUM(R6:R11) -> 122691.29 | S5: =SUM(S6:S11) -> 134179.34 | T5: =SUM(Q5:S5) -> 376637.04
B6: Laut | C6: Ton | D6: =SUM(H6,L6,P6,T6) -> 774415.16 | E6: =E61 -> 47094.474 | F6: =F61 -> 51144.2 | G6: =G61 -> 58230.457 | H6: =SUM(E6:G6) -> 156469.13 | I6: =I61 -> 55914.419 | J6: =J61 -> 57079.483 | K6: =K61 -> 56556.37 | L6: =SUM(I6:K6) -> 169550.27 | M6: =M61 -> 74919.428 | N6: =N61 -> 72360.697 | O6: =O61 -> 80512.764 | P6: =SUM(M6:O6) -> 227792.89 | Q6: =Q61 -> 69955.922 | R6: =R61 -> 72316.751 | S6: =S61 -> 78330.195 | T6: =SUM(Q6:S6) -> 220602.87
B7: Tambak | C7: Ton | D7: =SUM(H7,L7,P7,T7) -> 282359.63 | E7: =E105 -> 22313.374 | F7: =F105 -> 23749.563 | G7: =G105 -> 25210.445 | H7: =SUM(E7:G7) -> 71273.383 | I7: =I105 -> 23327.005 | J7: =J105 -> 21858.863 | K7: =K105 -> 22177.34 | L7: =SUM(I7:K7) -> 67363.208 | M7: =M105 -> 22574.998 | N7: =N105 -> 25552.928 | O7: =O105 -> 26363.971 | P7: =SUM(M7:O7) -> 74491.898 | Q7: =Q105 -> 22767.893 | R7: =R105 -> 21933.068 | S7: =S105 -> 24530.182 | T7: =SUM(Q7:S7) -> 69231.143
B8: Kolam | C8: Ton | D8: =SUM(H8,L8,P8,T8) -> 356663.33 | E8: =E148 -> 27488.954 | F8: =F148 -> 31413.318 | G8: =G148 -> 34255.335 | H8: =SUM(E8:G8) -> 93157.607 | I8: =I148 -> 35644.685 | J8: =J148 -> 38914.071 | K8: =K148 -> 31587.546 | L8: =SUM(I8:K8) -> 106146.3 | M8: =M148 -> 26576.82 | N8: =N148 -> 26086.586 | O8: =O148 -> 25774.87 | P8: =SUM(M8:O8) -> 78438.276 | Q8: =Q148 -> 25398.837 | R8: =R148 -> 26013.916 | S8: =S148 -> 27508.395 | T8: =SUM(Q8:S8) -> 78921.149
B9: Mina Padi | C9: Ton | D9: =SUM(H9,L9,P9,T9) -> 16316.298 | E9: =E191 -> 1750.2 | F9: =F191 -> 1899.32 | G9: =G191 -> 1594.743 | H9: =SUM(E9:G9) -> 5244.263 | I9: =I191 -> 1851.281 | J9: =J191 -> 1912.668 | K9: =K191 -> 1128.26 | L9: =SUM(I9:K9) -> 4892.209 | M9: =M191 -> 541.163 | N9: =N191 -> 717.716 | O9: =O191 -> 882.192 | P9: =SUM(M9:O9) -> 2141.071 | Q9: =Q191 -> 907.891 | R9: =R191 -> 1138.687 | S9: =S191 -> 1992.177 | T9: =SUM(Q9:S9) -> 4038.755
B10: Karamba | C10: Ton | D10: =SUM(H10,L10,P10,T10) -> 6969.165 | E10: =E234 -> 731.767 | F10: =F234 -> 663.737 | G10: =G234 -> 556.787 | H10: =SUM(E10:G10) -> 1952.291 | I10: =I234 -> 534.179 | J10: =J234 -> 515.965 | K10: =K234 -> 407.815 | L10: =SUM(I10:K10) -> 1457.959 | M10: =M234 -> 296.267 | N10: =N234 -> 422.733 | O10: =O234 -> 430.553 | P10: =SUM(M10:O10) -> 1149.553 | Q10: =Q234 -> 479.421 | R10: =R234 -> 882.978 | S10: =S234 -> 1046.963 | T10: =SUM(Q10:S10) -> 2409.362
B11: Japung/ KJA Tawar | C11: Ton | D11: =SUM(H11,L11,P11,T11) -> 5609.4059 | E11: =E277 -> 723.22499 | F11: =F277 -> 666.25253 | G11: =G277 -> 626.30481 | H11: =SUM(E11:G11) -> 2015.7823 | I11: =I277 -> 587.55241 | J11: =J277 -> 496.06505 | K11: =K277 -> 453.37827 | L11: =SUM(I11:K11) -> 1536.9957 | M11: =M277 -> 197.70101 | N11: =N277 -> 199.46572 | O11: =O277 -> 225.69751 | P11: =SUM(M11:O11) -> 622.86424 | Q11: =Q277 -> 256.44584 | R11: =R277 -> 405.88484 | S11: =S277 -> 771.43288 | T11: =SUM(Q11:S11) -> 1433.7636
A14: PRODUKSI BUDIDAYA JAWA TIMUR MENURUT KABUPATEN/KOTA
A15: No. | B15: U r a i a n | C15: Satuan | D15: Jumlah | E15: Januari | F15: Februari | G15: Maret | H15: TW I | I15: April | J15: Mei | K15: Juni | L15: TW II | M15: Juli | N15: Agustus | O15: September | P15: TW III | Q15: Oktober | R15: November | S15: Desember | T15: TW IV
B17: JUMLAH | C17: Ton | D17: =SUM(D18:D55) -> 1442333 | E17: =SUM(E18:E55) -> 100101.99 | F17: =SUM(F18:F55) -> 109536.39 | G17: =SUM(G18:G55) -> 120474.07 | H17: =SUM(E17:G17) -> 330112.46 | I17: =SUM(I18:I55) -> 117859.12 | J17: =SUM(J18:J55) -> 120777.12 | K17: =SUM(K18:K55) -> 112310.71 | L17: =SUM(I17:K17) -> 350946.95 | M17: =SUM(M18:M55) -> 125106.38 | N17: =SUM(N18:N55) -> 125340.13 | O17: =SUM(O18:O55) -> 134190.05 | P17: =SUM(M17:O17) -> 384636.55 | Q17: =SUM(Q18:Q55) -> 119766.41 | R17: =SUM(R18:R55) -> 122691.29 | S17: =SUM(S18:S55) -> 134179.34 | T17: =SUM(Q17:S17) -> 376637.04
A18: 1 | B18: KABUPATEN BANGKALAN | C18: Ton | D18: =SUM(H18,L18,P18,T18) -> 15081.607 | E18: =SUM(E62,E106,E149,E192,E235,E278) -> 1605.705 | F18: =SUM(F62,F106,F149,F192,F235,F278) -> 1634.597 | G18: =SUM(G62,G106,G149,G192,G235,G278) -> 1715.25 | H18: =SUM(E18:G18) -> 4955.552 | I18: =SUM(I62,I106,I149,I192,I235,I278) -> 736.5 | J18: =SUM(J62,J106,J149,J192,J235,J278) -> 666.785 | K18: =SUM(K62,K106,K149,K192,K235,K278) -> 633 | L18: =SUM(I18:K18) -> 2036.285 | M18: =SUM(M62,M106,M149,M192,M235,M278) -> 612.82 | N18: =SUM(N62,N106,N149,N192,N235,N278) -> 594 | O18: =SUM(O62,O106,O149,O192,O235,O278) -> 549.95 | P18: =SUM(M18:O18) -> 1756.77 | Q18: =SUM(Q62,Q106,Q149,Q192,Q235,Q278) -> 1414.4 | R18: =SUM(R62,R106,R149,R192,R235,R278) -> 1938.7 | S18: =SUM(S62,S106,S149,S192,S235,S278) -> 2979.9 | T18: =SUM(Q18:S18) -> 6333
A19: =A18+1 -> 2 | B19: KABUPATEN BANYUWANGI | C19: Ton | D19: =SUM(H19,L19,P19,T19) -> 30646.435 | E19: =SUM(E63,E107,E150,E193,E236,E279) -> 2406.035 | F19: =SUM(F63,F107,F150,F193,F236,F279) -> 2451.255 | G19: =SUM(G63,G107,G150,G193,G236,G279) -> 2444.88 | H19: =SUM(E19:G19) -> 7302.17 | I19: =SUM(I63,I107,I150,I193,I236,I279) -> 2485.895 | J19: =SUM(J63,J107,J150,J193,J236,J279) -> 2543.509 | K19: =SUM(K63,K107,K150,K193,K236,K279) -> 2519.45 | L19: =SUM(I19:K19) -> 7548.854 | M19: =SUM(M63,M107,M150,M193,M236,M279) -> 2582.146 | N19: =SUM(N63,N107,N150,N193,N236,N279) -> 2542.555 | O19: =SUM(O63,O107,O150,O193,O236,O279) -> 2597.649 | P19: =SUM(M19:O19) -> 7722.35 | Q19: =SUM(Q63,Q107,Q150,Q193,Q236,Q279) -> 2669.63 | R19: =SUM(R63,R107,R150,R193,R236,R279) -> 2730.051 | S19: =SUM(S63,S107,S150,S193,S236,S279) -> 2673.38 | T19: =SUM(Q19:S19) -> 8073.061
A20: =A19+1 -> 3 | B20: KABUPATEN BLITAR | C20: Ton | D20: =SUM(H20,L20,P20,T20) -> 17736.425 | E20: =SUM(E64,E108,E151,E194,E237,E280) -> 1348.3 | F20: =SUM(F64,F108,F151,F194,F237,F280) -> 1369.32 | G20: =SUM(G64,G108,G151,G194,G237,G280) -> 1420.56 | H20: =SUM(E20:G20) -> 4138.18 | I20: =SUM(I64,I108,I151,I194,I237,I280) -> 1492.15 | J20: =SUM(J64,J108,J151,J194,J237,J280) -> 1481.8 | K20: =SUM(K64,K108,K151,K194,K237,K280) -> 1473.79 | L20: =SUM(I20:K20) -> 4447.74 | M20: =SUM(M64,M108,M151,M194,M237,M280) -> 1488.46 | N20: =SUM(N64,N108,N151,N194,N237,N280) -> 1480.9 | O20: =SUM(O64,O108,O151,O194,O237,O280) -> 1310.5 | P20: =SUM(M20:O20) -> 4279.86 | Q20: =SUM(Q64,Q108,Q151,Q194,Q237,Q280) -> 1568.915 | R20: =SUM(R64,R108,R151,R194,R237,R280) -> 1641.46 | S20: =SUM(S64,S108,S151,S194,S237,S280) -> 1660.27 | T20: =SUM(Q20:S20) -> 4870.645
A21: =A20+1 -> 4 | B21: KABUPATEN BOJONEGORO | C21: Ton | D21: =SUM(H21,L21,P21,T21) -> 5384.128 | E21: =SUM(E65,E109,E152,E195,E238,E281) -> 566.063 | F21: =SUM(F65,F109,F152,F195,F238,F281) -> 540.145 | G21: =SUM(G65,G109,G152,G195,G238,G281) -> 504.827 | H21: =SUM(E21:G21) -> 1611.035 | I21: =SUM(I65,I109,I152,I195,I238,I281) -> 460.57 | J21: =SUM(J65,J109,J152,J195,J238,J281) -> 422.38 | K21: =SUM(K65,K109,K152,K195,K238,K281) -> 383.756 | L21: =SUM(I21:K21) -> 1266.706 | M21: =SUM(M65,M109,M152,M195,M238,M281) -> 331.584 | N21: =SUM(N65,N109,N152,N195,N238,N281) -> 345.653 | O21: =SUM(O65,O109,O152,O195,O238,O281) -> 386.585 | P21: =SUM(M21:O21) -> 1063.822 | Q21: =SUM(Q65,Q109,Q152,Q195,Q238,Q281) -> 422.596 | R21: =SUM(R65,R109,R152,R195,R238,R281) -> 505.617 | S21: =SUM(S65,S109,S152,S195,S238,S281) -> 514.352 | T21: =SUM(Q21:S21) -> 1442.565
A22: =A21+1 -> 5 | B22: KABUPATEN BONDOWOSO | C22: Ton | D22: =SUM(H22,L22,P22,T22) -> 849.316 | E22: =SUM(E66,E110,E153,E196,E239,E282) -> 75.492 | F22: =SUM(F66,F110,F153,F196,F239,F282) -> 72.229 | G22: =SUM(G66,G110,G153,G196,G239,G282) -> 78.873 | H22: =SUM(E22:G22) -> 226.594 | I22: =SUM(I66,I110,I153,I196,I239,I282) -> 70.17 | J22: =SUM(J66,J110,J153,J196,J239,J282) -> 66.314 | K22: =SUM(K66,K110,K153,K196,K239,K282) -> 70.069 | L22: =SUM(I22:K22) -> 206.553 | M22: =SUM(M66,M110,M153,M196,M239,M282) -> 67.283 | N22: =SUM(N66,N110,N153,N196,N239,N282) -> 69.232 | O22: =SUM(O66,O110,O153,O196,O239,O282) -> 66.202 | P22: =SUM(M22:O22) -> 202.717 | Q22: =SUM(Q66,Q110,Q153,Q196,Q239,Q282) -> 67.037 | R22: =SUM(R66,R110,R153,R196,R239,R282) -> 67.907 | S22: =SUM(S66,S110,S153,S196,S239,S282) -> 78.508 | T22: =SUM(Q22:S22) -> 213.452
A23: =A22+1 -> 6 | B23: KABUPATEN GRESIK | C23: Ton | D23: =SUM(H23,L23,P23,T23) -> 160439.07 | E23: =SUM(E67,E111,E154,E197,E240,E283) -> 12043.717 | F23: =SUM(F67,F111,F154,F197,F240,F283) -> 14138.772 | G23: =SUM(G67,G111,G154,G197,G240,G283) -> 14661.92 | H23: =SUM(E23:G23) -> 40844.408 | I23: =SUM(I67,I111,I154,I197,I240,I283) -> 13614.64 | J23: =SUM(J67,J111,J154,J197,J240,J283) -> 13091.1 | K23: =SUM(K67,K111,K154,K197,K240,K283) -> 14138.28 | L23: =SUM(I23:K23) -> 40844.02 | M23: =SUM(M67,M111,M154,M197,M240,M283) -> 12567.36 | N23: =SUM(N67,N111,N154,N197,N240,N283) -> 13091.003 | O23: =SUM(O67,O111,O154,O197,O240,O283) -> 14342.921 | P23: =SUM(M23:O23) -> 40001.284 | Q23: =SUM(Q67,Q111,Q154,Q197,Q240,Q283) -> 14661.922 | R23: =SUM(R67,R111,R154,R197,R240,R283) -> 12043.72 | S23: =SUM(S67,S111,S154,S197,S240,S283) -> 12043.72 | T23: =SUM(Q23:S23) -> 38749.362
A24: =A23+1 -> 7 | B24: KABUPATEN JEMBER | C24: Ton | D24: =SUM(H24,L24,P24,T24) -> 16410.715 | E24: =SUM(E68,E112,E155,E198,E241,E284) -> 1209.76 | F24: =SUM(F68,F112,F155,F198,F241,F284) -> 1588.36 | G24: =SUM(G68,G112,G155,G198,G241,G284) -> 1430.868 | H24: =SUM(E24:G24) -> 4228.988 | I24: =SUM(I68,I112,I155,I198,I241,I284) -> 1133.003 | J24: =SUM(J68,J112,J155,J198,J241,J284) -> 1093.578 | K24: =SUM(K68,K112,K155,K198,K241,K284) -> 1105.544 | L24: =SUM(I24:K24) -> 3332.125 | M24: =SUM(M68,M112,M155,M198,M241,M284) -> 1407.47 | N24: =SUM(N68,N112,N155,N198,N241,N284) -> 1512.05 | O24: =SUM(O68,O112,O155,O198,O241,O284) -> 1469.32 | P24: =SUM(M24:O24) -> 4388.8399 | Q24: =SUM(Q68,Q112,Q155,Q198,Q241,Q284) -> 1362.1245 | R24: =SUM(R68,R112,R155,R198,R241,R284) -> 1335.435 | S24: =SUM(S68,S112,S155,S198,S241,S284) -> 1763.203 | T24: =SUM(Q24:S24) -> 4460.7625
A25: =A24+1 -> 8 | B25: KABUPATEN JOMBANG | C25: Ton | D25: =SUM(H25,L25,P25,T25) -> 14792 | E25: =SUM(E69,E113,E156,E199,E242,E285) -> 1333.2 | F25: =SUM(F69,F113,F156,F199,F242,F285) -> 1244.8 | G25: =SUM(G69,G113,G156,G199,G242,G285) -> 1267.7 | H25: =SUM(E25:G25) -> 3845.7 | I25: =SUM(I69,I113,I156,I199,I242,I285) -> 1349.7 | J25: =SUM(J69,J113,J156,J199,J242,J285) -> 1228.6 | K25: =SUM(K69,K113,K156,K199,K242,K285) -> 1149.5 | L25: =SUM(I25:K25) -> 3727.8 | M25: =SUM(M69,M113,M156,M199,M242,M285) -> 1242.3 | N25: =SUM(N69,N113,N156,N199,N242,N285) -> 1101.2 | O25: =SUM(O69,O113,O156,O199,O242,O285) -> 1208.4 | P25: =SUM(M25:O25) -> 3551.9 | Q25: =SUM(Q69,Q113,Q156,Q199,Q242,Q285) -> 1188.8 | R25: =SUM(R69,R113,R156,R199,R242,R285) -> 1185.1 | S25: =SUM(S69,S113,S156,S199,S242,S285) -> 1292.7 | T25: =SUM(Q25:S25) -> 3666.6
A26: =A25+1 -> 9 | B26: KABUPATEN KEDIRI | C26: Ton | D26: =SUM(H26,L26,P26,T26) -> 25514.275 | E26: =SUM(E70,E114,E157,E200,E243,E286) -> 2088.55 | F26: =SUM(F70,F114,F157,F200,F243,F286) -> 2135.32 | G26: =SUM(G70,G114,G157,G200,G243,G286) -> 2193.25 | H26: =SUM(E26:G26) -> 6417.12 | I26: =SUM(I70,I114,I157,I200,I243,I286) -> 2124.38 | J26: =SUM(J70,J114,J157,J200,J243,J286) -> 2363.345 | K26: =SUM(K70,K114,K157,K200,K243,K286) -> 2429.395 | L26: =SUM(I26:K26) -> 6917.12 | M26: =SUM(M70,M114,M157,M200,M243,M286) -> 2040.43 | N26: =SUM(N70,N114,N157,N200,N243,N286) -> 2054.94 | O26: =SUM(O70,O114,O157,O200,O243,O286) -> 2003.415 | P26: =SUM(M26:O26) -> 6098.785 | Q26: =SUM(Q70,Q114,Q157,Q200,Q243,Q286) -> 1917.725 | R26: =SUM(R70,R114,R157,R200,R243,R286) -> 2044.945 | S26: =SUM(S70,S114,S157,S200,S243,S286) -> 2118.58 | T26: =SUM(Q26:S26) -> 6081.25
A27: =A26+1 -> 10 | B27: KABUPATEN LAMONGAN | C27: Ton | D27: =SUM(H27,L27,P27,T27) -> 46941.847 | E27: =SUM(E71,E115,E158,E201,E244,E287) -> 2935.83 | F27: =SUM(F71,F115,F158,F201,F244,F287) -> 4251.231 | G27: =SUM(G71,G115,G158,G201,G244,G287) -> 6773.719 | H27: =SUM(E27:G27) -> 13960.78 | I27: =SUM(I71,I115,I158,I201,I244,I287) -> 8545.468 | J27: =SUM(J71,J115,J158,J201,J244,J287) -> 13676.414 | K27: =SUM(K71,K115,K158,K201,K244,K287) -> 5958.024 | L27: =SUM(I27:K27) -> 28179.906 | M27: =SUM(M71,M115,M158,M201,M244,M287) -> 1631.901 | N27: =SUM(N71,N115,N158,N201,N244,N287) -> 809.437 | O27: =SUM(O71,O115,O158,O201,O244,O287) -> 573.975 | P27: =SUM(M27:O27) -> 3015.313 | Q27: =SUM(Q71,Q115,Q158,Q201,Q244,Q287) -> 540.527 | R27: =SUM(R71,R115,R158,R201,R244,R287) -> 545.437 | S27: =SUM(S71,S115,S158,S201,S244,S287) -> 699.884 | T27: =SUM(Q27:S27) -> 1785.848
A28: =A27+1 -> 11 | B28: KABUPATEN LUMAJANG | C28: Ton | D28: =SUM(H28,L28,P28,T28) -> 5111.5964 | E28: =SUM(E72,E116,E159,E202,E245,E288) -> 432 | F28: =SUM(F72,F116,F159,F202,F245,F288) -> 415 | G28: =SUM(G72,G116,G159,G202,G245,G288) -> 465.0004 | H28: =SUM(E28:G28) -> 1312.0004 | I28: =SUM(I72,I116,I159,I202,I245,I288) -> 425.134 | J28: =SUM(J72,J116,J159,J202,J245,J288) -> 422.873 | K28: =SUM(K72,K116,K159,K202,K245,K288) -> 415.31 | L28: =SUM(I28:K28) -> 1263.317 | M28: =SUM(M72,M116,M159,M202,M245,M288) -> 405.431 | N28: =SUM(N72,N116,N159,N202,N245,N288) -> 434.854 | O28: =SUM(O72,O116,O159,O202,O245,O288) -> 410.608 | P28: =SUM(M28:O28) -> 1250.893 | Q28: =SUM(Q72,Q116,Q159,Q202,Q245,Q288) -> 416.413 | R28: =SUM(R72,R116,R159,R202,R245,R288) -> 389.453 | S28: =SUM(S72,S116,S159,S202,S245,S288) -> 479.52 | T28: =SUM(Q28:S28) -> 1285.386
A29: =A28+1 -> 12 | B29: KABUPATEN MADIUN | C29: Ton | D29: =SUM(H29,L29,P29,T29) -> 3850.1 | E29: =SUM(E73,E117,E160,E203,E246,E289) -> 322.95 | F29: =SUM(F73,F117,F160,F203,F246,F289) -> 319.05 | G29: =SUM(G73,G117,G160,G203,G246,G289) -> 341.3 | H29: =SUM(E29:G29) -> 983.3 | I29: =SUM(I73,I117,I160,I203,I246,I289) -> 349.1 | J29: =SUM(J73,J117,J160,J203,J246,J289) -> 314.6 | K29: =SUM(K73,K117,K160,K203,K246,K289) -> 327.1 | L29: =SUM(I29:K29) -> 990.8 | M29: =SUM(M73,M117,M160,M203,M246,M289) -> 287.55 | N29: =SUM(N73,N117,N160,N203,N246,N289) -> 296.45 | O29: =SUM(O73,O117,O160,O203,O246,O289) -> 297.45 | P29: =SUM(M29:O29) -> 881.45 | Q29: =SUM(Q73,Q117,Q160,Q203,Q246,Q289) -> 326.55 | R29: =SUM(R73,R117,R160,R203,R246,R289) -> 328.75 | S29: =SUM(S73,S117,S160,S203,S246,S289) -> 339.25 | T29: =SUM(Q29:S29) -> 994.55
A30: =A29+1 -> 13 | B30: KABUPATEN MAGETAN | C30: Ton | D30: =SUM(H30,L30,P30,T30) -> 1860.28 | E30: =SUM(E74,E118,E161,E204,E247,E290) -> 153.1 | F30: =SUM(F74,F118,F161,F204,F247,F290) -> 159.77 | G30: =SUM(G74,G118,G161,G204,G247,G290) -> 170.71 | H30: =SUM(E30:G30) -> 483.58 | I30: =SUM(I74,I118,I161,I204,I247,I290) -> 160.7 | J30: =SUM(J74,J118,J161,J204,J247,J290) -> 162.29 | K30: =SUM(K74,K118,K161,K204,K247,K290) -> 160.71 | L30: =SUM(I30:K30) -> 483.7 | M30: =SUM(M74,M118,M161,M204,M247,M290) -> 148.21 | N30: =SUM(N74,N118,N161,N204,N247,N290) -> 143.65 | O30: =SUM(O74,O118,O161,O204,O247,O290) -> 139.13 | P30: =SUM(M30:O30) -> 430.99 | Q30: =SUM(Q74,Q118,Q161,Q204,Q247,Q290) -> 149.31 | R30: =SUM(R74,R118,R161,R204,R247,R290) -> 155.65 | S30: =SUM(S74,S118,S161,S204,S247,S290) -> 157.05 | T30: =SUM(Q30:S30) -> 462.01
... A39: =A38+1 -> 22 | B39: KABUPATEN PROBOLINGGO | C39: Ton | D39: =SUM(H39,L39,P39,T39) -> 15433.568 | E39: =SUM(E83,E127,E170,E213,E256,E299) -> 1847.4 | F39: =SUM(F83,F127,F170,F213,F256,F299) -> 1693.5 | G39: =SUM(G83,G127,G170,G213,G256,G299) -> 1172 | H39: =SUM(E39:G39) -> 4712.9 | I39: =SUM(I83,I127,I170,I213,I256,I299) -> 1939.1 | J39: =SUM(J83,J127,J170,J213,J256,J299) -> 607.84 | K39: =SUM(K83,K127,K170,K213,K256,K299) -> 1339.65 | L39: =SUM(I39:K39) -> 3886.59 | M39: =SUM(M83,M127,M170,M213,M256,M299) -> 1524.938 | N39: =SUM(N83,N127,N170,N213,N256,N299) -> 1334.75 | O39: =SUM(O83,O127,O170,O213,O256,O299) -> 1167.52 | P39: =SUM(M39:O39) -> 4027.208 | Q39: =SUM(Q83,Q127,Q170,Q213,Q256,Q299) -> 1014.97 | R39: =SUM(R83,R127,R170,R213,R256,R299) -> 736.39 | S39: =SUM(S83,S127,S170,S213,S256,S299) -> 1055.51 | T39: =SUM(Q39:S39) -> 2806.87
A40: 23 | B40: KABUPATEN SAMPANG | C40: Ton | D40: =SUM(H40,L40,P40,T40) -> 1083.028 | E40: =SUM(E84,E128,E171,E214,E257,E300) -> 86.751 | F40: =SUM(F84,F128,F171,F214,F257,F300) -> 166.838 | G40: =SUM(G84,G128,G171,G214,G257,G300) -> 61.056 | H40: =SUM(E40:G40) -> 314.645 | I40: =SUM(I84,I128,I171,I214,I257,I300) -> 91.713 | J40: =SUM(J84,J128,J171,J214,J257,J300) -> 136.991 | K40: =SUM(K84,K128,K171,K214,K257,K300) -> 128.663 | L40: =SUM(I40:K40) -> 357.367 | M40: =SUM(M84,M128,M171,M214,M257,M300) -> 54.1 | N40: =SUM(N84,N128,N171,N214,N257,N300) -> 52.42 | O40: =SUM(O84,O128,O171,O214,O257,O300) -> 40.85 | P40: =SUM(M40:O40) -> 147.37 | Q40: =SUM(Q84,Q128,Q171,Q214,Q257,Q300) -> 63.393 | R40: =SUM(R84,R128,R171,R214,R257,R300) -> 76.613 | S40: =SUM(S84,S128,S171,S214,S257,S300) -> 123.64 | T40: =SUM(Q40:S40) -> 263.646
A41: 24 | B41: KABUPATEN SIDOARJO | C41: Ton | D41: =SUM(H41,L41,P41,T41) -> 110739.69 | E41: =SUM(E85,E129,E172,E215,E258,E301) -> 6842.34 | F41: =SUM(F85,F129,F172,F215,F258,F301) -> 8927.811 | G41: =SUM(G85,G129,G172,G215,G258,G301) -> 10673.23 | H41: =SUM(E41:G41) -> 26443.381 | I41: =SUM(I85,I129,I172,I215,I258,I301) -> 8999.8 | J41: =SUM(J85,J129,J172,J215,J258,J301) -> 9316.89 | K41: =SUM(K85,K129,K172,K215,K258,K301) -> 8322.762 | L41: =SUM(I41:K41) -> 26639.452 | M41: =SUM(M85,M129,M172,M215,M258,M301) -> 8597.5 | N41: =SUM(N85,N129,N172,N215,N258,N301) -> 11627.927 | O41: =SUM(O85,O129,O172,O215,O258,O301) -> 11759.277 | P41: =SUM(M41:O41) -> 31984.704 | Q41: =SUM(Q85,Q129,Q172,Q215,Q258,Q301) -> 8748.209 | R41: =SUM(R85,R129,R172,R215,R258,R301) -> 8025.257 | S41: =SUM(S85,S129,S172,S215,S258,S301) -> 8898.684 | T41: =SUM(Q41:S41) -> 25672.15
A42: 25 | B42: KABUPATEN SITUBONDO | C42: Ton | D42: =SUM(H42,L42,P42,T42) -> 11675.328 | E42: =SUM(E86,E130,E173,E216,E259,E302) -> 1003.856 | F42: =SUM(F86,F130,F173,F216,F259,F302) -> 977.065 | G42: =SUM(G86,G130,G173,G216,G259,G302) -> 1002.806 | H42: =SUM(E42:G42) -> 2983.727 | I42: =SUM(I86,I130,I173,I216,I259,I302) -> 1006.122 | J42: =SUM(J86,J130,J173,J216,J259,J302) -> 1104.638 | K42: =SUM(K86,K130,K173,K216,K259,K302) -> 1009.395 | L42: =SUM(I42:K42) -> 3120.155 | M42: =SUM(M86,M130,M173,M216,M259,M302) -> 972.561 | N42: =SUM(N86,N130,N173,N216,N259,N302) -> 1055.002 | O42: =SUM(O86,O130,O173,O216,O259,O302) -> 1068.847 | P42: =SUM(M42:O42) -> 3096.41 | Q42: =SUM(Q86,Q130,Q173,Q216,Q259,Q302) -> 785.05 | R42: =SUM(R86,R130,R173,R216,R259,R302) -> 919.504 | S42: =SUM(S86,S130,S173,S216,S259,S302) -> 770.482 | T42: =SUM(Q42:S42) -> 2475.036
A43: 26 | B43: KABUPATEN SUMENEP | C43: Ton | D43: =SUM(H43,L43,P43,T43) -> 770272.1 | E43: =SUM(E87,E131,E174,E217,E260,E303) -> 47499.914 | F43: =SUM(F87,F131,F174,F217,F260,F303) -> 51273.365 | G43: =SUM(G87,G131,G174,G217,G260,G303) -> 58200.256 | H43: =SUM(E43:G43) -> 156973.54 | I43: =SUM(I87,I131,I174,I217,I260,I303) -> 56248.26 | J43: =SUM(J87,J131,J174,J217,J260,J303) -> 56940.771 | K43: =SUM(K87,K131,K174,K217,K260,K303) -> 56340.022 | L43: =SUM(I43:K43) -> 169529.05 | M43: =SUM(M87,M131,M174,M217,M260,M303) -> 75576.904 | N43: =SUM(N87,N131,N174,N217,N260,N303) -> 72111.453 | O43: =SUM(O87,O131,O174,O217,O260,O303) -> 80454.008 | P43: =SUM(M43:O43) -> 228142.36 | Q43: =SUM(Q87,Q131,Q174,Q217,Q260,Q303) -> 67305.944 | R43: =SUM(R87,R131,R174,R217,R260,R303) -> 71040.35 | S43: =SUM(S87,S131,S174,S217,S260,S303) -> 77280.849 | T43: =SUM(Q43:S43) -> 215627.14
A44: 27 | B44: KABUPATEN TRENGGALEK | C44: Ton | D44: =SUM(H44,L44,P44,T44) -> 5088.463 | E44: =SUM(E88,E132,E175,E218,E261,E304) -> 429.654 | F44: =SUM(F88,F132,F175,F218,F261,F304) -> 443.616 | G44: =SUM(G88,G132,G175,G218,G261,G304) -> 457.544 | H44: =SUM(E44:G44) -> 1330.814 | I44: =SUM(I88,I132,I175,I218,I261,I304) -> 485.558 | J44: =SUM(J88,J132,J175,J218,J261,J304) -> 462.37 | K44: =SUM(K88,K132,K175,K218,K261,K304) -> 448.608 | L44: =SUM(I44:K44) -> 1396.536 | M44: =SUM(M88,M132,M175,M218,M261,M304) -> 430.775 | N44: =SUM(N88,N132,N175,N218,N261,N304) -> 407.875 | O44: =SUM(O88,O132,O175,O218,O261,O304) -> 397.795 | P44: =SUM(M44:O44) -> 1236.445 | Q44: =SUM(Q88,Q132,Q175,Q218,Q261,Q304) -> 386.856 | R44: =SUM(R88,R132,R175,R218,R261,R304) -> 376.443 | S44: =SUM(S88,S132,S175,S218,S261,S304) -> 361.369 | T44: =SUM(Q44:S44) -> 1124.668
A45: 28 | B45: KABUPATEN TUBAN | C45: Ton | D45: =SUM(H45,L45,P45,T45) -> 53319.43 | E45: =SUM(E89,E133,E176,E219,E262,E305) -> 4897.61 | F45: =SUM(F89,F133,F176,F219,F262,F305) -> 5185.71 | G45: =SUM(G89,G133,G176,G219,G262,G305) -> 4321.42 | H45: =SUM(E45:G45) -> 14404.74 | I45: =SUM(I89,I133,I176,I219,I262,I305) -> 4938.77 | J45: =SUM(J89,J133,J176,J219,J262,J305) -> 4321.42 | K45: =SUM(K89,K133,K176,K219,K262,K305) -> 3086.73 | L45: =SUM(I45:K45) -> 12346.92 | M45: =SUM(M89,M133,M176,M219,M262,M305) -> 2639.17 | N45: =SUM(N89,N133,N176,N219,N262,N305) -> 3518.88 | O45: =SUM(O89,O133,O176,O219,O262,O305) -> 3616.62 | P45: =SUM(M45:O45) -> 9774.67 | Q45: =SUM(Q89,Q133,Q176,Q219,Q262,Q305) -> 4475.76 | R45: =SUM(R89,R133,R176,R219,R262,R305) -> 5623.34 | S45: =SUM(S89,S133,S176,S219,S262,S305) -> 6694 | T45: =SUM(Q45:S45) -> 16793.1
A46: 29 | B46: KABUPATEN TULUNGAGUNG | C46: Ton | D46: =SUM(H46,L46,P46,T46) -> 53751.5 | E46: =SUM(E90,E134,E177,E220,E263,E306) -> 4094 | F46: =SUM(F90,F134,F177,F220,F263,F306) -> 4034 | G46: =SUM(G90,G134,G177,G220,G263,G306) -> 4244 | H46: =SUM(E46:G46) -> 12372 | I46: =SUM(I90,I134,I177,I220,I263,I306) -> 4436 | J46: =SUM(J90,J134,J177,J220,J263,J306) -> 4544 | K46: =SUM(K90,K134,K177,K220,K263,K306) -> 4839.5 | L46: =SUM(I46:K46) -> 13819.5 | M46: =SUM(M90,M134,M177,M220,M263,M306) -> 4569.5 | N46: =SUM(N90,N134,N177,N220,N263,N306) -> 4334.5 | O46: =SUM(O90,O134,O177,O220,O263,O306) -> 4304.5 | P46: =SUM(M46:O46) -> 13208.5 | Q46: =SUM(Q90,Q134,Q177,Q220,Q263,Q306) -> 4334.5 | R46: =SUM(R90,R134,R177,R220,R263,R306) -> 4935 | S46: =SUM(S90,S134,S177,S220,S263,S306) -> 5082 | T46: =SUM(Q46:S46) -> 14351.5
A47: 30 | B47: KOTA BATU | C47: Ton | D47: =SUM(H47,L47,P47,T47) -> 65.339 | E47: =SUM(E91,E135,E178,E221,E264,E307) -> 4.635 | F47: =SUM(F91,F135,F178,F221,F264,F307) -> 5.993 | G47: =SUM(G91,G135,G178,G221,G264,G307) -> 4.573 | H47: =SUM(E47:G47) -> 15.201 | I47: =SUM(I91,I135,I178,I221,I264,I307) -> 5.63 | J47: =SUM(J91,J135,J178,J221,J264,J307) -> 5.245 | K47: =SUM(K91,K135,K178,K221,K264,K307) -> 4.955 | L47: =SUM(I47:K47) -> 15.83 | M47: =SUM(M91,M135,M178,M221,M264,M307) -> 5.24 | N47: =SUM(N91,N135,N178,N221,N264,N307) -> 5.739 | O47: =SUM(O91,O135,O178,O221,O264,O307) -> 5.904 | P47: =SUM(M47:O47) -> 16.883 | Q47: =SUM(Q91,Q135,Q178,Q221,Q264,Q307) -> 5.805 | R47: =SUM(R91,R135,R178,R221,R264,R307) -> 5.863 | S47: =SUM(S91,S135,S178,S221,S264,S307) -> 5.757 | T47: =SUM(Q47:S47) -> 17.425
A48: 31 | B48: KOTA BLITAR | C48: Ton | D48: =SUM(H48,L48,P48,T48) -> 244.78 | E48: =SUM(E92,E136,E179,E222,E265,E308) -> 22.81 | F48: =SUM(F92,F136,F179,F222,F265,F308) -> 22.63 | G48: =SUM(G92,G136,G179,G222,G265,G308) -> 22.99 | H48: =SUM(E48:G48) -> 68.43 | I48: =SUM(I92,I136,I179,I222,I265,I308) -> 22.57 | J48: =SUM(J92,J136,J179,J222,J265,J308) -> 21.56 | K48: =SUM(K92,K136,K179,K222,K265,K308) -> 18.57 | L48: =SUM(I48:K48) -> 62.7 | M48: =SUM(M92,M136,M179,M222,M265,M308) -> 20.3 | N48: =SUM(N92,N136,N179,N222,N265,N308) -> 20.41 | O48: =SUM(O92,O136,O179,O222,O265,O308) -> 20.43 | P48: =SUM(M48:O48) -> 61.14 | Q48: =SUM(Q92,Q136,Q179,Q222,Q265,Q308) -> 17.32 | R48: =SUM(R92,R136,R179,R222,R265,R308) -> 17.5 | S48: =SUM(S92,S136,S179,S222,S265,S308) -> 17.69 | T48: =SUM(Q48:S48) -> 52.51
A49: 32 | B49: KOTA KEDIRI | C49: Ton | D49: =SUM(H49,L49,P49,T49) -> 193.1 | E49: =SUM(E93,E137,E180,E223,E266,E309) -> 16.2 | F49: =SUM(F93,F137,F180,F223,F266,F309) -> 16.7 | G49: =SUM(G93,G137,G180,G223,G266,G309) -> 18 | H49: =SUM(E49:G49) -> 50.9 | I49: =SUM(I93,I137,I180,I223,I266,I309) -> 16.1 | J49: =SUM(J93,J137,J180,J223,J266,J309) -> 16 | K49: =SUM(K93,K137,K180,K223,K266,K309) -> 15.5 | L49: =SUM(I49:K49) -> 47.6 | M49: =SUM(M93,M137,M180,M223,M266,M309) -> 16 | N49: =SUM(N93,N137,N180,N223,N266,N309) -> 11.7 | O49: =SUM(O93,O137,O180,O223,O266,O309) -> 18.6 | P49: =SUM(M49:O49) -> 46.3 | Q49: =SUM(Q93,Q137,Q180,Q223,Q266,Q309) -> 16.1 | R49: =SUM(R93,R137,R180,R223,R266,R309) -> 17.1 | S49: =SUM(S93,S137,S180,S223,S266,S309) -> 15.1 | T49: =SUM(Q49:S49) -> 48.3
A50: 33 | B50: KOTA MADIUN | C50: Ton | D50: =SUM(H50,L50,P50,T50) -> 290.62495 | E50: =SUM(E94,E138,E181,E224,E267,E310) -> 30.025 | F50: =SUM(F94,F138,F181,F224,F267,F310) -> 31.595 | G50: =SUM(G94,G138,G181,G224,G267,G310) -> 30.32498 | H50: =SUM(E50:G50) -> 91.94498 | I50: =SUM(I94,I138,I181,I224,I267,I310) -> 29.89997 | J50: =SUM(J94,J138,J181,J224,J267,J310) -> 27.22 | K50: =SUM(K94,K138,K181,K224,K267,K310) -> 25.67 | L50: =SUM(I50:K50) -> 82.78997 | M50: =SUM(M94,M138,M181,M224,M267,M310) -> 18.875 | N50: =SUM(N94,N138,N181,N224,N267,N310) -> 18.565 | O50: =SUM(O94,O138,O181,O224,O267,O310) -> 17.925 | P50: =SUM(M50:O50) -> 55.365 | Q50: =SUM(Q94,Q138,Q181,Q224,Q267,Q310) -> 18.805 | R50: =SUM(R94,R138,R181,R224,R267,R310) -> 19.865 | S50: =SUM(S94,S138,S181,S224,S267,S310) -> 21.855 | T50: =SUM(Q50:S50) -> 60.525
A51: 34 | B51: KOTA MALANG | C51: Ton | D51: =SUM(H51,L51,P51,T51) -> 162 | E51: =SUM(E95,E139,E182,E225,E268,E311) -> 4.85 | F51: =SUM(F95,F139,F182,F225,F268,F311) -> 14.05 | G51: =SUM(G95,G139,G182,G225,G268,G311) -> 28.1 | H51: =SUM(E51:G51) -> 47 | I51: =SUM(I95,I139,I182,I225,I268,I311) -> 6.95 | J51: =SUM(J95,J139,J182,J225,J268,J311) -> 12.8 | K51: =SUM(K95,K139,K182,K225,K268,K311) -> 15.25 | L51: =SUM(I51:K51) -> 35 | M51: =SUM(M95,M139,M182,M225,M268,M311) -> 10.1 | N51: =SUM(N95,N139,N182,N225,N268,N311) -> 8.7 | O51: =SUM(O95,O139,O182,O225,O268,O311) -> 6.2 | P51: =SUM(M51:O51) -> 25 | Q51: =SUM(Q95,Q139,Q182,Q225,Q268,Q311) -> 8.3 | R51: =SUM(R95,R139,R182,R225,R268,R311) -> 18.5 | S51: =SUM(S95,S139,S182,S225,S268,S311) -> 28.2 | T51: =SUM(Q51:S51) -> 55
... A55: 38 | B55: KOTA SURABAYA | C55: Ton | D55: =SUM(H55,L55,P55,T55) -> 9979.52 | E55: =SUM(E99,E143,E186,E229,E272,E315) -> 872.987 | F55: =SUM(F99,F143,F186,F229,F272,F315) -> 963.117 | G55: =SUM(G99,G143,G186,G229,G272,G315) -> 1058.596 | H55: =SUM(E55:G55) -> 2894.7 | I55: =SUM(I99,I143,I186,I229,I272,I315) -> 690.53 | J55: =SUM(J99,J143,J186,J229,J272,J315) -> 782.832 | K55: =SUM(K99,K143,K186,K229,K272,K315) -> 799.268 | L55: =SUM(I55:K55) -> 2272.63 | M55: =SUM(M99,M143,M186,M229,M272,M315) -> 804.63 | N55: =SUM(N99,N143,N186,N229,N272,N315) -> 782.43 | O55: =SUM(O99,O143,O186,O229,O272,O315) -> 775.18 | P55: =SUM(M55:O55) -> 2362.24 | Q55: =SUM(Q99,Q143,Q186,Q229,Q272,Q315) -> 800.78 | R55: =SUM(R99,R143,R186,R229,R272,R315) -> 862.74 | S55: =SUM(S99,S143,S186,S229,S272,S315) -> 786.43 | T55: =SUM(Q55:S55) -> 2449.95
...

Sheet TANGKAP
A1: PRODUKSI PERIKANAN TANGKAP JAWA TIMUR
B3: JENIS USAHA | C3: SATUAN | D3: JUMLAH | E3: TRIWULAN 2025
E4: Januari | F4: Februari | G4: Maret | H4: TW I | I4: April | J4: Mei | K4: Juni | L4: TW II | M4: Juli | N4: Agustus | O4: September | P4: TW III | Q4: Oktober | R4: November | S4: Desember | T4: TW IV
C5: TON | D5: =SUM(D6:D8) -> 607343.91 | E5: =SUM(E6:E8) -> 44320.111 | F5: =SUM(F6:F8) -> 37536.034 | G5: =SUM(G6:G8) -> 41768.325 | H5: =SUM(E5:G5) -> 123624.47 | I5: =SUM(I6:I8) -> 47007.973 | J5: =SUM(J6:J8) -> 52953.863 | K5: =SUM(K6:K8) -> 50700.556 | L5: =SUM(I5:K5) -> 150662.39 | M5: =SUM(M6:M8) -> 61473.013 | N5: =SUM(N6:N8) -> 57456.03 | O5: =SUM(O6:O8) -> 63027.588 | P5: =SUM(M5:O5) -> 181956.63 | Q5: =SUM(Q6:Q8) -> 56439.269 | R5: =SUM(R6:R8) -> 50806.882 | S5: =SUM(S6:S8) -> 43854.262 | T5: =SUM(Q5:S5) -> 151100.41
B6: Laut / Non Pelabuhan | C6: Ton | D6: =SUM(H6,L6,P6,T6) -> 391334.21 | E6: =E58 -> 29152.746 | F6: =F58 -> 26940.293 | G6: =G58 -> 26650.341 | H6: =SUM(E6:G6) -> 82743.38 | I6: =I58 -> 32706.072 | J6: =J58 -> 35177.115 | K6: =K58 -> 34135.075 | L6: =SUM(I6:K6) -> 102018.26 | M6: =M58 -> 36065.859 | N6: =N58 -> 36701.989 | O6: =O58 -> 40121.112 | P6: =SUM(M6:O6) -> 112888.96 | Q6: =Q58 -> 35223.213 | R6: =R58 -> 31009.544 | S6: =S58 -> 27450.849 | T6: =SUM(Q6:S6) -> 93683.606
B7: Pelabuhan | C7: Ton | D7: =SUM(H7,L7,P7,T7) -> 202034.43 | E7: =E102 -> 14042.054 | F7: =F102 -> 9371.009 | G7: =G102 -> 13805.294 | H7: =SUM(E7:G7) -> 37218.357 | I7: =I102 -> 13032.606 | J7: =J102 -> 16472.47 | K7: =K102 -> 15372.703 | L7: =SUM(I7:K7) -> 44877.779 | M7: =M102 -> 24345.19 | N7: =N102 -> 19641.811 | O7: =O102 -> 21784.06 | P7: =SUM(M7:O7) -> 65771.061 | Q7: =Q102 -> 20107.096 | R7: =R102 -> 18712.018 | S7: =S102 -> 15348.116 | T7: =SUM(Q7:S7) -> 54167.23
B8: PUD | C8: Ton | D8: =SUM(H8,L8,P8,T8) -> 13975.271 | E8: =E146 -> 1125.311 | F8: =F146 -> 1224.732 | G8: =G146 -> 1312.69 | H8: =H146 -> 3662.733 | I8: =I146 -> 1269.295 | J8: =J146 -> 1304.278 | K8: =K146 -> 1192.778 | L8: =SUM(I8:K8) -> 3766.351 | M8: =M146 -> 1061.964 | N8: =N146 -> 1112.23 | O8: =O146 -> 1122.416 | P8: =SUM(M8:O8) -> 3296.61 | Q8: =Q146 -> 1108.96 | R8: =R146 -> 1085.32 | S8: =S146 -> 1055.297 | T8: =SUM(Q8:S8) -> 3249.577
A11: PRODUKSI TANGKAP JAWA TIMUR MENURUT KABUPATEN/KOTA
A12: No. | B12: U r a i a n | C12: Satuan | D12: Jumlah | E12: Januari | F12: Februari | G12: Maret | H12: TW I | I12: April | J12: Mei | K12: Juni | L12: TW II | M12: Juli | N12: Agustus | O12: September | P12: TW III | Q12: Oktober | R12: November | S12: Desember | T12: TW IV
B14: JUMLAH | C14: Ton | D14: =SUM(D15:D52) -> 607343.91 | E14: =SUM(E15:E52) -> 44320.111 | F14: =SUM(F15:F52) -> 37536.034 | G14: =SUM(G15:G52) -> 41768.325 | H14: =SUM(E14:G14) -> 123624.47 | I14: =SUM(I15:I52) -> 47007.973 | J14: =SUM(J15:J52) -> 52953.863 | K14: =SUM(K15:K52) -> 50700.556 | L14: =SUM(I14:K14) -> 150662.39 | M14: =SUM(M15:M52) -> 61473.013 | N14: =SUM(N15:N52) -> 57456.03 | O14: =SUM(O15:O52) -> 63027.588 | P14: =SUM(M14:O14) -> 181956.63 | Q14: =SUM(Q15:Q52) -> 56439.269 | R14: =SUM(R15:R52) -> 50806.882 | S14: =SUM(S15:S52) -> 43854.262 | T14: =SUM(Q14:S14) -> 151100.41
A15: 1 | B15: Pacitan | C15: Ton | D15: =SUM(H15,L15,P15,T15) -> 14658.785 | E15: =SUM(E59,E103,E147) -> 468.367 | F15: =SUM(F59,F103,F147) -> 478.546 | G15: =SUM(G59,G103,G147) -> 696.582 | H15: =SUM(E15:G15) -> 1643.495 | I15: =SUM(I59,I103,I147) -> 1041.71 | J15: =SUM(J59,J103,J147) -> 1461.211 | K15: =SUM(K59,K103,K147) -> 1720.228 | L15: =SUM(I15:K15) -> 4223.149 | M15: =SUM(M59,M103,M147) -> 1773.756 | N15: =SUM(N59,N103,N147) -> 2503.661 | O15: =SUM(O59,O103,O147) -> 1813.694 | P15: =SUM(M15:O15) -> 6091.111 | Q15: =SUM(Q59,Q103,Q147) -> 1188.943 | R15: =SUM(R59,R103,R147) -> 736.394 | S15: =SUM(S59,S103,S147) -> 775.693 | T15: =SUM(Q15:S15) -> 2701.03
A16: =A15+1 -> 2 | B16: Ponorogo | C16: Ton | D16: =SUM(H16,L16,P16,T16) -> 11963.11 | E16: =SUM(E60,E104,E148) -> 252.72 | F16: =SUM(F60,F104,F148) -> 100.49 | G16: =SUM(G60,G104,G148) -> 600.21 | H16: =SUM(E16:G16) -> 953.42 | I16: =SUM(I60,I104,I148) -> 1404.96 | J16: =SUM(J60,J104,J148) -> 701.47 | K16: =SUM(K60,K104,K148) -> 377.96 | L16: =SUM(I16:K16) -> 2484.39 | M16: =SUM(M60,M104,M148) -> 4040.57 | N16: =SUM(N60,N104,N148) -> 1162.73 | O16: =SUM(O60,O104,O148) -> 2008.71 | P16: =SUM(M16:O16) -> 7212.01 | Q16: =SUM(Q60,Q104,Q148) -> 981.62 | R16: =SUM(R60,R104,R148) -> 208.48 | S16: =SUM(S60,S104,S148) -> 123.19 | T16: =SUM(Q16:S16) -> 1313.29
A17: =A16+1 -> 3 | B17: Trenggalek | C17: Ton | D17: =SUM(H17,L17,P17,T17) -> 7422.044 | E17: =SUM(E61,E105,E149) -> 348.495 | F17: =SUM(F61,F105,F149) -> 248.093 | G17: =SUM(G61,G105,G149) -> 363.859 | H17: =SUM(E17:G17) -> 960.447 | I17: =SUM(I61,I105,I149) -> 431.182 | J17: =SUM(J61,J105,J149) -> 561.982 | K17: =SUM(K61,K105,K149) -> 537.937 | L17: =SUM(I17:K17) -> 1531.101 | M17: =SUM(M61,M105,M149) -> 1232.282 | N17: =SUM(N61,N105,N149) -> 936.304 | O17: =SUM(O61,O105,O149) -> 1012.475 | P17: =SUM(M17:O17) -> 3181.061 | Q17: =SUM(Q61,Q105,Q149) -> 866.003 | R17: =SUM(R61,R105,R149) -> 439.794 | S17: =SUM(S61,S105,S149) -> 443.638 | T17: =SUM(Q17:S17) -> 1749.435
A18: =A17+1 -> 4 | B18: Tulungagung | C18: Ton | D18: =SUM(H18,L18,P18,T18) -> 13924.347 | E18: =SUM(E62,E106,E150) -> 1491.186 | F18: =SUM(F62,F106,F150) -> 1081.316 | G18: =SUM(G62,G106,G150) -> 810.22 | H18: =SUM(E18:G18) -> 3382.722 | I18: =SUM(I62,I106,I150) -> 853.52 | J18: =SUM(J62,J106,J150) -> 1302.516 | K18: =SUM(K62,K106,K150) -> 1144.49 | L18: =SUM(I18:K18) -> 3300.526 | M18: =SUM(M62,M106,M150) -> 1323.874 | N18: =SUM(N62,N106,N150) -> 1478.214 | O18: =SUM(O62,O106,O150) -> 1154.757 | P18: =SUM(M18:O18) -> 3956.845 | Q18: =SUM(Q62,Q106,Q150) -> 1497.153 | R18: =SUM(R62,R106,R150) -> 886.006 | S18: =SUM(S62,S106,S150) -> 901.095 | T18: =SUM(Q18:S18) -> 3284.254
A19: =A18+1 -> 5 | B19: Blitar | C19: Ton | D19: =SUM(H19,L19,P19,T19) -> 3828.242 | E19: =SUM(E63,E107,E151) -> 151.41 | F19: =SUM(F63,F107,F151) -> 159.956 | G19: =SUM(G63,G107,G151) -> 122.509 | H19: =SUM(E19:G19) -> 433.875 | I19: =SUM(I63,I107,I151) -> 264.775 | J19: =SUM(J63,J107,J151) -> 176.052 | K19: =SUM(K63,K107,K151) -> 208.29 | L19: =SUM(I19:K19) -> 649.117 | M19: =SUM(M63,M107,M151) -> 541.34 | N19: =SUM(N63,N107,N151) -> 497.01 | O19: =SUM(O63,O107,O151) -> 419.95 | P19: =SUM(M19:O19) -> 1458.3 | Q19: =SUM(Q63,Q107,Q151) -> 444.4 | R19: =SUM(R63,R107,R151) -> 460.75 | S19: =SUM(S63,S107,S151) -> 381.8 | T19: =SUM(Q19:S19) -> 1286.95
A20: =A19+1 -> 6 | B20: Kediri | C20: Ton | D20: =SUM(H20,L20,P20,T20) -> 17331.797 | E20: =SUM(E64,E108,E152) -> 50.207 | F20: =SUM(F64,F108,F152) -> 769.076 | G20: =SUM(G64,G108,G152) -> 1581.142 | H20: =SUM(E20:G20) -> 2400.425 | I20: =SUM(I64,I108,I152) -> 1539.294 | J20: =SUM(J64,J108,J152) -> 1956.511 | K20: =SUM(K64,K108,K152) -> 2481.357 | L20: =SUM(I20:K20) -> 5977.162 | M20: =SUM(M64,M108,M152) -> 2507.17 | N20: =SUM(N64,N108,N152) -> 1927.09 | O20: =SUM(O64,O108,O152) -> 1607.21 | P20: =SUM(M20:O20) -> 6041.47 | Q20: =SUM(Q64,Q108,Q152) -> 1206.95 | R20: =SUM(R64,R108,R152) -> 998.55 | S20: =SUM(S64,S108,S152) -> 707.24 | T20: =SUM(Q20:S20) -> 2912.74
A21: =A20+1 -> 7 | B21: Malang | C21: Ton | D21: =SUM(H21,L21,P21,T21) -> 15567.705 | E21: =SUM(E65,E109,E153) -> 1421.461 | F21: =SUM(F65,F109,F153) -> 900.702 | G21: =SUM(G65,G109,G153) -> 1668.587 | H21: =SUM(E21:G21) -> 3990.75 | I21: =SUM(I65,I109,I153) -> 1481.007 | J21: =SUM(J65,J109,J153) -> 1576.436 | K21: =SUM(K65,K109,K153) -> 1681.533 | L21: =SUM(I21:K21) -> 4738.976 | M21: =SUM(M65,M109,M153) -> 1885.309 | N21: =SUM(N65,N109,N153) -> 1677.105 | O21: =SUM(O65,O109,O153) -> 1104.569 | P21: =SUM(M21:O21) -> 4666.983 | Q21: =SUM(Q65,Q109,Q153) -> 821.934 | R21: =SUM(R65,R109,R153) -> 735.443 | S21: =SUM(S65,S109,S153) -> 613.619 | T21: =SUM(Q21:S21) -> 2170.996
A22: =A21+1 -> 8 | B22: Lumajang | C22: Ton | D22: =SUM(H22,L22,P22,T22) -> 11540.541 | E22: =SUM(E66,E110,E154) -> 585.771 | F22: =SUM(F66,F110,F154) -> 596.433 | G22: =SUM(G66,G110,G154) -> 720.124 | H22: =SUM(E22:G22) -> 1902.328 | I22: =SUM(I66,I110,I154) -> 410.513 | J22: =SUM(J66,J110,J154) -> 432.809 | K22: =SUM(K66,K110,K154) -> 1114.118 | L22: =SUM(I22:K22) -> 1957.44 | M22: =SUM(M66,M110,M154) -> 1594.442 | N22: =SUM(N66,N110,N154) -> 1508.22 | O22: =SUM(O66,O110,O154) -> 1453.879 | P22: =SUM(M22:O22) -> 4556.541 | Q22: =SUM(Q66,Q110,Q154) -> 1048.832 | R22: =SUM(R66,R110,R154) -> 1051.8 | S22: =SUM(S66,S110,S154) -> 1023.6 | T22: =SUM(Q22:S22) -> 3124.232
A23: =A22+1 -> 9 | B23: Jember | C23: Ton | D23: =SUM(H23,L23,P23,T23) -> 19172.523 | E23: =SUM(E67,E111,E155) -> 325.37 | F23: =SUM(F67,F111,F155) -> 284.2 | G23: =SUM(G67,G111,G155) -> 458.77 | H23: =SUM(E23:G23) -> 1068.34 | I23: =SUM(I67,I111,I155) -> 494.01 | J23: =SUM(J67,J111,J155) -> 714.85 | K23: =SUM(K67,K111,K155) -> 1292.34 | L23: =SUM(I23:K23) -> 2501.2 | M23: =SUM(M67,M111,M155) -> 1888.56 | N23: =SUM(N67,N111,N155) -> 2732.96 | O23: =SUM(O67,O111,O155) -> 3332.95 | P23: =SUM(M23:O23) -> 7954.47 | Q23: =SUM(Q67,Q111,Q155) -> 2897.1 | R23: =SUM(R67,R111,R155) -> 2712.11 | S23: =SUM(S67,S111,S155) -> 2039.303 | T23: =SUM(Q23:S23) -> 7648.513
A24: =A23+1 -> 10 | B24: Banyuwangi | C24: Ton | D24: =SUM(H24,L24,P24,T24) -> 72382.493 | E24: =SUM(E68,E112,E156) -> 6865.711 | F24: =SUM(F68,F112,F156) -> 4667.912 | G24: =SUM(G68,G112,G156) -> 3880.912 | H24: =SUM(E24:G24) -> 15414.535 | I24: =SUM(I68,I112,I156) -> 5304.814 | J24: =SUM(J68,J112,J156) -> 5875.212 | K24: =SUM(K68,K112,K156) -> 6421.617 | L24: =SUM(I24:K24) -> 17601.643 | M24: =SUM(M68,M112,M156) -> 6700.419 | N24: =SUM(N68,N112,N156) -> 4807.819 | O24: =SUM(O68,O112,O156) -> 5402.917 | P24: =SUM(M24:O24) -> 16911.155 | Q24: =SUM(Q68,Q112,Q156) -> 7671.96 | R24: =SUM(R68,R112,R156) -> 7920.1 | S24: =SUM(S68,S112,S156) -> 6863.1 | T24: =SUM(Q24:S24) -> 22455.16
A25: =A24+1 -> 11 | B25: Bondowoso | C25: Ton | D25: =SUM(H25,L25,P25,T25) -> 8117.96 | E25: =SUM(E69,E113,E157) -> 259.23 | F25: =SUM(F69,F113,F157) -> 281.65 | G25: =SUM(G69,G113,G157) -> 325.92 | H25: =SUM(E25:G25) -> 866.8 | I25: =SUM(I69,I113,I157) -> 441.45 | J25: =SUM(J69,J113,J157) -> 480.27 | K25: =SUM(K69,K113,K157) -> 735.88 | L25: =SUM(I25:K25) -> 1657.6 | M25: =SUM(M69,M113,M157) -> 912.97 | N25: =SUM(N69,N113,N157) -> 988.15 | O25: =SUM(O69,O113,O157) -> 951.55 | P25: =SUM(M25:O25) -> 2852.67 | Q25: =SUM(Q69,Q113,Q157) -> 957.82 | R25: =SUM(R69,R113,R157) -> 923.85 | S25: =SUM(S69,S113,S157) -> 859.22 | T25: =SUM(Q25:S25) -> 2740.89
A26: =A25+1 -> 12 | B26: Situbondo | C26: Ton | D26: =SUM(H26,L26,P26,T26) -> 75133.247 | E26: =SUM(E70,E114,E158) -> 6311.23 | F26: =SUM(F70,F114,F158) -> 5301.5 | G26: =SUM(G70,G114,G158) -> 6816.65 | H26: =SUM(E26:G26) -> 18429.38 | I26: =SUM(I70,I114,I158) -> 4941.2 | J26: =SUM(J70,J114,J158) -> 5908.8 | K26: =SUM(K70,K114,K158) -> 4392.7 | L26: =SUM(I26:K26) -> 15242.7 | M26: =SUM(M70,M114,M158) -> 5531.8 | N26: =SUM(N70,N114,N158) -> 6298.2 | O26: =SUM(O70,O114,O158) -> 6961.4 | P26: =SUM(M26:O26) -> 18791.4 | Q26: =SUM(Q70,Q114,Q158) -> 6896.7 | R26: =SUM(R70,R114,R158) -> 7748.6 | S26: =SUM(S70,S114,S158) -> 8024.467 | T26: =SUM(Q26:S26) -> 22669.767
A27: =A26+1 -> 13 | B27: Probolinggo | C27: Ton | D27: =SUM(H27,L27,P27,T27) -> 36601.17 | E27: =SUM(E71,E115,E159) -> 2375.87 | F27: =SUM(F71,F115,F159) -> 2500.14 | G27: =SUM(G71,G115,G159) -> 2817.39 | H27: =SUM(E27:G27) -> 7693.4 | I27: =SUM(I71,I115,I159) -> 4223.15 | J27: =SUM(J71,J115,J159) -> 4207.38 | K27: =SUM(K71,K115,K159) -> 3164.07 | L27: =SUM(I27:K27) -> 11594.6 | M27: =SUM(M71,M115,M159) -> 2840.06 | N27: =SUM(N71,N115,N159) -> 2447.91 | O27: =SUM(O71,O115,O159) -> 3140.8 | P27: =SUM(M27:O27) -> 8428.77 | Q27: =SUM(Q71,Q115,Q159) -> 3040.58 | R27: =SUM(R71,R115,R159) -> 2939.29 | S27: =SUM(S71,S115,S159) -> 2904.53 | T27: =SUM(Q27:S27) -> 8884.4
... A36: =A35+1 -> 22 | B36: Bojonegoro | C36: Ton | D36: =SUM(H36,L36,P36,T36) -> 7733.412 | E36: =SUM(E80,E124,E168) -> 241.877 | F36: =SUM(F80,F124,F168) -> 139.328 | G36: =SUM(G80,G124,G168) -> 199.127 | H36: =SUM(E36:G36) -> 580.332 | I36: =SUM(I80,I124,I168) -> 397.813 | J36: =SUM(J80,J124,J168) -> 253.675 | K36: =SUM(K80,K124,K168) -> 265.73 | L36: =SUM(I36:K36) -> 917.218 | M36: =SUM(M80,M124,M168) -> 1083.44 | N36: =SUM(N80,N124,N168) -> 1176.907 | O36: =SUM(O80,O124,O168) -> 1283.643 | P36: =SUM(M36:O36) -> 3543.99 | Q36: =SUM(Q80,Q124,Q168) -> 1149.125 | R36: =SUM(R80,R124,R168) -> 920.702 | S36: =SUM(S80,S124,S168) -> 622.045 | T36: =SUM(Q36:S36) -> 2691.872
A37: 23 | B37: Tuban | C37: Ton | D37: =SUM(H37,L37,P37,T37) -> 37758.3 | E37: =SUM(E81,E125,E169) -> 3254.7 | F37: =SUM(F81,F125,F169) -> 3475.3 | G37: =SUM(G81,G125,G169) -> 3339.8 | H37: =SUM(E37:G37) -> 10069.8 | I37: =SUM(I81,I125,I169) -> 3055.8 | J37: =SUM(J81,J125,J169) -> 3094.2 | K37: =SUM(K81,K125,K169) -> 2880.4 | L37: =SUM(I37:K37) -> 9030.4 | M37: =SUM(M81,M125,M169) -> 3023.3 | N37: =SUM(N81,N125,N169) -> 3172.1 | O37: =SUM(O81,O125,O169) -> 3302.9 | P37: =SUM(M37:O37) -> 9498.3 | Q37: =SUM(Q81,Q125,Q169) -> 3618.7 | R37: =SUM(R81,R125,R169) -> 3013.9 | S37: =SUM(S81,S125,S169) -> 2527.2 | T37: =SUM(Q37:S37) -> 9159.8
A38: 24 | B38: Lamongan | C38: Ton | D38: =SUM(H38,L38,P38,T38) -> 26006.57 | E38: =SUM(E82,E126,E170) -> 496.63 | F38: =SUM(F82,F126,F170) -> 883.76 | G38: =SUM(G82,G126,G170) -> 577.67 | H38: =SUM(E38:G38) -> 1958.06 | I38: =SUM(I82,I126,I170) -> 945.57 | J38: =SUM(J82,J126,J170) -> 1457.47 | K38: =SUM(K82,K126,K170) -> 2160.35 | L38: =SUM(I38:K38) -> 4563.39 | M38: =SUM(M82,M126,M170) -> 4127.47 | N38: =SUM(N82,N126,N170) -> 4257.57 | O38: =SUM(O82,O126,O170) -> 5706.15 | P38: =SUM(M38:O38) -> 14091.19 | Q38: =SUM(Q82,Q126,Q170) -> 3096.73 | R38: =SUM(R82,R126,R170) -> 1218.5 | S38: =SUM(S82,S126,S170) -> 1078.7 | T38: =SUM(Q38:S38) -> 5393.93
A39: 25 | B39: Gresik | C39: Ton | D39: =SUM(H39,L39,P39,T39) -> 10843 | E39: =SUM(E83,E127,E171) -> 540.4 | F39: =SUM(F83,F127,F171) -> 688.3 | G39: =SUM(G83,G127,G171) -> 930.2 | H39: =SUM(E39:G39) -> 2158.9 | I39: =SUM(I83,I127,I171) -> 905.4 | J39: =SUM(J83,J127,J171) -> 899 | K39: =SUM(K83,K127,K171) -> 650.9 | L39: =SUM(I39:K39) -> 2455.3 | M39: =SUM(M83,M127,M171) -> 681.6 | N39: =SUM(N83,N127,N171) -> 1012.1 | O39: =SUM(O83,O127,O171) -> 1370 | P39: =SUM(M39:O39) -> 3063.7 | Q39: =SUM(Q83,Q127,Q171) -> 1150.7 | R39: =SUM(R83,R127,R171) -> 1050.1 | S39: =SUM(S83,S127,S171) -> 964.3 | T39: =SUM(Q39:S39) -> 3165.1
A40: 26 | B40: Bangkalan | C40: Ton | D40: =SUM(H40,L40,P40,T40) -> 25778.3 | E40: =SUM(E84,E128,E172) -> 1039.4 | F40: =SUM(F84,F128,F172) -> 1178.6 | G40: =SUM(G84,G128,G172) -> 1021.4 | H40: =SUM(E40:G40) -> 3239.4 | I40: =SUM(I84,I128,I172) -> 1673 | J40: =SUM(J84,J128,J172) -> 2853.2 | K40: =SUM(K84,K128,K172) -> 3086.9 | L40: =SUM(I40:K40) -> 7613.1 | M40: =SUM(M84,M128,M172) -> 3321.5 | N40: =SUM(N84,N128,N172) -> 3616.3 | O40: =SUM(O84,O128,O172) -> 3009.9 | P40: =SUM(M40:O40) -> 9947.7 | Q40: =SUM(Q84,Q128,Q172) -> 2077.3 | R40: =SUM(R84,R128,R172) -> 1583.9 | S40: =SUM(S84,S128,S172) -> 1316.9 | T40: =SUM(Q40:S40) -> 4978.1
A41: 27 | B41: Sampang | C41: Ton | D41: =SUM(H41,L41,P41,T41) -> 16805.3 | E41: =SUM(E85,E129,E173) -> 1063 | F41: =SUM(F85,F129,F173) -> 1152.2 | G41: =SUM(G85,G129,G173) -> 1193.4 | H41: =SUM(E41:G41) -> 3408.6 | I41: =SUM(I85,I129,I173) -> 1474.4 | J41: =SUM(J85,J129,J173) -> 1627 | K41: =SUM(K85,K129,K173) -> 1747.4 | L41: =SUM(I41:K41) -> 4848.8 | M41: =SUM(M85,M129,M173) -> 1679.2 | N41: =SUM(N85,N129,N173) -> 1603.3 | O41: =SUM(O85,O129,O173) -> 1495.3 | P41: =SUM(M41:O41) -> 4777.8 | Q41: =SUM(Q85,Q129,Q173) -> 1316.2 | R41: =SUM(R85,R129,R173) -> 1256.2 | S41: =SUM(S85,S129,S173) -> 1197.7 | T41: =SUM(Q41:S41) -> 3770.1
A42: 28 | B42: Pamekasan | C42: Ton | D42: =SUM(H42,L42,P42,T42) -> 18004.6 | E42: =SUM(E86,E130,E174) -> 1013.1 | F42: =SUM(F86,F130,F174) -> 1284.5 | G42: =SUM(G86,G130,G174) -> 1246.3 | H42: =SUM(E42:G42) -> 3543.9 | I42: =SUM(I86,I130,I174) -> 1517.5 | J42: =SUM(J86,J130,J174) -> 1624.6 | K42: =SUM(K86,K130,K174) -> 1870.3 | L42: =SUM(I42:K42) -> 5012.4 | M42: =SUM(M86,M130,M174) -> 1507.3 | N42: =SUM(N86,N130,N174) -> 1523 | O42: =SUM(O86,O130,O174) -> 1555.8 | P42: =SUM(M42:O42) -> 4586.1 | Q42: =SUM(Q86,Q130,Q174) -> 1599.1 | R42: =SUM(R86,R130,R174) -> 1663.1 | S42: =SUM(S86,S130,S174) -> 1600 | T42: =SUM(Q42:S42) -> 4862.2
A43: 29 | B43: Sumenep | C43: Ton | D43: =SUM(H43,L43,P43,T43) -> 40137.189 | E43: =SUM(E87,E131,E175) -> 4660.5 | F43: =SUM(F87,F131,F175) -> 4330.7 | G43: =SUM(G87,G131,G175) -> 3744.3 | H43: =SUM(E43:G43) -> 12735.5 | I43: =SUM(I87,I131,I175) -> 2523.4 | J43: =SUM(J87,J131,J175) -> 5143.5 | K43: =SUM(K87,K131,K175) -> 3843.58 | L43: =SUM(I43:K43) -> 11510.48 | M43: =SUM(M87,M131,M175) -> 2492.4 | N43: =SUM(N87,N131,N175) -> 2800.6 | O43: =SUM(O87,O131,O175) -> 4101.7 | P43: =SUM(M43:O43) -> 9394.7 | Q43: =SUM(Q87,Q131,Q175) -> 2490.609 | R43: =SUM(R87,R131,R175) -> 2293.9 | S43: =SUM(S87,S131,S175) -> 1712 | T43: =SUM(Q43:S43) -> 6496.509
A44: 30 | B44: Kota Kediri | C44: Ton | D44: =SUM(H44,L44,P44,T44) -> 33.2 | E44: =SUM(E88,E132,E176) -> 2.7 | F44: =SUM(F88,F132,F176) -> 2.8 | G44: =SUM(G88,G132,G176) -> 2.8 | H44: =SUM(E44:G44) -> 8.3 | I44: =SUM(I88,I132,I176) -> 3.3 | J44: =SUM(J88,J132,J176) -> 3.1 | K44: =SUM(K88,K132,K176) -> 2.6 | L44: =SUM(I44:K44) -> 9 | M44: =SUM(M88,M132,M176) -> 2.7 | N44: =SUM(N88,N132,N176) -> 2.6 | O44: =SUM(O88,O132,O176) -> 2.6 | P44: =SUM(M44:O44) -> 7.9 | Q44: =SUM(Q88,Q132,Q176) -> 2.5 | R44: =SUM(R88,R132,R176) -> 2.7 | S44: =SUM(S88,S132,S176) -> 2.8 | T44: =SUM(Q44:S44) -> 8
A45: 31 | B45: Kota Blitar | C45: Ton | D45: =SUM(H45,L45,P45,T45) -> 0 | E45: =SUM(E89,E133,E177) -> 0 | F45: =SUM(F89,F133,F177) -> 0 | G45: =SUM(G89,G133,G177) -> 0 | H45: =SUM(E45:G45) -> 0 | I45: =SUM(I89,I133,I177) -> 0 | J45: =SUM(J89,J133,J177) -> 0 | K45: =SUM(K89,K133,K177) -> 0 | L45: =SUM(I45:K45) -> 0 | M45: =SUM(M89,M133,M177) -> 0 | N45: =SUM(N89,N133,N177) -> 0 | O45: =SUM(O89,O133,O177) -> 0 | P45: =SUM(M45:O45) -> 0 | Q45: =SUM(Q89,Q133,Q177) -> 0 | R45: =SUM(R89,R133,R177) -> 0 | S45: =SUM(S89,S133,S177) -> 0 | T45: =SUM(Q45:S45) -> 0
A46: 32 | B46: Kota Malang | C46: Ton | D46: =SUM(H46,L46,P46,T46) -> 0 | E46: =SUM(E90,E134,E178) -> 0 | F46: =SUM(F90,F134,F178) -> 0 | G46: =SUM(G90,G134,G178) -> 0 | H46: =SUM(E46:G46) -> 0 | I46: =SUM(I90,I134,I178) -> 0 | J46: =SUM(J90,J134,J178) -> 0 | K46: =SUM(K90,K134,K178) -> 0 | L46: =SUM(I46:K46) -> 0 | M46: =SUM(M90,M134,M178) -> 0 | N46: =SUM(N90,N134,N178) -> 0 | O46: =SUM(O90,O134,O178) -> 0 | P46: =SUM(M46:O46) -> 0 | Q46: =SUM(Q90,Q134,Q178) -> 0 | R46: =SUM(R90,R134,R178) -> 0 | S46: =SUM(S90,S134,S178) -> 0 | T46: =SUM(Q46:S46) -> 0
A47: 33 | B47: Kota Probolinggo | C47: Ton | D47: =SUM(H47,L47,P47,T47) -> 939.077 | E47: =SUM(E91,E135,E179) -> 57.411 | F47: =SUM(F91,F135,F179) -> 70.203 | G47: =SUM(G91,G135,G179) -> 83.673 | H47: =SUM(E47:G47) -> 211.287 | I47: =SUM(I91,I135,I179) -> 92.447 | J47: =SUM(J91,J135,J179) -> 98.085 | K47: =SUM(K91,K135,K179) -> 109.315 | L47: =SUM(I47:K47) -> 299.847 | M47: =SUM(M91,M135,M179) -> 78.47 | N47: =SUM(N91,N135,N179) -> 57.618 | O47: =SUM(O91,O135,O179) -> 55.19 | P47: =SUM(M47:O47) -> 191.278 | Q47: =SUM(Q91,Q135,Q179) -> 66.38 | R47: =SUM(R91,R135,R179) -> 79.13 | S47: =SUM(S91,S135,S179) -> 91.155 | T47: =SUM(Q47:S47) -> 236.665
A48: 34 | B48: Kota Pasuruan | C48: Ton | D48: =SUM(H48,L48,P48,T48) -> 11036.6 | E48: =SUM(E92,E136,E180) -> 730.3 | F48: =SUM(F92,F136,F180) -> 843.5 | G48: =SUM(G92,G136,G180) -> 1444.8 | H48: =SUM(E48:G48) -> 3018.6 | I48: =SUM(I92,I136,I180) -> 1690.4 | J48: =SUM(J92,J136,J180) -> 1023.8 | K48: =SUM(K92,K136,K180) -> 903 | L48: =SUM(I48:K48) -> 3617.2 | M48: =SUM(M92,M136,M180) -> 843.3 | N48: =SUM(N92,N136,N180) -> 823.9 | O48: =SUM(O92,O136,O180) -> 821.5 | P48: =SUM(M48:O48) -> 2488.7 | Q48: =SUM(Q92,Q136,Q180) -> 672 | R48: =SUM(R92,R136,R180) -> 645.5 | S48: =SUM(S92,S136,S180) -> 594.6 | T48: =SUM(Q48:S48) -> 1912.1
... A52: 38 | B52: Kota Batu | C52: Ton | D52: =SUM(H52,L52,P52,T52) -> 0 | E52: =SUM(E96,E140,E184) -> 0 | F52: =SUM(F96,F140,F184) -> 0 | G52: =SUM(G96,G140,G184) -> 0 | H52: =SUM(E52:G52) -> 0 | I52: =SUM(I96,I140,I184) -> 0 | J52: =SUM(J96,J140,J184) -> 0 | K52: =SUM(K96,K140,K184) -> 0 | L52: =SUM(I52:K52) -> 0 | M52: =SUM(M96,M140,M184) -> 0 | N52: =SUM(N96,N140,N184) -> 0 | O52: =SUM(O96,O140,O184) -> 0 | P52: =SUM(M52:O52) -> 0 | Q52: =SUM(Q96,Q140,Q184) -> 0 | R52: =SUM(R96,R140,R184) -> 0 | S52: =SUM(S96,S140,S184) -> 0 | T52: =SUM(Q52:S52) -> 0
A55: PRODUKSI LAUT/ NON PELABUHAN JAWA TIMUR
A56: No. | B56: U r a i a n | C56: Satuan | D56: Jumlah | E56: Januari | F56: Februari | G56: Maret | H56: TW I | I56: April | J56: Mei | K56: Juni | L56: TW II | M56: Juli | N56: Agustus | O56: September | P56: TW III | Q56: Oktober | R56: November | S56: Desember | T56: TW IV
B58: JUMLAH | C58: Ton | D58: =SUM(D59:D96) -> 391334.21 | E58: =SUM(E59:E96) -> 29152.746 | F58: =SUM(F59:F96) -> 26940.293 | G58: =SUM(G59:G96) -> 26650.341 | H58: =SUM(E58:G58) -> 82743.38 | I58: =SUM(I59:I96) -> 32706.072 | J58: =SUM(J59:J96) -> 35177.115 | K58: =SUM(K59:K96) -> 34135.075 | L58: =SUM(I58:K58) -> 102018.26 | M58: =SUM(M59:M96) -> 36065.859 | N58: =SUM(N59:N96) -> 36701.989 | O58: =SUM(O59:O96) -> 40121.112 | P58: =SUM(M58:O58) -> 112888.96 | Q58: =SUM(Q59:Q96) -> 35223.213 | R58: =SUM(R59:R96) -> 31009.544 | S58: =SUM(S59:S96) -> 27450.849 | T58: =SUM(Q58:S58) -> 93683.606
...

Sheet GARAM
A1: PRODUKSI GARAM JAWA TIMUR
A4: No. | B4: U r a i a n | C4: Satuan | D4: Jumlah | E4: Januari | F4: Februari | G4: Maret | H4: TW I | I4: April | J4: Mei | K4: Juni | L4: TW II | M4: Juli | N4: Agustus | O4: September | P4: TW III | Q4: Oktober | R4: November | S4: Desember | T4: TW IV
B6: JUMLAH | C6: Ton | D6: =SUM(D7:D44) -> 161.3 | E6: =SUM(E7:E44) -> 1 | F6: =SUM(F7:F44) -> 1.2 | G6: =SUM(G7:G44) -> 10.5 | H6: =SUM(E6:G6) -> 12.7 | I6: =SUM(I7:I44) -> 148.6 | J6: =SUM(J7:J44) -> 0 | K6: =SUM(K7:K44) -> 0 | L6: =SUM(I6:K6) -> 148.6 | M6: =SUM(M7:M28) -> 0 | N6: =SUM(N7:N28) -> 0 | O6: =SUM(O7:O28) -> 0 | P6: =SUM(M6:O6) -> 0 | Q6: =SUM(Q7:Q28) -> 0 | R6: =SUM(R7:R28) -> 0 | S6: =SUM(S7:S28) -> 0 | T6: =SUM(Q6:S6) -> 0
A7: 1 | B7: Pacitan | C7: Ton | D7: =SUM(H7,L7,P7,T7) -> 0 | E7: 0 | F7: 0 | G7: 0 | H7: =SUM(E7:G7) -> 0 | I7: 0 | J7: 0 | K7: 0 | L7: =SUM(I7:K7) -> 0 | M7: 0 | N7: 0 | O7: 0 | P7: =SUM(M7:O7) -> 0 | Q7: 0 | R7: 0 | S7: 0 | T7: =SUM(Q7:S7) -> 0
A8: =A7+1 -> 2 | B8: Ponorogo | C8: Ton | D8: =SUM(H8,L8,P8,T8) -> 0 | E8: 0 | F8: 0 | G8: 0 | H8: =SUM(E8:G8) -> 0 | I8: 0 | J8: 0 | K8: 0 | L8: =SUM(I8:K8) -> 0 | M8: 0 | N8: 0 | O8: 0 | P8: =SUM(M8:O8) -> 0 | Q8: 0 | R8: 0 | S8: 0 | T8: =SUM(Q8:S8) -> 0
A9: =A8+1 -> 3 | B9: Trenggalek | C9: Ton | D9: =SUM(H9,L9,P9,T9) -> 0 | E9: 0 | F9: 0 | G9: 0 | H9: =SUM(E9:G9) -> 0 | I9: 0 | J9: 0 | K9: 0 | L9: =SUM(I9:K9) -> 0 | M9: 0 | N9: 0 | O9: 0 | P9: =SUM(M9:O9) -> 0 | Q9: 0 | R9: 0 | S9: 0 | T9: =SUM(Q9:S9) -> 0
A10: =A9+1 -> 4 | B10: Tulungagung | C10: Ton | D10: =SUM(H10,L10,P10,T10) -> 0 | E10: 0 | F10: 0 | G10: 0 | H10: =SUM(E10:G10) -> 0 | I10: 0 | J10: 0 | K10: 0 | L10: =SUM(I10:K10) -> 0 | M10: 0 | N10: 0 | O10: 0 | P10: =SUM(M10:O10) -> 0 | Q10: 0 | R10: 0 | S10: 0 | T10: =SUM(Q10:S10) -> 0
A11: =A10+1 -> 5 | B11: Blitar | C11: Ton | D11: =SUM(H11,L11,P11,T11) -> 0 | E11: 0 | F11: 0 | G11: 0 | H11: =SUM(E11:G11) -> 0 | I11: 0 | J11: 0 | K11: 0 | L11: =SUM(I11:K11) -> 0 | M11: 0 | N11: 0 | O11: 0 | P11: =SUM(M11:O11) -> 0 | Q11: 0 | R11: 0 | S11: 0 | T11: =SUM(Q11:S11) -> 0
A12: =A11+1 -> 6 | B12: Kediri | C12: Ton | D12: =SUM(H12,L12,P12,T12) -> 0 | E12: 0 | F12: 0 | G12: 0 | H12: =SUM(E12:G12) -> 0 | I12: 0 | J12: 0 | K12: 0 | L12: =SUM(I12:K12) -> 0 | M12: 0 | N12: 0 | O12: 0 | P12: =SUM(M12:O12) -> 0 | Q12: 0 | R12: 0 | S12: 0 | T12: =SUM(Q12:S12) -> 0
A13: =A12+1 -> 7 | B13: Malang | C13: Ton | D13: =SUM(H13,L13,P13,T13) -> 0 | E13: 0 | F13: 0 | G13: 0 | H13: =SUM(E13:G13) -> 0 | I13: 0 | J13: 0 | K13: 0 | L13: =SUM(I13:K13) -> 0 | M13: 0 | N13: 0 | O13: 0 | P13: =SUM(M13:O13) -> 0 | Q13: 0 | R13: 0 | S13: 0 | T13: =SUM(Q13:S13) -> 0
A14: =A13+1 -> 8 | B14: Lumajang | C14: Ton | D14: =SUM(H14,L14,P14,T14) -> 0 | E14: 0 | F14: 0 | G14: 0 | H14: =SUM(E14:G14) -> 0 | I14: 0 | J14: 0 | K14: 0 | L14: =SUM(I14:K14) -> 0 | M14: 0 | N14: 0 | O14: 0 | P14: =SUM(M14:O14) -> 0 | Q14: 0 | R14: 0 | S14: 0 | T14: =SUM(Q14:S14) -> 0
A15: =A14+1 -> 9 | B15: Jember | C15: Ton | D15: =SUM(H15,L15,P15,T15) -> 0 | E15: 0 | F15: 0 | G15: 0 | H15: =SUM(E15:G15) -> 0 | I15: 0 | J15: 0 | K15: 0 | L15: =SUM(I15:K15) -> 0 | M15: 0 | N15: 0 | O15: 0 | P15: =SUM(M15:O15) -> 0 | Q15: 0 | R15: 0 | S15: 0 | T15: =SUM(Q15:S15) -> 0
A16: =A15+1 -> 10 | B16: Banyuwangi | C16: Ton | D16: =SUM(H16,L16,P16,T16) -> 0 | E16: 0 | F16: 0 | G16: 0 | H16: =SUM(E16:G16) -> 0 | I16: 0 | J16: 0 | K16: 0 | L16: =SUM(I16:K16) -> 0 | M16: 0 | N16: 0 | O16: 0 | P16: =SUM(M16:O16) -> 0 | Q16: 0 | R16: 0 | S16: 0 | T16: =SUM(Q16:S16) -> 0
A17: =A16+1 -> 11 | B17: Bondowoso | C17: Ton | D17: =SUM(H17,L17,P17,T17) -> 0 | E17: 0 | F17: 0 | G17: 0 | H17: =SUM(E17:G17) -> 0 | I17: 0 | J17: 0 | K17: 0 | L17: =SUM(I17:K17) -> 0 | M17: 0 | N17: 0 | O17: 0 | P17: =SUM(M17:O17) -> 0 | Q17: 0 | R17: 0 | S17: 0 | T17: =SUM(Q17:S17) -> 0
A18: =A17+1 -> 12 | B18: Situbondo | C18: Ton | D18: =SUM(H18,L18,P18,T18) -> 14.1 | E18: 0 | F18: 0 | G18: 9 | H18: =SUM(E18:G18) -> 9 | I18: 5.1 | J18: 0 | K18: 0 | L18: =SUM(I18:K18) -> 5.1 | M18: 0 | N18: 0 | O18: 0 | P18: =SUM(M18:O18) -> 0 | Q18: 0 | R18: 0 | S18: 0 | T18: =SUM(Q18:S18) -> 0
A19: =A18+1 -> 13 | B19: Probolinggo | C19: Ton | D19: =SUM(H19,L19,P19,T19) -> 0 | E19: 0 | F19: 0 | G19: 0 | H19: =SUM(E19:G19) -> 0 | I19: 0 | J19: 0 | K19: 0 | L19: =SUM(I19:K19) -> 0 | M19: 0 | N19: 0 | O19: 0 | P19: =SUM(M19:O19) -> 0 | Q19: 0 | R19: 0 | S19: 0 | T19: =SUM(Q19:S19) -> 0
... A28: =A27+1 -> 22 | B28: Bojonegoro | C28: Ton | D28: =SUM(H28,L28,P28,T28) -> 0 | E28: 0 | F28: 0 | G28: 0 | H28: =SUM(E28:G28) -> 0 | I28: 0 | J28: 0 | K28: 0 | L28: =SUM(I28:K28) -> 0 | M28: 0 | N28: 0 | O28: 0 | P28: =SUM(M28:O28) -> 0 | Q28: 0 | R28: 0 | S28: 0 | T28: =SUM(Q28:S28) -> 0
A29: 23 | B29: Tuban | C29: Ton | D29: =SUM(H29,L29,P29,T29) -> 5.2 | E29: 1 | F29: 1.2 | G29: 1.5 | H29: =SUM(E29:G29) -> 3.7 | I29: 1.5 | J29: 0 | K29: 0 | L29: =SUM(I29:K29) -> 1.5 | M29: 0 | N29: 0 | O29: 0 | P29: =SUM(M29:O29) -> 0 | Q29: 0 | R29: 0 | S29: 0 | T29: =SUM(Q29:S29) -> 0
A30: 24 | B30: Lamongan | C30: Ton | D30: =SUM(H30,L30,P30,T30) -> 4 | E30: 0 | F30: 0 | G30: 0 | H30: =SUM(E30:G30) -> 0 | I30: 4 | J30: 0 | K30: 0 | L30: =SUM(I30:K30) -> 4 | M30: 0 | N30: 0 | O30: 0 | P30: =SUM(M30:O30) -> 0 | Q30: 0 | R30: 0 | S30: 0 | T30: =SUM(Q30:S30) -> 0
A31: 25 | B31: Gresik | C31: Ton | D31: =SUM(H31,L31,P31,T31) -> 0 | E31: 0 | F31: 0 | G31: 0 | H31: =SUM(E31:G31) -> 0 | I31: 0 | J31: 0 | K31: 0 | L31: =SUM(I31:K31) -> 0 | M31: 0 | N31: 0 | O31: 0 | P31: =SUM(M31:O31) -> 0 | Q31: 0 | R31: 0 | S31: 0 | T31: =SUM(Q31:S31) -> 0
A32: 26 | B32: Bangkalan | C32: Ton | D32: =SUM(H32,L32,P32,T32) -> 138 | E32: 0 | F32: 0 | G32: 0 | H32: =SUM(E32:G32) -> 0 | I32: 138 | J32: 0 | K32: 0 | L32: =SUM(I32:K32) -> 138 | M32: 0 | N32: 0 | O32: 0 | P32: =SUM(M32:O32) -> 0 | Q32: 0 | R32: 0 | S32: 0 | T32: =SUM(Q32:S32) -> 0
A33: 27 | B33: Sampang | C33: Ton | D33: =SUM(H33,L33,P33,T33) -> 0 | E33: 0 | F33: 0 | G33: 0 | H33: =SUM(E33:G33) -> 0 | I33: 0 | J33: 0 | K33: 0 | L33: =SUM(I33:K33) -> 0 | M33: 0 | N33: 0 | O33: 0 | P33: =SUM(M33:O33) -> 0 | Q33: 0 | R33: 0 | S33: 0 | T33: =SUM(Q33:S33) -> 0
A34: 28 | B34: Pamekasan | C34: Ton | D34: =SUM(H34,L34,P34,T34) -> 0 | E34: 0 | F34: 0 | G34: 0 | H34: =SUM(E34:G34) -> 0 | I34: 0 | J34: 0 | K34: 0 | L34: =SUM(I34:K34) -> 0 | M34: 0 | N34: 0 | O34: 0 | P34: =SUM(M34:O34) -> 0 | Q34: 0 | R34: 0 | S34: 0 | T34: =SUM(Q34:S34) -> 0
A35: 29 | B35: Sumenep | C35: Ton | D35: =SUM(H35,L35,P35,T35) -> 0 | E35: 0 | F35: 0 | G35: 0 | H35: =SUM(E35:G35) -> 0 | I35: 0 | J35: 0 | K35: 0 | L35: =SUM(I35:K35) -> 0 | M35: 0 | N35: 0 | O35: 0 | P35: =SUM(M35:O35) -> 0 | Q35: 0 | R35: 0 | S35: 0 | T35: =SUM(Q35:S35) -> 0
A36: 30 | B36: Kota Kediri | C36: Ton | D36: =SUM(H36,L36,P36,T36) -> 0 | E36: 0 | F36: 0 | G36: 0 | H36: =SUM(E36:G36) -> 0 | I36: 0 | J36: 0 | K36: 0 | L36: =SUM(I36:K36) -> 0 | M36: 0 | N36: 0 | O36: 0 | P36: =SUM(M36:O36) -> 0 | Q36: 0 | R36: 0 | S36: 0 | T36: =SUM(Q36:S36) -> 0
A37: 31 | B37: Kota Blitar | C37: Ton | D37: =SUM(H37,L37,P37,T37) -> 0 | E37: 0 | F37: 0 | G37: 0 | H37: =SUM(E37:G37) -> 0 | I37: 0 | J37: 0 | K37: 0 | L37: =SUM(I37:K37) -> 0 | M37: 0 | N37: 0 | O37: 0 | P37: =SUM(M37:O37) -> 0 | Q37: 0 | R37: 0 | S37: 0 | T37: =SUM(Q37:S37) -> 0
A38: 32 | B38: Kota Malang | C38: Ton | D38: =SUM(H38,L38,P38,T38) -> 0 | E38: 0 | F38: 0 | G38: 0 | H38: =SUM(E38:G38) -> 0 | I38: 0 | J38: 0 | K38: 0 | L38: =SUM(I38:K38) -> 0 | M38: 0 | N38: 0 | O38: 0 | P38: =SUM(M38:O38) -> 0 | Q38: 0 | R38: 0 | S38: 0 | T38: =SUM(Q38:S38) -> 0
A39: 33 | B39: Kota Probolinggo | C39: Ton | D39: =SUM(H39,L39,P39,T39) -> 0 | E39: 0 | F39: 0 | G39: 0 | H39: =SUM(E39:G39) -> 0 | I39: 0 | J39: 0 | K39: 0 | L39: =SUM(I39:K39) -> 0 | M39: 0 | N39: 0 | O39: 0 | P39: =SUM(M39:O39) -> 0 | Q39: 0 | R39: 0 | S39: 0 | T39: =SUM(Q39:S39) -> 0
A40: 34 | B40: Kota Pasuruan | C40: Ton | D40: =SUM(H40,L40,P40,T40) -> 0 | E40: 0 | F40: 0 | G40: 0 | H40: =SUM(E40:G40) -> 0 | I40: 0 | J40: 0 | K40: 0 | L40: =SUM(I40:K40) -> 0 | M40: 0 | N40: 0 | O40: 0 | P40: =SUM(M40:O40) -> 0 | Q40: 0 | R40: 0 | S40: 0 | T40: =SUM(Q40:S40) -> 0
... A44: 38 | B44: Kota Batu | C44: Ton | D44: =SUM(H44,L44,P44,T44) -> 0 | E44: 0 | F44: 0 | G44: 0 | H44: =SUM(E44:G44) -> 0 | I44: 0 | J44: 0 | K44: 0 | L44: =SUM(I44:K44) -> 0 | M44: 0 | N44: 0 | O44: 0 | P44: =SUM(M44:O44) -> 0 | Q44: 0 | R44: 0 | S44: 0 | T44: =SUM(Q44:S44) -> 0

Sheet EKSPOR

Sheet TRIWULAN
B1: PRODUKSI PERIKANAN JAWA TIMUR
A3: No | B3: Uraian | C3: SATUAN | D3: JUMLAH | E3: TRIWULAN 2025
E4: Januari | F4: Februari | G4: Maret | H4: TW I | I4: April | J4: Mei | K4: Juni | L4: TW II | M4: Juli | N4: Agustus | O4: September | P4: TW III | Q4: Oktober | R4: November | S4: Desember | T4: TW IV
B5: Total | C5: TON | D5: =SUM(D6,D10) -> 2049676.9 | E5: =SUM(E6,E10) -> 144422.11 | F5: =SUM(F6,F10) -> 147072.42 | G5: =SUM(G6,G10) -> 162242.4 | H5: =SUM(H6,H10) -> 453736.93 | I5: =SUM(I6,I10) -> 164867.09 | J5: =SUM(J6,J10) -> 173730.98 | K5: =SUM(K6,K10) -> 163011.26 | ... T5: =SUM(T6,T10) -> 527737.45
A6: 1 | B6: Perikanan Tangkap | C6: TON | D6: =SUM(H6,L6,P6,T6) -> 607343.91 | E6: =SUM(E7:E9) -> 44320.111 | F6: =SUM(F7:F9) -> 37536.034 | G6: =SUM(G7:G9) -> 41768.325 | H6: =SUM(E6:G6) -> 123624.47 | I6: =SUM(I7:I9) -> 47007.973 | J6: =SUM(J7:J9) -> 52953.863 | K6: =SUM(K7:K9) -> 50700.556 | L6: =SUM(I6:K6) -> 150662.39 | M6: =SUM(M7:M9) -> 61473.013 | N6: =SUM(N7:N9) -> 57456.03 | O6: =SUM(O7:O9) -> 63027.588 | P6: =SUM(M6:O6) -> 181956.63 | Q6: =SUM(Q7:Q9) -> 56439.269 | R6: =SUM(R7:R9) -> 50806.882 | S6: =SUM(S7:S9) -> 43854.262 | T6: =SUM(Q6:S6) -> 151100.41
A7: - | B7: Laut / Non Pelabuhan | C7: Ton | D7: =SUM(H7,L7,P7,T7) -> 391334.21 | E7: =TANGKAP!E6 -> 29152.746 | F7: =TANGKAP!F6 -> 26940.293 | G7: =TANGKAP!G6 -> 26650.341 | H7: =SUM(E7:G7) -> 82743.38 | I7: =TANGKAP!I6 -> 32706.072 | J7: =TANGKAP!J6 -> 35177.115 | K7: =TANGKAP!K6 -> 34135.075 | L7: =SUM(I7:K7) -> 102018.26 | M7: =TANGKAP!M6 -> 36065.859 | N7: =TANGKAP!N6 -> 36701.989 | O7: =TANGKAP!O6 -> 40121.112 | P7: =SUM(M7:O7) -> 112888.96 | Q7: =TANGKAP!Q6 -> 35223.213 | R7: =TANGKAP!R6 -> 31009.544 | S7: =TANGKAP!S6 -> 27450.849 | T7: =SUM(Q7:S7) -> 93683.606
A8: - | B8: Pelabuhan | C8: Ton | D8: =SUM(H8,L8,P8,T8) -> 202034.43 | E8: =TANGKAP!E7 -> 14042.054 | F8: =TANGKAP!F7 -> 9371.009 | G8: =TANGKAP!G7 -> 13805.294 | H8: =SUM(E8:G8) -> 37218.357 | I8: =TANGKAP!I7 -> 13032.606 | J8: =TANGKAP!J7 -> 16472.47 | K8: =TANGKAP!K7 -> 15372.703 | L8: =SUM(I8:K8) -> 44877.779 | M8: =TANGKAP!M7 -> 24345.19 | N8: =TANGKAP!N7 -> 19641.811 | O8: =TANGKAP!O7 -> 21784.06 | P8: =SUM(M8:O8) -> 65771.061 | Q8: =TANGKAP!Q7 -> 20107.096 | R8: =TANGKAP!R7 -> 18712.018 | S8: =TANGKAP!S7 -> 15348.116 | T8: =SUM(Q8:S8) -> 54167.23
